Workbook
Name Slicer_Column47: #N/A

Sheet FCS
A1: FIELD COMPACTION SUMMARY | P1: Reporte Nº: | S1: CV-QC-RM-CS-210011
A2: PRESA DE RELAVES ENLOZADA C1 | P2: Mes del reporte | S2: Diciembre
P3: Periodo : | S3: 44531 | T3: al | U3: 44530
A4: TEST IDENTIFICATION | N4: IN SITU DATA | Y4: LABORATORY TEST DATA | AH4: FIELD AND LABORATORY CORRELATION | AO4: REMARKS
A5: SOURCE (4): CYCLONE STATION
A6: FILL (2): TAILING | P6: Loose lift thickness= | U6: 30 cm | Y6: PROCTOR COMPACTION STANDARD-S (7)
A7: Test No./ code (1) | C7: File No. | D7: Resp. Guar. | E7: Turn | F7: Lift No. | G7: Date | H7: Location | Y7: SPECIFIED COMPACTION: | AC7: 98 | AD7: % | AE7: Proctor Compaction | AH7: One-Point Proctor | AX7: Sin Formula
H8: Easting | I8: Northing | J8: Elev. | K8: Cancha | L8: Sb/ Sp No. | M8: Depth (cm) | N8: No. Dens | O8: Corr. Moisture | P8: Moisture, % (6) | R8: Dry Density g/cm3 | T8: Wet density Dens | U8: Method (9) | V8: Compactor (5) | W8: Passes | X8: Real Passes | Y8: Specific Gravity | Z8: Max. Particle size | AA8: Percent passing (Control) | AE8: Max. Dry Density | AF8: Optimum Moisture | AG8: Curve Code | AH8: Dry Density | AI8: Wet density | AJ8: Moisture | AK8: Select. Curve | AL8: Moisture | AM8: Compaction % | AO8: Opinion (8) | AP8: Retest from | AQ8: Remarks | AR8: Retest on | AS8: R. Sem | AT8: R. Sem | AU8: R. Sem | AV8: R. Sem | AX8: revisar
A9: MWH-QA | B9: SMCV-QC | O9: k | P9: Oven | Q9: Dens. | R9: Corr. | S9: Dens. | U9: N/S/PR | W9: # | X9: # | Y9: g/cm3 | AA9: No. 30 | AB9: No. 50 | AC9: No. 100 | AD9: No. 200 | AE9: g/cm3 | AF9: % | AH9: g/cm3 | AI9: g/cm3 | AJ9: % | AK9: No. | AL9: +/- | AM9: Pass | AN9: Failure | AS9: AP East | AT9: Fail East | AU9: CA point | AV9: # Sem
B10: Column1 | C10: Column2 | D10: Column3 | E10: Column4 | F10: Column5 | G10: Column6 | H10: Column7 | I10: Column8 | J10: Column9 | K10: Column10 | L10: Column11 | M10: Column12 | N10: Column13 | O10: Column14 | P10: Column15 | Q10: Column16 | R10: Column17 | S10: Column18 | T10: Column19 | U10: Column20 | V10: Column21 | W10: Column22 | X10: Column23 | Y10: Column24 | Z10: Column25 | AA10: Column26 | AB10: Column27 | AC10: Column28 | AD10: Column29 | AE10: Column30 | AF10: Column31 | AG10: Column32 | AH10: Column33 | AI10: Column34 | AJ10: Column35 | AK10: Column36 | AL10: Column37 | AM10: Column38 | AN10: Column39 | AO10: Column40 | AP10: Column41 | AQ10: Column42 | AR10: Column43 | AS10: Column44 | AT10: Column45 | AU10: Column46 | AV10: Column47
B11: DN-261020 | D11: GM | E11: A | G11: 46082 | H11: 1845.17 | I11: 98.61 | J11: 2590.66 | K11: 4B-H | L11: Sp 57 | M11: 30 | N11: 88653 | O11: 67.5 | P11: 7.6 | Q11: 8.7361677 | R11: 1.7351301 | S11: 1.717 | T11: 1.867 | U11: N | V11: D6R+B6T | W11: 8 | X11: 4 | Y11: 2.807 | AE11: 1.714 | AF11: 16.2 | AH11: 1.7131783 | AI11: 1.989 | AJ11: 16.1 | AK11: PR-260003 | AL11: 0.1 | AM11: 101.2328 | AO11: Ok | AQ11: CA-260102 | AS11: =+IF(Table1[[#This Row],[Column40]]="ok",Table1[[#This Row],[Column7]],0) -> 1845.17 | AT11: =+IF(Table1[[#This Row],[Column40]]="No",Table1[[#This Row],[Column7]],0) -> 0 | AU11: =+IF(LEFT(Table1[[#This Row],[Column42]],2)="DN",IF(Table1[[#This Row],[Column40]]="ok","(CA)",_xlfn.CONCAT("(CA)",CHAR(10),"FAIL")),"") | AV11: =+IF(Table1[[#This Row],[Column6]]=0,"",_xlfn.CONCAT("Sem ",WEEKNUM(Table1[[#This Row],[Column6]],2))) -> Sem 9
B12: CA-260102 | D12: GM | E12: A | G12: 46082 | H12: 1845.17 | I12: 98.61 | J12: 2590.66 | K12: 4B-H | L12: Sp 57 | M12: 15 | P12: 7.6181873 | R12: 1.7292599 | T12: 1.8609981 | U12: S | V12: D6R+B6T | W12: 6 | X12: 8 | Z12: N° 16 | AA12: 98.614875 | AB12: 76.96477 | AC12: 35.350798 | AD12: 13.158687 | AE12: 1.714 | AF12: 16.2 | AG12: PR-260003 | AH12: 1.7130556 | AI12: 1.988715 | AJ12: 16.091677 | AK12: PR-260003 | AL12: 0.10832328 | AM12: 100.89031 | AO12: OK | AP12: 0 | AQ12: DN-261020 | AS12: =+IF(Table1[[#This Row],[Column40]]="ok",Table1[[#This Row],[Column7]],0) -> 1845.17 | AT12: =+IF(Table1[[#This Row],[Column40]]="No",Table1[[#This Row],[Column7]],0) -> 0 | AU12: =+IF(LEFT(Table1[[#This Row],[Column42]],2)="DN",IF(Table1[[#This Row],[Column40]]="ok","(CA)",_xlfn.CONCAT("(CA)",CHAR(10),"FAIL")),"") -> (CA) | AV12: =+IF(Table1[[#This Row],[Column6]]=0,"",_xlfn.CONCAT("Sem ",WEEKNUM(Table1[[#This Row],[Column6]],2))) -> Sem 9
B13: DN-261021 | D13: GM | E13: A | G13: 46082 | H13: 1769.33 | I13: 111.15 | J13: 2601.52 | K13: 4B-H | L13: Sp 54 | M13: 30 | N13: 88653 | O13: 67.5 | P13: 8.8 | Q13: 8.87471 | R13: 1.7251838 | S13: 1.724 | T13: 1.877 | U13: N | V13: D6R+B6T | W13: 8 | X13: 4 | Y13: 2.807 | AE13: 1.717 | AF13: 0 | AK13: PR-260031 | AM13: 100.47664 | AO13: Ok | AQ13: 0 | AS13: =+IF(Table1[[#This Row],[Column40]]="ok",Table1[[#This Row],[Column7]],0) -> 1769.33 | AT13: =+IF(Table1[[#This Row],[Column40]]="No",Table1[[#This Row],[Column7]],0) -> 0 | AU13: =+IF(LEFT(Table1[[#This Row],[Column42]],2)="DN",IF(Table1[[#This Row],[Column40]]="ok","(CA)",_xlfn.CONCAT("(CA)",CHAR(10),"FAIL")),"") | AV13: =+IF(Table1[[#This Row],[Column6]]=0,"",_xlfn.CONCAT("Sem ",WEEKNUM(Table1[[#This Row],[Column6]],2))) -> Sem 9
B14: DN-261022 | D14: GM | E14: A | G14: 46082 | H14: 1700.27 | I14: 129.83 | J14: 2604.08 | K14: 4A-H | L14: Sp 51 | M14: 30 | N14: 88653 | O14: 67.5 | P14: 10.5 | Q14: 10.152284 | R14: 1.7674208 | S14: 1.773 | T14: 1.953 | U14: N | V14: D6R+B6T | W14: 8 | X14: 4 | Y14: 2.807 | AE14: 1.717 | AF14: 0 | AK14: PR-260031 | AM14: 102.93656 | AO14: Ok | AQ14: 0 | AS14: =+IF(Table1[[#This Row],[Column40]]="ok",Table1[[#This Row],[Column7]],0) -> 1700.27 | AT14: =+IF(Table1[[#This Row],[Column40]]="No",Table1[[#This Row],[Column7]],0) -> 0 | AU14: =+IF(LEFT(Table1[[#This Row],[Column42]],2)="DN",IF(Table1[[#This Row],[Column40]]="ok","(CA)",_xlfn.CONCAT("(CA)",CHAR(10),"FAIL")),"") | AV14: =+IF(Table1[[#This Row],[Column6]]=0,"",_xlfn.CONCAT("Sem ",WEEKNUM(Table1[[#This Row],[Column6]],2))) -> Sem 9
B15: DN-261023 | D15: GM | E15: A | G15: 46082 | H15: 1723.48 | I15: 209.82 | J15: 2578.96 | K15: 4A-H | L15: Sp 52 | M15: 30 | N15: 88653 | O15: 67.5 | P15: 10.4 | Q15: 9.1967404 | R15: 1.6992754 | S15: 1.718 | T15: 1.876 | U15: N | V15: D6R+B6T | W15: 8 | X15: 4 | Y15: 2.807 | AE15: 1.717 | AK15: PR-260031 | AM15: 98.967697 | AO15: Ok | AQ15: 0 | AS15: =+IF(Table1[[#This Row],[Column40]]="ok",Table1[[#This Row],[Column7]],0) -> 1723.48 | AT15: =+IF(Table1[[#This Row],[Column40]]="No",Table1[[#This Row],[Column7]],0) -> 0 | AU15: =+IF(LEFT(Table1[[#This Row],[Column42]],2)="DN",IF(Table1[[#This Row],[Column40]]="ok","(CA)",_xlfn.CONCAT("(CA)",CHAR(10),"FAIL")),"") | AV15: =+IF(Table1[[#This Row],[Column6]]=0,"",_xlfn.CONCAT("Sem ",WEEKNUM(Table1[[#This Row],[Column6]],2))) -> Sem 9
B16: DN-261024 | D16: GM | E16: A | G16: 46082 | H16: 1801.93 | I16: 190.9 | J16: 2573.74 | K16: 4B-H | L16: Sp 55 | M16: 30 | N16: 88653 | O16: 67.5 | P16: 15.9 | Q16: 13.847013 | R16: 1.7592752 | S16: 1.791 | T16: 2.039 | U16: N | V16: D6R+B6T | W16: 8 | X16: 4 | Y16: 2.807 | AE16: 1.717 | AF16: 0 | AK16: PR-260031 | AM16: 102.46216 | AO16: Ok | AQ16: 0 | AS16: =+IF(Table1[[#This Row],[Column40]]="ok",Table1[[#This Row],[Column7]],0) -> 1801.93 | AT16: =+IF(Table1[[#This Row],[Column40]]="No",Table1[[#This Row],[Column7]],0) -> 0 | AU16: =+IF(LEFT(Table1[[#This Row],[Column42]],2)="DN",IF(Table1[[#This Row],[Column40]]="ok","(CA)",_xlfn.CONCAT("(CA)",CHAR(10),"FAIL")),"") | AV16: =+IF(Table1[[#This Row],[Column6]]=0,"",_xlfn.CONCAT("Sem ",WEEKNUM(Table1[[#This Row],[Column6]],2))) -> Sem 9
B17: DN-261025 | D17: GM | E17: A | G17: 46082 | H17: 1886.67 | I17: 167.36 | J17: 2571.16 | K17: 4B-H | L17: Sp 59 | M17: 30 | N17: 88653 | O17: 67.5 | P17: 7 | Q17: 8.4872979 | R17: 1.7560748 | S17: 1.732 | T17: 1.879 | U17: N | V17: D6R+B6T | W17: 8 | X17: 4 | Y17: 2.807 | AE17: 1.717 | AF17: 0 | AK17: PR-260031 | AM17: 102.27576 | AO17: Ok | AQ17: 0 | AS17: =+IF(Table1[[#This Row],[Column40]]="ok",Table1[[#This Row],[Column7]],0) -> 1886.67 | AT17: =+IF(Table1[[#This Row],[Column40]]="No",Table1[[#This Row],[Column7]],0) -> 0 | AU17: =+IF(LEFT(Table1[[#This Row],[Column42]],2)="DN",IF(Table1[[#This Row],[Column40]]="ok","(CA)",_xlfn.CONCAT("(CA)",CHAR(10),"FAIL")),"") | AV17: =+IF(Table1[[#This Row],[Column6]]=0,"",_xlfn.CONCAT("Sem ",WEEKNUM(Table1[[#This Row],[Column6]],2))) -> Sem 9
B18: DN-261026 | D18: GM | E18: A | G18: 46082 | H18: 1827.54 | I18: 252.76 | J18: 2555.87 | K18: 4B-M | L18: Sp 56 | M18: 30 | N18: 88653 | O18: 67.5 | P18: 10.7 | Q18: 10.075275 | R18: 1.7172538 | S18: 1.727 | T18: 1.901 | U18: N | V18: D6R+B6T | W18: 8 | X18: 4 | Y18: 2.807 | AE18: 1.717 | AF18: 0 | AK18: PR-260031 | AM18: 100.01478 | AO18: Ok | AQ18: 0 | AS18: =+IF(Table1[[#This Row],[Column40]]="ok",Table1[[#This Row],[Column7]],0) -> 1827.54 | AT18: =+IF(Table1[[#This Row],[Column40]]="No",Table1[[#This Row],[Column7]],0) -> 0 | AU18: =+IF(LEFT(Table1[[#This Row],[Column42]],2)="DN",IF(Table1[[#This Row],[Column40]]="ok","(CA)",_xlfn.CONCAT("(CA)",CHAR(10),"FAIL")),"") | AV18: =+IF(Table1[[#This Row],[Column6]]=0,"",_xlfn.CONCAT("Sem ",WEEKNUM(Table1[[#This Row],[Column6]],2))) -> Sem 9
B19: DN-261027 | D19: GM | E19: A | G19: 46082 | H19: 1761.91 | I19: 252.76 | J19: 2563.96 | K19: 4B-M | L19: Sp 54 | M19: 30 | N19: 88653 | O19: 67.5 | P19: 9.1 | Q19: 9.4903339 | R19: 1.7131072 | S19: 1.707 | T19: 1.869 | U19: N | V19: D6R+B6T | W19: 8 | X19: 4 | Y19: 2.807 | AE19: 1.717 | AF19: 16.3 | AH19: 1.7157623 | AI19: 1.992 | AJ19: 16.1 | AK19: PR-260031 | AL19: 0.2 | AM19: 99.773281 | AO19: Ok | AQ19: 0 | AS19: =+IF(Table1[[#This Row],[Column40]]="ok",Table1[[#This Row],[Column7]],0) -> 1761.91 | AT19: =+IF(Table1[[#This Row],[Column40]]="No",Table1[[#This Row],[Column7]],0) -> 0 | AU19: =+IF(LEFT(Table1[[#This Row],[Column42]],2)="DN",IF(Table1[[#This Row],[Column40]]="ok","(CA)",_xlfn.CONCAT("(CA)",CHAR(10),"FAIL")),"") | AV19: =+IF(Table1[[#This Row],[Column6]]=0,"",_xlfn.CONCAT("Sem ",WEEKNUM(Table1[[#This Row],[Column6]],2))) -> Sem 9
B20: DN-261028 | D20: GM | E20: A | G20: 46082 | H20: 1614.85 | I20: 155.49 | J20: 2597.06 | K20: 3C-H | L20: Sp 49 | M20: 30 | N20: 88653 | O20: 67.5 | P20: 10.8 | Q20: 9.9360837 | R20: 1.7075812 | S20: 1.721 | T20: 1.892 | U20: N | V20: D6R+B6T | W20: 8 | X20: 4 | Y20: 2.807 | AE20: 1.717 | AF20: 0 | AK20: PR-260031 | AM20: 99.45144 | AO20: Ok | AQ20: 0 | AS20: =+IF(Table1[[#This Row],[Column40]]="ok",Table1[[#This Row],[Column7]],0) -> 1614.85 | AT20: =+IF(Table1[[#This Row],[Column40]]="No",Table1[[#This Row],[Column7]],0) -> 0 | AU20: =+IF(LEFT(Table1[[#This Row],[Column42]],2)="DN",IF(Table1[[#This Row],[Column40]]="ok","(CA)",_xlfn.CONCAT("(CA)",CHAR(10),"FAIL")),"") | AV20: =+IF(Table1[[#This Row],[Column6]]=0,"",_xlfn.CONCAT("Sem ",WEEKNUM(Table1[[#This Row],[Column6]],2))) -> Sem 9
B21: DN-261029 | D21: GM | E21: A | G21: 46082 | H21: 1618.5 | I21: 238.34 | J21: 2571.8 | K21: 3C-H | L21: Sp 49 | M21: 30 | N21: 88653 | O21: 67.5 | P21: 9.4 | Q21: 9.3841642 | R21: 1.7047532 | S21: 1.705 | T21: 1.865 | U21: N | V21: D6R+B6T | W21: 8 | X21: 4 | Y21: 2.807 | AE21: 1.724 | AF21: 16.1 | AH21: 1.7226529 | AI21: 2 | AJ21: 16.1 | AK21: PR-260010 | AL21: 0 | AM21: 98.883596 | AO21: Ok | AQ21: 0 | AS21: =+IF(Table1[[#This Row],[Column40]]="ok",Table1[[#This Row],[Column7]],0) -> 1618.5 | AT21: =+IF(Table1[[#This Row],[Column40]]="No",Table1[[#This Row],[Column7]],0) -> 0 | AU21: =+IF(LEFT(Table1[[#This Row],[Column42]],2)="DN",IF(Table1[[#This Row],[Column40]]="ok","(CA)",_xlfn.CONCAT("(CA)",CHAR(10),"FAIL")),"") | AV21: =+IF(Table1[[#This Row],[Column6]]=0,"",_xlfn.CONCAT("Sem ",WEEKNUM(Table1[[#This Row],[Column6]],2))) -> Sem 9
B22: DN-261030 | D22: GM | E22: A | G22: 46082 | H22: 661.66 | I22: 45.54 | J22: 2635.6 | K22: 2A-H | L22: Plataforma | M22: 30 | N22: 88653 | O22: 67.5 | P22: 8.2 | Q22: 9.1514143 | R22: 1.818854 | S22: 1.803 | T22: 1.968 | U22: N | V22: B13T | W22: 4 | X22: 2 | Y22: 2.807 | AE22: 1.737 | AF22: 16.2 | AH22: 1.7358003 | AI22: 2.017 | AJ22: 16.2 | AK22: PR-260015 | AL22: 0 | AM22: 104.71238 | AO22: Ok | AQ22: CA-260103 | AS22: =+IF(Table1[[#This Row],[Column40]]="ok",Table1[[#This Row],[Column7]],0) -> 661.66 | AT22: =+IF(Table1[[#This Row],[Column40]]="No",Table1[[#This Row],[Column7]],0) -> 0 | AU22: =+IF(LEFT(Table1[[#This Row],[Column42]],2)="DN",IF(Table1[[#This Row],[Column40]]="ok","(CA)",_xlfn.CONCAT("(CA)",CHAR(10),"FAIL")),"") | AV22: =+IF(Table1[[#This Row],[Column6]]=0,"",_xlfn.CONCAT("Sem ",WEEKNUM(Table1[[#This Row],[Column6]],2))) -> Sem 9
B23: CA-260103 | D23: GM | E23: A1 | G23: 46082 | H23: 661.66 | I23: 45.54 | J23: 2635.6 | K23: 2A-H | L23: Plataforma | M23: 15 | P23: 8.2290363 | R23: 1.7630156 | T23: 1.9080948 | U23: S | V23: B13T | W23: 4/4 | X23: 4 | Z23: N° 16 | AA23: 98.998748 | AB23: 77.377972 | AC23: 35.294118 | AD23: 11.98373 | AE23: 1.737 | AF23: 16.2 | AG23: PR-260015 | AH23: 1.7362511 | AI23: 2.0174598 | AJ23: 16.196319 | AK23: PR-260015 | AL23: 0.0036809816 | AM23: 101.49773 | AO23: OK | AP23: 0 | AQ23: DN-261030 | AS23: =+IF(Table1[[#This Row],[Column40]]="ok",Table1[[#This Row],[Column7]],0) -> 661.66 | AT23: =+IF(Table1[[#This Row],[Column40]]="No",Table1[[#This Row],[Column7]],0) -> 0 | AU23: =+IF(LEFT(Table1[[#This Row],[Column42]],2)="DN",IF(Table1[[#This Row],[Column40]]="ok","(CA)",_xlfn.CONCAT("(CA)",CHAR(10),"FAIL")),"") -> (CA) | AV23: =+IF(Table1[[#This Row],[Column6]]=0,"",_xlfn.CONCAT("Sem ",WEEKNUM(Table1[[#This Row],[Column6]],2))) -> Sem 9
B24: DN-261031 | D24: GM | E24: B | G24: 46082 | H24: 1548.05 | I24: 138.03 | J24: 2604.431 | K24: 3C-H | L24: Sp 47 | M24: 30 | N24: 88653 | O24: 67.5 | P24: 8.6 | Q24: 7.1054164 | R24: 1.6933702 | S24: 1.717 | T24: 1.839 | U24: N | V24: D6R+B6T | W24: 8 | X24: 4 | Y24: 2.807 | AE24: 1.717 | AK24: PR-260031 | AM24: 98.623772 | AO24: Ok | AS24: =+IF(Table1[[#This Row],[Column40]]="ok",Table1[[#This Row],[Column7]],0) -> 1548.05 | AT24: =+IF(Table1[[#This Row],[Column40]]="No",Table1[[#This Row],[Column7]],0) -> 0 | AU24: =+IF(LEFT(Table1[[#This Row],[Column42]],2)="DN",IF(Table1[[#This Row],[Column40]]="ok","(CA)",_xlfn.CONCAT("(CA)",CHAR(10),"FAIL")),"") | AV24: =+IF(Table1[[#This Row],[Column6]]=0,"",_xlfn.CONCAT("Sem ",WEEKNUM(Table1[[#This Row],[Column6]],2))) -> Sem 9
B25: DN-261032 | D25: GM | E25: B | G25: 46082 | H25: 1470.97 | I25: 109.77 | J25: 2612.439 | K25: 3C-H | L25: Sp 45 | M25: 30 | N25: 88653 | O25: 67.5 | P25: 10.1 | Q25: 9.4393593 | R25: 1.7375114 | S25: 1.748 | T25: 1.913 | U25: N | V25: D6R+B6T | W25: 8 | X25: 4 | Y25: 2.807 | AE25: 1.717 | AF25: 0 | AK25: PR-260031 | AM25: 101.1946 | AO25: Ok | AS25: =+IF(Table1[[#This Row],[Column40]]="ok",Table1[[#This Row],[Column7]],0) -> 1470.97 | AT25: =+IF(Table1[[#This Row],[Column40]]="No",Table1[[#This Row],[Column7]],0) -> 0 | AU25: =+IF(LEFT(Table1[[#This Row],[Column42]],2)="DN",IF(Table1[[#This Row],[Column40]]="ok","(CA)",_xlfn.CONCAT("(CA)",CHAR(10),"FAIL")),"") | AV25: =+IF(Table1[[#This Row],[Column6]]=0,"",_xlfn.CONCAT("Sem ",WEEKNUM(Table1[[#This Row],[Column6]],2))) -> Sem 9
B26: DN-261033 | D26: GM | E26: B | G26: 46082 | H26: 1475.25 | I26: 190.77 | J26: 2589.265 | K26: 3C-H | L26: Sp 45 | M26: 30 | N26: 88653 | O26: 67.5 | P26: 8 | Q26: 8.8719154 | R26: 1.7157407 | S26: 1.702 | T26: 1.853 | U26: N | V26: D6R+B6T | W26: 8 | X26: 4 | Y26: 2.807 | AE26: 1.731 | AF26: 16.3 | AH26: 1.7185886 | AI26: 1.997 | AJ26: 16.2 | AK26: PR-260029 | AL26: 0.1 | AM26: 99.118471 | AO26: Ok | AS26: =+IF(Table1[[#This Row],[Column40]]="ok",Table1[[#This Row],[Column7]],0) -> 1475.25 | AT26: =+IF(Table1[[#This Row],[Column40]]="No",Table1[[#This Row],[Column7]],0) -> 0 | AU26: =+IF(LEFT(Table1[[#This Row],[Column42]],2)="DN",IF(Table1[[#This Row],[Column40]]="ok","(CA)",_xlfn.CONCAT("(CA)",CHAR(10),"FAIL")),"") | AV26: =+IF(Table1[[#This Row],[Column6]]=0,"",_xlfn.CONCAT("Sem ",WEEKNUM(Table1[[#This Row],[Column6]],2))) -> Sem 9
B27: DN-261034 | D27: GM | E27: B | G27: 46082 | H27: 1541.25 | I27: 219.06 | J27: 2580.76 | K27: 3C-H | L27: Sp 47 | M27: 30 | N27: 88653 | O27: 67.5 | P27: 8.7 | Q27: 8.7260035 | R27: 1.7194112 | S27: 1.719 | T27: 1.869 | U27: N | V27: D6R+B6T | W27: 8 | X27: 4 | Y27: 2.807 | AE27: 1.717 | AK27: PR-260031 | AM27: 100.14043 | AO27: Ok | AS27: =+IF(Table1[[#This Row],[Column40]]="ok",Table1[[#This Row],[Column7]],0) -> 1541.25 | AT27: =+IF(Table1[[#This Row],[Column40]]="No",Table1[[#This Row],[Column7]],0) -> 0 | AU27: =+IF(LEFT(Table1[[#This Row],[Column42]],2)="DN",IF(Table1[[#This Row],[Column40]]="ok","(CA)",_xlfn.CONCAT("(CA)",CHAR(10),"FAIL")),"") | AV27: =+IF(Table1[[#This Row],[Column6]]=0,"",_xlfn.CONCAT("Sem ",WEEKNUM(Table1[[#This Row],[Column6]],2))) -> Sem 9
B28: DN-261035 | D28: GM | E28: B | G28: 46082 | H28: 1571.96 | I28: 262.55 | J28: 2566.955 | K28: 3C-M | L28: Sp 48 | M28: 30 | N28: 88653 | O28: 67.5 | P28: 7.7 | Q28: 7.9512478 | R28: 1.7270195 | S28: 1.723 | T28: 1.86 | U28: N | V28: D6R+B6T | W28: 8 | X28: 4 | Y28: 2.807 | AE28: 1.717 | AF28: 0 | AK28: PR-260031 | AM28: 100.58355 | AO28: Ok | AS28: =+IF(Table1[[#This Row],[Column40]]="ok",Table1[[#This Row],[Column7]],0) -> 1571.96 | AT28: =+IF(Table1[[#This Row],[Column40]]="No",Table1[[#This Row],[Column7]],0) -> 0 | AU28: =+IF(LEFT(Table1[[#This Row],[Column42]],2)="DN",IF(Table1[[#This Row],[Column40]]="ok","(CA)",_xlfn.CONCAT("(CA)",CHAR(10),"FAIL")),"") | AV28: =+IF(Table1[[#This Row],[Column6]]=0,"",_xlfn.CONCAT("Sem ",WEEKNUM(Table1[[#This Row],[Column6]],2))) -> Sem 9
B29: DN-261036 | D29: GM | E29: B | G29: 46082 | H29: 1764.3 | I29: -45.39 | J29: 2635.217 | K29: 4B-H | L29: Sp 54 | M29: 30 | N29: 88653 | O29: 67.5 | P29: 16.2 | Q29: 17.275943 | R29: 1.711704 | S29: 1.696 | T29: 1.989 | U29: N | V29: B3.3T | W29: 12 | X29: 6 | Y29: 2.807 | AE29: 1.684 | AF29: 16.8 | AH29: 1.6772532 | AI29: 1.954 | AJ29: 16.5 | AK29: PRM-1562 | AL29: 0.3 | AM29: 101.64513 | AO29: Ok | AS29: =+IF(Table1[[#This Row],[Column40]]="ok",Table1[[#This Row],[Column7]],0) -> 1764.3 | AT29: =+IF(Table1[[#This Row],[Column40]]="No",Table1[[#This Row],[Column7]],0) -> 0 | AU29: =+IF(LEFT(Table1[[#This Row],[Column42]],2)="DN",IF(Table1[[#This Row],[Column40]]="ok","(CA)",_xlfn.CONCAT("(CA)",CHAR(10),"FAIL")),"") | AV29: =+IF(Table1[[#This Row],[Column6]]=0,"",_xlfn.CONCAT("Sem ",WEEKNUM(Table1[[#This Row],[Column6]],2))) -> Sem 9
B30: DN-261037 | D30: GM | E30: A | G30: 46083 | H30: 661.38 | I30: 24.75 | J30: 2635.6 | K30: 2A-H | L30: P.46 OF | M30: 30 | N30: 88653 | O30: 67.5 | P30: 8.9 | Q30: 9.212828 | R30: 1.7199265 | S30: 1.715 | T30: 1.873 | U30: N | V30: B7T | W30: 6 | X30: 3 | Y30: 2.807 | AE30: 1.717 | AF30: 16.3 | AH30: 1.7128117 | AI30: 1.992 | AJ30: 16.3 | AK30: PR-260031 | AL30: 0 | AM30: 100.17044 | AO30: Ok | AQ30: 0 | AS30: =+IF(Table1[[#This Row],[Column40]]="ok",Table1[[#This Row],[Column7]],0) -> 661.38 | AT30: =+IF(Table1[[#This Row],[Column40]]="No",Table1[[#This Row],[Column7]],0) -> 0 | AU30: =+IF(LEFT(Table1[[#This Row],[Column42]],2)="DN",IF(Table1[[#This Row],[Column40]]="ok","(CA)",_xlfn.CONCAT("(CA)",CHAR(10),"FAIL")),"") | AV30: =+IF(Table1[[#This Row],[Column6]]=0,"",_xlfn.CONCAT("Sem ",WEEKNUM(Table1[[#This Row],[Column6]],2))) -> Sem 10
B31: DN-261038 | D31: GM | E31: A | G31: 46083 | H31: 661 | I31: 18.19 | J31: 2635.6 | K31: 2A-H | L31: SA-OF | M31: 30 | N31: 88653 | O31: 67.5 | P31: 8.5 | Q31: 9.0079818 | R31: 1.762212 | S31: 1.754 | T31: 1.912 | U31: N | V31: B13T(*) | W31: 6 | X31: 3 | Y31: 2.807 | AE31: 1.74 | AF31: 0 | AK31: PRM-1565 | AM31: 101.27655 | AO31: Ok | AQ31: 0 | AS31: =+IF(Table1[[#This Row],[Column40]]="ok",Table1[[#This Row],[Column7]],0) -> 661 | AT31: =+IF(Table1[[#This Row],[Column40]]="No",Table1[[#This Row],[Column7]],0) -> 0 | AU31: =+IF(LEFT(Table1[[#This Row],[Column42]],2)="DN",IF(Table1[[#This Row],[Column40]]="ok","(CA)",_xlfn.CONCAT("(CA)",CHAR(10),"FAIL")),"") | AV31: =+IF(Table1[[#This Row],[Column6]]=0,"",_xlfn.CONCAT("Sem ",WEEKNUM(Table1[[#This Row],[Column6]],2))) -> Sem 10
B32: DN-261039 | D32: GM | E32: A | G32: 46083 | H32: 660.94 | I32: 84.9 | J32: 2635.54 | K32: 2A-H | L32: SA-UF | M32: 30 | N32: 88653 | O32: 67.5 | P32: 8.5 | Q32: 8.2758621 | R32: 1.7364055 | S32: 1.74 | T32: 1.884 | U32: N | V32: B13T(*) | W32: 6 | X32: 3 | Y32: 2.807 | AE32: 1.74 | AK32: PRM-1565 | AM32: 99.793421 | AO32: Ok | AQ32: 0 | AS32: =+IF(Table1[[#This Row],[Column40]]="ok",Table1[[#This Row],[Column7]],0) -> 660.94 | AT32: =+IF(Table1[[#This Row],[Column40]]="No",Table1[[#This Row],[Column7]],0) -> 0 | AU32: =+IF(LEFT(Table1[[#This Row],[Column42]],2)="DN",IF(Table1[[#This Row],[Column40]]="ok","(CA)",_xlfn.CONCAT("(CA)",CHAR(10),"FAIL")),"") | AV32: =+IF(Table1[[#This Row],[Column6]]=0,"",_xlfn.CONCAT("Sem ",WEEKNUM(Table1[[#This Row],[Column6]],2))) -> Sem 10
B33: DN-261040 | D33: GM | E33: A | G33: 46083 | H33: 818.24 | I33: 19.36 | J33: 2635.61 | K33: 2B-H | L33: P.76 UF | M33: 30 | N33: 88653 | O33: 67.5 | P33: 10.4 | Q33: 9.2677346 | R33: 1.7300725 | S33: 1.748 | T33: 1.91 | U33: N | V33: B7T | W33: 6 | X33: 3 | Y33: 2.807 | AE33: 1.717 | AF33: 16.3 | AH33: 1.7160069 | AI33: 1.994 | AJ33: 16.2 | AK33: PR-260031 | AL33: 0.1 | AM33: 100.76135 | AO33: Ok | AQ33: CA-260104 | AS33: =+IF(Table1[[#This Row],[Column40]]="ok",Table1[[#This Row],[Column7]],0) -> 818.24 | AT33: =+IF(Table1[[#This Row],[Column40]]="No",Table1[[#This Row],[Column7]],0) -> 0 | AU33: =+IF(LEFT(Table1[[#This Row],[Column42]],2)="DN",IF(Table1[[#This Row],[Column40]]="ok","(CA)",_xlfn.CONCAT("(CA)",CHAR(10),"FAIL")),"") | AV33: =+IF(Table1[[#This Row],[Column6]]=0,"",_xlfn.CONCAT("Sem ",WEEKNUM(Table1[[#This Row],[Column6]],2))) -> Sem 10
B34: CA-260104 | D34: GM | E34: A | G34: 46083 | H34: 818.24 | I34: 19.36 | J34: 2635.61 | K34: 2B-H | L34: P.76 UF | M34: 15 | P34: 10.364814 | R34: 1.7072373 | T34: 1.8841892 | U34: S | V34: B7T | W34: 4/4 | X34: 6 | Z34: N° 16 | AA34: 98.772588 | AB34: 72.690078 | AC34: 29.526083 | AD34: 10.398909 | AE34: 1.717 | AF34: 16.3 | AG34: PR-260031 | AH34: 1.7157619 | AI34: 1.9940381 | AJ34: 16.21881 | AK34: PR-260031 | AL34: 0.081190019 | AM34: 99.431407 | AO34: OK | AP34: 0 | AQ34: DN-261040 | AS34: =+IF(Table1[[#This Row],[Column40]]="ok",Table1[[#This Row],[Column7]],0) -> 818.24 | AT34: =+IF(Table1[[#This Row],[Column40]]="No",Table1[[#This Row],[Column7]],0) -> 0 | AU34: =+IF(LEFT(Table1[[#This Row],[Column42]],2)="DN",IF(Table1[[#This Row],[Column40]]="ok","(CA)",_xlfn.CONCAT("(CA)",CHAR(10),"FAIL")),"") -> (CA) | AV34: =+IF(Table1[[#This Row],[Column6]]=0,"",_xlfn.CONCAT("Sem ",WEEKNUM(Table1[[#This Row],[Column6]],2))) -> Sem 10
B35: DN-261041 | D35: GM | E35: A | G35: 46083 | H35: 810.7 | I35: 25.16 | J35: 2635.55 | K35: 2B-H | L35: SA-UF | M35: 30 | N35: 88653 | O35: 67.5 | P35: 8.2 | Q35: 9.5048378 | R35: 1.7781885 | S35: 1.757 | T35: 1.924 | U35: N | V35: B13T(*) | W35: 6 | X35: 3 | Y35: 2.807 | AE35: 1.74 | AF35: 0 | AK35: PRM-1565 | AM35: 102.19474 | AO35: Ok | AQ35: 0 | AS35: =+IF(Table1[[#This Row],[Column40]]="ok",Table1[[#This Row],[Column7]],0) -> 810.7 | AT35: =+IF(Table1[[#This Row],[Column40]]="No",Table1[[#This Row],[Column7]],0) -> 0 | AU35: =+IF(LEFT(Table1[[#This Row],[Column42]],2)="DN",IF(Table1[[#This Row],[Column40]]="ok","(CA)",_xlfn.CONCAT("(CA)",CHAR(10),"FAIL")),"") | AV35: =+IF(Table1[[#This Row],[Column6]]=0,"",_xlfn.CONCAT("Sem ",WEEKNUM(Table1[[#This Row],[Column6]],2))) -> Sem 10
B36: DN-261042 | D36: GM | E36: A | G36: 46083 | H36: 998.8 | I36: -30.77 | J36: 2635.6 | K36: 2C-H | L36: SA-OF | M36: 30 | N36: 88653 | O36: 67.5 | P36: 6.2 | Q36: 7.6484018 | R36: 1.7758945 | S36: 1.752 | T36: 1.886 | U36: N | V36: B13T(*) | W36: 6 | X36: 3 | Y36: 2.807 | AE36: 1.74 | AK36: PRM-1565 | AM36: 102.0629 | AO36: Ok | AQ36: 0 | AS36: =+IF(Table1[[#This Row],[Column40]]="ok",Table1[[#This Row],[Column7]],0) -> 998.8 | AT36: =+IF(Table1[[#This Row],[Column40]]="No",Table1[[#This Row],[Column7]],0) -> 0 | AU36: =+IF(LEFT(Table1[[#This Row],[Column42]],2)="DN",IF(Table1[[#This Row],[Column40]]="ok","(CA)",_xlfn.CONCAT("(CA)",CHAR(10),"FAIL")),"") | AV36: =+IF(Table1[[#This Row],[Column6]]=0,"",_xlfn.CONCAT("Sem ",WEEKNUM(Table1[[#This Row],[Column6]],2))) -> Sem 10
B37: DN-261043 | D37: GT | E37: B | G37: 46083 | H37: 1135.97 | I37: 62.23 | J37: 2626.19 | K37: 3A-H | L37: Sp 35 | M37: 30 | N37: 88653 | O37: 55.75 | P37: 11.2 | Q37: 12.116041 | R37: 1.772482 | S37: 1.758 | T37: 1.971 | U37: N | V37: D6R+B6T | W37: 8 | X37: 4 | Y37: 2.807 | AE37: 1.721 | AK37: PRM-1566 | AM37: 102.9914 | AO37: Ok | AS37: =+IF(Table1[[#This Row],[Column40]]="ok",Table1[[#This Row],[Column7]],0) -> 1135.97 | AT37: =+IF(Table1[[#This Row],[Column40]]="No",Table1[[#This Row],[Column7]],0) -> 0 | AU37: =+IF(LEFT(Table1[[#This Row],[Column42]],2)="DN",IF(Table1[[#This Row],[Column40]]="ok","(CA)",_xlfn.CONCAT("(CA)",CHAR(10),"FAIL")),"") | AV37: =+IF(Table1[[#This Row],[Column6]]=0,"",_xlfn.CONCAT("Sem ",WEEKNUM(Table1[[#This Row],[Column6]],2))) -> Sem 10
B38: DN-261044 | D38: GT | E38: B | G38: 46083 | H38: 1244.03 | I38: 54.69 | J38: 2628.41 | K38: 3A-H | L38: Sp 38 | M38: 30 | N38: 88653 | O38: 55.75 | P38: 12.4 | Q38: 12.036509 | R38: 1.747331 | S38: 1.753 | T38: 1.964 | U38: N | V38: D6R+B6T | W38: 8 | X38: 4 | Y38: 2.807 | AE38: 1.721 | AF38: 0 | AK38: PRM-1566 | AM38: 101.52998 | AO38: Ok | AS38: =+IF(Table1[[#This Row],[Column40]]="ok",Table1[[#This Row],[Column7]],0) -> 1244.03 | AT38: =+IF(Table1[[#This Row],[Column40]]="No",Table1[[#This Row],[Column7]],0) -> 0 | AU38: =+IF(LEFT(Table1[[#This Row],[Column42]],2)="DN",IF(Table1[[#This Row],[Column40]]="ok","(CA)",_xlfn.CONCAT("(CA)",CHAR(10),"FAIL")),"") | AV38: =+IF(Table1[[#This Row],[Column6]]=0,"",_xlfn.CONCAT("Sem ",WEEKNUM(Table1[[#This Row],[Column6]],2))) -> Sem 10
B39: DN-261045 | D39: GT | E39: B | G39: 46083 | H39: 1245.53 | I39: 120.8 | J39: 2609.94 | K39: 3A-H | L39: Sp 38 | M39: 30 | N39: 88653 | O39: 55.75 | P39: 12.3 | Q39: 11.794582 | R39: 1.7640249 | S39: 1.772 | T39: 1.981 | U39: N | V39: D6R+B6T | W39: 8 | X39: 4 | Y39: 2.807 | AE39: 1.721 | AK39: PRM-1566 | AM39: 102.5 | AO39: Ok | AS39: =+IF(Table1[[#This Row],[Column40]]="ok",Table1[[#This Row],[Column7]],0) -> 1245.53 | AT39: =+IF(Table1[[#This Row],[Column40]]="No",Table1[[#This Row],[Column7]],0) -> 0 | AU39: =+IF(LEFT(Table1[[#This Row],[Column42]],2)="DN",IF(Table1[[#This Row],[Column40]]="ok","(CA)",_xlfn.CONCAT("(CA)",CHAR(10),"FAIL")),"") | AV39: =+IF(Table1[[#This Row],[Column6]]=0,"",_xlfn.CONCAT("Sem ",WEEKNUM(Table1[[#This Row],[Column6]],2))) -> Sem 10
B40: DN-261046 | D40: GT | E40: B | G40: 46083 | H40: 1568.63 | I40: 497.41 | J40: 2499.77 | K40: 3C-M | L40: Contacto | M40: 30 | N40: 88653 | O40: 55.75 | P40: 7.9 | Q40: 7.1880391 | R40: 1.7275255 | S40: 1.739 | T40: 1.864 | U40: N | V40: Plancha 1T/Exc. | W40: 15 | X40: 15 | Y40: 2.807 | AE40: 1.721 | AK40: PRM-1566 | AM40: 100.37917 | AO40: Ok | AS40: =+IF(Table1[[#This Row],[Column40]]="ok",Table1[[#This Row],[Column7]],0) -> 1568.63 | AT40: =+IF(Table1[[#This Row],[Column40]]="No",Table1[[#This Row],[Column7]],0) -> 0 | AU40: =+IF(LEFT(Table1[[#This Row],[Column42]],2)="DN",IF(Table1[[#This Row],[Column40]]="ok","(CA)",_xlfn.CONCAT("(CA)",CHAR(10),"FAIL")),"") | AV40: =+IF(Table1[[#This Row],[Column6]]=0,"",_xlfn.CONCAT("Sem ",WEEKNUM(Table1[[#This Row],[Column6]],2))) -> Sem 10
...

Sheet R Semanal
AJ1: CONTORNO - ABRIL 2025 | AO1: ZONAS | AS1: SUB ZONAS | AW1: CONTORNO CORONA 2025 | AZ1: CONTORNO INTERNO C7 - JULIO 2025
AJ2: 2158.22 | AK2: -148.11 | AL2: 2622.2611 | AN2: Z1 | AO2: 600 | AP2: 42.91 | AQ2: 602 | AR2: Z1 | AS2: 280 | AT2: 35.43 | AU2: 263 | AW2: OVER | AX2: 3.68 | AY2: -11.37 | AZ2: 1523.8 | BA2: 540.03 | BB2: 2483.329
G3: ZONA 1 | L3: ZONA 2 | Q3: ZONA 3 | V3: ZONA 4 | AJ3: 2156.13 | AK3: -144.1 | AL3: 2621.3351 | AO3: 600 | AP3: 540.22 | AS3: 280 | AT3: 340.96 | AX3: 19.07 | AY3: 19.85 | AZ3: 1521.25 | BA3: 543.6 | BB3: 2482.441
AJ4: 2153.64 | AK4: -137.4 | AL4: 2617.537 | AN4: Z2 | AO4: 1120 | AP4: -32.33 | AQ4: 1112 | AS4: 450 | AT4: 39.42 | AU4: 444 | AX4: 41.82 | AY4: 28.33 | AZ4: 1519.23 | BA4: 547.21 | BB4: 2480.901
AJ5: 2150.86 | AK5: -127.17 | AL5: 2615.5033 | AO5: 1120 | AP5: 833.77 | AS5: 450 | AT5: 461.69 | AX5: 64.57 | AY5: 36.81 | AZ5: 1518.16 | BA5: 550.11 | BB5: 2479.626
AJ6: 2148.2 | AK6: -117.2 | AL6: 2614.173 | AN6: Z3 | AO6: 1640 | AP6: -29.33 | AQ6: 1642 | AR6: Z2 | AS6: 780 | AT6: -18 | AU6: 840 | AX6: 87.32 | AY6: 45.29 | AZ6: 1517.41 | BA6: 554.98 | BB6: 2477.547
C7: H (Corona) | AJ7: 2143.61 | AK7: -108.66 | AL7: 2612.175 | AO7: 1640 | AP7: 424.19 | AS7: 780 | AT7: 620 | AX7: 110.08 | AY7: 53.77 | AZ7: 1516.76 | BA7: 558.77 | BB7: 2476.035
AJ8: 2141.06 | AK8: -104.58 | AL8: 2611.0857 | AN8: Z4 | AS8: 940 | AT8: -18 | AU8: 964 | AX8: 132.83 | AY8: 62.25 | AZ8: 1516.77 | BA8: 563.14 | BB8: 2474.266
AJ9: 2138.37 | AK9: -100.41 | AL9: 2610.0435 | AS9: 940 | AT9: 720 | AX9: 155.58 | AY9: 70.73 | AZ9: 1517.11 | BA9: 567.08 | BB9: 2472.845
AJ10: 2133.36 | AK10: -92.26 | AL10: 2608.056 | AR10: Z3 | AS10: 1280 | AT10: -31.16 | AU10: 1292 | AX10: 178.33 | AY10: 79.21 | AZ10: 1517.01 | BA10: 571.83 | BB10: 2471.424
C11: H (50 a 250m) | AJ11: 2132.44 | AK11: -90.25 | AL11: 2607.479 | AS11: 1280 | AT11: 1006.71 | AX11: 205.09 | AY11: 89.19 | AZ11: 1517.9 | BA11: 575.76 | BB11: 2470.129
AJ12: 2129.21 | AK12: -83.94 | AL12: 2605.4326 | AS12: 1460 | AT12: -18 | AU12: 1473 | AX12: 225.08 | AY12: 89.72 | AZ12: 1519.48 | BA12: 580.47 | BB12: 2468.807
AJ13: 2125.04 | AK13: -75.34 | AL13: 2602.6701 | AS13: 1460 | AT13: 780 | AX13: 249.35 | AY13: 90.37 | AZ13: 1521.01 | BA13: 583.49 | BB13: 2468.082
AJ14: 2120.85 | AK14: -67.16 | AL14: 2599.4551 | AR14: Z4 | AS14: 1760 | AT14: -120 | AU14: 1765 | AX14: 273.63 | AY14: 91.03 | AZ14: 1521.97 | BA14: 586.64 | BB14: 2467.502
AJ15: 2118.5 | AK15: -61.28 | AL15: 2596.9969 | AS15: 1760 | AT15: 400 | AX15: 297.9 | AY15: 91.68 | AZ15: 1522.65 | BA15: 592.43 | BB15: 2466.046
AJ16: 2118.17 | AK16: -51.81 | AL16: 2593.3621 | AS16: 1920 | AT16: -200 | AU16: 1932 | AX16: 322.17 | AY16: 92.33 | AZ16: 1521.02 | BA16: 596.09 | BB16: 2464.9821
C17: M (250m a 500m) | AJ17: 2118.59 | AK17: -49.53 | AL17: 2592.5861 | AS17: 1920 | AT17: 310 | AX17: 346.44 | AY17: 92.98 | AZ17: 1518.89 | BA17: 599.85 | BB17: 2464.274
AJ18: 2121.34 | AK18: -40.63 | AL18: 2589.913 | AX18: 370.71 | AY18: 93.63 | AZ18: 1518.06 | BA18: 602.98 | BB18: 2463.104
AJ19: 2124.82 | AK19: -31.94 | AL19: 2587.634 | AX19: 394.98 | AY19: 94.28 | AZ19: 1517.78 | BA19: 607.01 | BB19: 2461.723
AJ20: 2127.99 | AK20: -25.57 | AL20: 2586.1587 | AX20: 419.25 | AY20: 94.93 | AZ20: 1517.38 | BA20: 610.16 | BB20: 2460.652
AJ21: 2129.51 | AK21: -16.77 | AL21: 2584.248 | AX21: 443.52 | AY21: 95.58 | AZ21: 1517.6 | BA21: 614.33 | BB21: 2459.351
G22: ="Ensayos Compactación Semana "&WEEKNUM(N39) -> Ensayos Compactación Semana 15 | AJ22: 2126.6 | AK22: -10.98 | AL22: 2583.224 | AX22: 467.8 | AY22: 96.24 | AZ22: 1517.57 | BA22: 616.86 | BB22: 2458.65
C23: L (500m a 750m) | AJ23: 2122.09 | AK23: -3.08 | AL23: 2581.22 | AX23: 492.07 | AY23: 96.89 | AZ23: 1518.91 | BA23: 619.97 | BB23: 2457.7469
G24: N° Ensayos | H24: DensÍmetro Nuclear | I24: Cono de Arena | J24: % Compact. | AJ24: 2117.84 | AK24: 4.38 | AL24: 2579.4535 | AX24: 516.34 | AY24: 97.54 | AZ24: 1520.29 | BA24: 624.92 | BB24: 2456.65
AJ25: 2113.51 | AK25: 10.09 | AL25: 2578.327 | AX25: 540.61 | AY25: 98.08 | AZ25: 1520.3 | BA25: 632.02 | BB25: 2455.2629
G26: Pasa | H26: =+FCS!I861 -> 628 | I26: =+FCS!K861 -> 63 | J26: =ROUND(+FCS!M861,1) -> 101.6 | AJ26: 2109.77 | AK26: 15.63 | AL26: 2577.204 | AX26: 564.89 | AY26: 98.55 | AZ26: 1520.25 | BA26: 637.57 | BB26: 2454.202
AJ27: 2106.46 | AK27: 20.87 | AL27: 2575.8929 | AX27: 589.16 | AY27: 99.02 | AZ27: 1521.3 | BA27: 644.86 | BB27: 2452.728
G28: Falla | H28: =+FCS!I862 -> 0 | I28: =+FCS!K862 -> 0 | J28: =ROUND(+FCS!M862,1) -> 0 | AJ28: 2103.97 | AK28: 25.86 | AL28: 2574.5861 | AX28: 613.41 | AY28: 98.3 | AZ28: 1521.13 | BA28: 649.69 | BB28: 2451.749
C29: Blanket (750 a 1000m) | AJ29: 2100.09 | AK29: 30.95 | AL29: 2573.286 | AX29: 637.22 | AY29: 93.67 | AZ29: 1519.77 | BA29: 657.08 | BB29: 2450.327
G30: Total | H30: =H26+H28 -> 628 | I30: =I26+I28 -> 63 | J30: =ROUND(+FCS!M863,1) -> 101.6 | AJ30: 2097.66 | AK30: 35.85 | AL30: 2572.123 | AX30: 659.92 | AY30: 85.15 | AZ30: 1519.08 | BA30: 662.8 | BB30: 2449.109
AJ31: 2095.23 | AK31: 41.31 | AL31: 2571.299 | AX31: 680.9 | AY31: 72.99 | AZ31: 1517.72 | BA31: 668.09 | BB31: 2448.1021
AJ32: 2091.08 | AK32: 51.12 | AL32: 2569.295 | AX32: 719.14 | AY32: 43.06 | AZ32: 1515.28 | BA32: 673.04 | BB32: 2447.14
AJ33: 2085.73 | AK33: 60.03 | AL33: 2566.851 | AX33: 741.81 | AY33: 25.13 | AZ33: 1513.08 | BA33: 678.2 | BB33: 2446.1639
AJ34: 2079.28 | AK34: 68.67 | AL34: 2563.749 | AX34: 761.46 | AY34: 25.06 | AZ34: 1511.17 | BA34: 682.92 | BB34: 2445.234
AJ35: 2074.26 | AK35: 80.58 | AL35: 2560.105 | AX35: 785.74 | AY35: 24.97 | AZ35: 1509.46 | BA35: 687.74 | BB35: 2444.058
E36: FECHA: | G36: del | H36: =+UPPER(TEXT(SUBTOTAL(5,Table1[Column6]),"dd-mmm")) -> 01-MAR | J36: al | K36: =+UPPER(TEXT(SUBTOTAL(4,Table1[Column6]),"dd-mmm")) -> 31-MAR | AJ36: 2073.72 | AK36: 89.67 | AL36: 2557.3764 | AX36: 810.02 | AY36: 24.91 | AZ36: 1506.24 | BA36: 693.95 | BB36: 2442.751
E37: ENSAYOS COMPACTACIÓN | Q37: PORCENTAJE DE FALLAS DE COMPACTACION | AJ37: 2074.93 | AK37: 95.49 | AL37: 2555.772 | AX37: 834.3 | AY37: 24.99 | AZ37: 1502.55 | BA37: 699.04 | BB37: 2441.574
E38: N° Ensayos | G38: DensÍmetro Nuclear | I38: Cono de Arena | K38: % Compactación | Q38: Número total de ensayos semanal: | W38: =G40+I40+G41+I41 -> 691 | AJ38: 2078.61 | AK38: 102.78 | AL38: 2553.598 | AX38: 858.58 | AY38: 24.99 | AZ38: 1499.88 | BA38: 702.46 | BB38: 2440.476
N39: =TODAY() -> 46118 | Q39: Número de fallas en la semana: | W39: =G41+I41 -> 0 | AJ39: 2081.79 | AK39: 105.5 | AL39: 2552.847 | AX39: 882.86 | AY39: 24.99 | AZ39: 1495.48 | BA39: 710.11 | BB39: 2437.701
E40: Pasa | G40: =+FCS!I861 -> 628 | I40: =+FCS!K861 -> 63 | K40: =+FCS!M861 -> 101.57144 | N40: =WEEKNUM(N39) -> 15 | Q40: % de fallas en la Semana: | W40: =W39/W38 -> 0 | AJ40: 2087.22 | AK40: 109.94 | AL40: 2552.105 | AX40: 907.14 | AY40: 24.99 | AZ40: 1494.05 | BA40: 714.19 | BB40: 2435.999
...

Sheet RepTopoP1
K2: Valores promedio de la semana filtrada
D3: Hoy | F3: Filtrando | I3: Mensual
B4: Ayer | C4: =D4-1 -> 46117 | D4: =TODAY()-C6 -> 46118 | F4: Desde | G4: =C5+1 -> 46111 | I4: Densidad seca | J4: %Compact | K4: Densidad seca | L4: %Compact
B5: Hace 7 días | C5: =C4-7 -> 46110 | F5: Hasta | G5: =C4 -> 46117 | I5: =ROUND(AVERAGEIF(D16:D815,">0"),3) -> 1.741 | J5: =ROUND(AVERAGEIF(E16:E815,">0"),2) -> 101.59 | K5: =ROUND(AVERAGEIF(F16:F815,">0"),3) -> 1.749 | L5: =ROUND(AVERAGEIF(G16:G815,">0"),2) -> 101.59
B6: Hace X días | C6: =[1]TOPOGRAFIA!$D$7 -> 0 | K6: Contador | L6: Contador
K7: =COUNTIF(F16:F815,">0") -> 51 | L7: =COUNTIF(G16:G815,">0") -> 51
K8: Suma | L8: Suma
K9: =SUM(F15:F1463) -> 89.206008 | L9: =SUM(G15:G1463) -> 5181.3052
B15: Fecha | C15: Verificación | D15: Densidad Seca corr. | E15: %Compact | F15: Filtro DS | G15: Filtro Comp. | H15: Opinión
B16: =FCS!G11 -> 46082 | C16: =IF(AND(B16>$C$5,B16<$D$4,H16="OK"),1,0) -> 0 | D16: =FCS!R11 -> 1.7351301 | E16: =FCS!AM11 -> 101.2328 | F16: =IFERROR(D16*C16,0) -> 0 | G16: =IFERROR(E16*C16,0) -> 0 | H16: =FCS!AO11 -> Ok
B17: =FCS!G12 -> 46082 | C17: =IF(AND(B17>$C$5,B17<$D$4,H17="OK"),1,0) -> 0 | D17: =FCS!R12 -> 1.7292599 | E17: =FCS!AM12 -> 100.89031 | F17: =IFERROR(D17*C17,0) -> 0 | G17: =IFERROR(E17*C17,0) -> 0 | H17: =FCS!AO12 -> OK
B18: =FCS!G13 -> 46082 | C18: =IF(AND(B18>$C$5,B18<$D$4,H18="OK"),1,0) -> 0 | D18: =FCS!R13 -> 1.7251838 | E18: =FCS!AM13 -> 100.47664 | F18: =IFERROR(D18*C18,0) -> 0 | G18: =IFERROR(E18*C18,0) -> 0 | H18: =FCS!AO13 -> Ok
B19: =FCS!G14 -> 46082 | C19: =IF(AND(B19>$C$5,B19<$D$4,H19="OK"),1,0) -> 0 | D19: =FCS!R14 -> 1.7674208 | E19: =FCS!AM14 -> 102.93656 | F19: =IFERROR(D19*C19,0) -> 0 | G19: =IFERROR(E19*C19,0) -> 0 | H19: =FCS!AO14 -> Ok
B20: =FCS!G15 -> 46082 | C20: =IF(AND(B20>$C$5,B20<$D$4,H20="OK"),1,0) -> 0 | D20: =FCS!R15 -> 1.6992754 | E20: =FCS!AM15 -> 98.967697 | F20: =IFERROR(D20*C20,0) -> 0 | G20: =IFERROR(E20*C20,0) -> 0 | H20: =FCS!AO15 -> Ok
B21: =FCS!G16 -> 46082 | C21: =IF(AND(B21>$C$5,B21<$D$4,H21="OK"),1,0) -> 0 | D21: =FCS!R16 -> 1.7592752 | E21: =FCS!AM16 -> 102.46216 | F21: =IFERROR(D21*C21,0) -> 0 | G21: =IFERROR(E21*C21,0) -> 0 | H21: =FCS!AO16 -> Ok
B22: =FCS!G17 -> 46082 | C22: =IF(AND(B22>$C$5,B22<$D$4,H22="OK"),1,0) -> 0 | D22: =FCS!R17 -> 1.7560748 | E22: =FCS!AM17 -> 102.27576 | F22: =IFERROR(D22*C22,0) -> 0 | G22: =IFERROR(E22*C22,0) -> 0 | H22: =FCS!AO17 -> Ok
B23: =FCS!G18 -> 46082 | C23: =IF(AND(B23>$C$5,B23<$D$4,H23="OK"),1,0) -> 0 | D23: =FCS!R18 -> 1.7172538 | E23: =FCS!AM18 -> 100.01478 | F23: =IFERROR(D23*C23,0) -> 0 | G23: =IFERROR(E23*C23,0) -> 0 | H23: =FCS!AO18 -> Ok
B24: =FCS!G19 -> 46082 | C24: =IF(AND(B24>$C$5,B24<$D$4,H24="OK"),1,0) -> 0 | D24: =FCS!R19 -> 1.7131072 | E24: =FCS!AM19 -> 99.773281 | F24: =IFERROR(D24*C24,0) -> 0 | G24: =IFERROR(E24*C24,0) -> 0 | H24: =FCS!AO19 -> Ok
B25: =FCS!G20 -> 46082 | C25: =IF(AND(B25>$C$5,B25<$D$4,H25="OK"),1,0) -> 0 | D25: =FCS!R20 -> 1.7075812 | E25: =FCS!AM20 -> 99.45144 | F25: =IFERROR(D25*C25,0) -> 0 | G25: =IFERROR(E25*C25,0) -> 0 | H25: =FCS!AO20 -> Ok
B26: =FCS!G21 -> 46082 | C26: =IF(AND(B26>$C$5,B26<$D$4,H26="OK"),1,0) -> 0 | D26: =FCS!R21 -> 1.7047532 | E26: =FCS!AM21 -> 98.883596 | F26: =IFERROR(D26*C26,0) -> 0 | G26: =IFERROR(E26*C26,0) -> 0 | H26: =FCS!AO21 -> Ok
B27: =FCS!G22 -> 46082 | C27: =IF(AND(B27>$C$5,B27<$D$4,H27="OK"),1,0) -> 0 | D27: =FCS!R22 -> 1.818854 | E27: =FCS!AM22 -> 104.71238 | F27: =IFERROR(D27*C27,0) -> 0 | G27: =IFERROR(E27*C27,0) -> 0 | H27: =FCS!AO22 -> Ok
... B376: =FCS!G371 -> 46099 | C376: =IF(AND(B376>$C$5,B376<$D$4,H376="OK"),1,0) -> 0 | D376: =FCS!R371 -> 1.6858169 | E376: =FCS!AM371 -> 98.62155 | F376: =IFERROR(D376*C376,0) -> 0 | G376: =IFERROR(E376*C376,0) -> 0 | H376: =FCS!AO371 -> Ok
B377: =FCS!G373 -> 46099 | C377: =IF(AND(B377>$C$5,B377<$D$4,H377="OK"),1,0) -> 0 | D377: =FCS!R373 -> 1.7067899 | E377: =FCS!AM373 -> 99.68114 | F377: =IFERROR(D377*C377,0) -> 0 | G377: =IFERROR(E377*C377,0) -> 0 | H377: =FCS!AO373 -> OK
B378: =FCS!G374 -> 46099 | C378: =IF(AND(B378>$C$5,B378<$D$4,H378="OK"),1,0) -> 0 | D378: =FCS!R374 -> 1.7100271 | E378: =FCS!AM374 -> 100.47163 | F378: =IFERROR(D378*C378,0) -> 0 | G378: =IFERROR(E378*C378,0) -> 0 | H378: =FCS!AO374 -> Ok
B379: =FCS!G375 -> 46099 | C379: =IF(AND(B379>$C$5,B379<$D$4,H379="OK"),1,0) -> 0 | D379: =FCS!R375 -> 1.7735004 | E379: =FCS!AM375 -> 104.20097 | F379: =IFERROR(D379*C379,0) -> 0 | G379: =IFERROR(E379*C379,0) -> 0 | H379: =FCS!AO375 -> Ok
B380: =FCS!G376 -> 46099 | C380: =IF(AND(B380>$C$5,B380<$D$4,H380="OK"),1,0) -> 0 | D380: =FCS!R376 -> 1.7580645 | E380: =FCS!AM376 -> 103.29404 | F380: =IFERROR(D380*C380,0) -> 0 | G380: =IFERROR(E380*C380,0) -> 0 | H380: =FCS!AO376 -> Ok
B381: =FCS!G377 -> 46099 | C381: =IF(AND(B381>$C$5,B381<$D$4,H381="OK"),1,0) -> 0 | D381: =FCS!R377 -> 1.7444543 | E381: =FCS!AM377 -> 102.49438 | F381: =IFERROR(D381*C381,0) -> 0 | G381: =IFERROR(E381*C381,0) -> 0 | H381: =FCS!AO377 -> Ok
B382: =FCS!G378 -> 46099 | C382: =IF(AND(B382>$C$5,B382<$D$4,H382="OK"),1,0) -> 0 | D382: =FCS!R378 -> - | E382: =FCS!AM378 -> - | F382: =IFERROR(D382*C382,0) -> 0 | G382: =IFERROR(E382*C382,0) -> 0 | H382: =FCS!AO378 -> -
B383: =FCS!G379 -> 46100 | C383: =IF(AND(B383>$C$5,B383<$D$4,H383="OK"),1,0) -> 0 | D383: =FCS!R379 -> 1.6976127 | E383: =FCS!AM379 -> 99.742229 | F383: =IFERROR(D383*C383,0) -> 0 | G383: =IFERROR(E383*C383,0) -> 0 | H383: =FCS!AO379 -> Ok
B384: =FCS!G380 -> 46100 | C384: =IF(AND(B384>$C$5,B384<$D$4,H384="OK"),1,0) -> 0 | D384: =FCS!R380 -> 1.7039356 | E384: =FCS!AM380 -> 100.11372 | F384: =IFERROR(D384*C384,0) -> 0 | G384: =IFERROR(E384*C384,0) -> 0 | H384: =FCS!AO380 -> Ok
B385: =FCS!G381 -> 46100 | C385: =IF(AND(B385>$C$5,B385<$D$4,H385="OK"),1,0) -> 0 | D385: =FCS!R381 -> 1.7238422 | E385: =FCS!AM381 -> 101.28333 | F385: =IFERROR(D385*C385,0) -> 0 | G385: =IFERROR(E385*C385,0) -> 0 | H385: =FCS!AO381 -> Ok
B386: =FCS!G382 -> 46100 | C386: =IF(AND(B386>$C$5,B386<$D$4,H386="OK"),1,0) -> 0 | D386: =FCS!R382 -> 1.7212066 | E386: =FCS!AM382 -> 101.12847 | F386: =IFERROR(D386*C386,0) -> 0 | G386: =IFERROR(E386*C386,0) -> 0 | H386: =FCS!AO382 -> Ok
B387: =FCS!G383 -> 46100 | C387: =IF(AND(B387>$C$5,B387<$D$4,H387="OK"),1,0) -> 0 | D387: =FCS!R383 -> - | E387: =FCS!AM383 -> - | F387: =IFERROR(D387*C387,0) -> 0 | G387: =IFERROR(E387*C387,0) -> 0 | H387: =FCS!AO383 -> -
B388: =FCS!G384 -> 46100 | C388: =IF(AND(B388>$C$5,B388<$D$4,H388="OK"),1,0) -> 0 | D388: =FCS!R384 -> 1.7879925 | E388: =FCS!AM384 -> 103.11375 | F388: =IFERROR(D388*C388,0) -> 0 | G388: =IFERROR(E388*C388,0) -> 0 | H388: =FCS!AO384 -> Ok
B389: =FCS!G386 -> 46100 | C389: =IF(AND(B389>$C$5,B389<$D$4,H389="OK"),1,0) -> 0 | D389: =FCS!R386 -> 1.7268723 | E389: =FCS!AM386 -> 99.142272 | F389: =IFERROR(D389*C389,0) -> 0 | G389: =IFERROR(E389*C389,0) -> 0 | H389: =FCS!AO386 -> OK
B390: =FCS!G387 -> 46100 | C390: =IF(AND(B390>$C$5,B390<$D$4,H390="OK"),1,0) -> 0 | D390: =FCS!R387 -> 1.7343608 | E390: =FCS!AM387 -> 101.60286 | F390: =IFERROR(D390*C390,0) -> 0 | G390: =IFERROR(E390*C390,0) -> 0 | H390: =FCS!AO387 -> Ok
B391: =FCS!G388 -> 46100 | C391: =IF(AND(B391>$C$5,B391<$D$4,H391="OK"),1,0) -> 0 | D391: =FCS!R388 -> 1.7543379 | E391: =FCS!AM388 -> 102.77316 | F391: =IFERROR(D391*C391,0) -> 0 | G391: =IFERROR(E391*C391,0) -> 0 | H391: =FCS!AO388 -> Ok
B392: =FCS!G389 -> 46100 | C392: =IF(AND(B392>$C$5,B392<$D$4,H392="OK"),1,0) -> 0 | D392: =FCS!R389 -> 1.733214 | E392: =FCS!AM389 -> 101.53567 | F392: =IFERROR(D392*C392,0) -> 0 | G392: =IFERROR(E392*C392,0) -> 0 | H392: =FCS!AO389 -> Ok
B393: =FCS!G390 -> 46100 | C393: =IF(AND(B393>$C$5,B393<$D$4,H393="OK"),1,0) -> 0 | D393: =FCS!R390 -> 1.70194 | E393: =FCS!AM390 -> 99.703576 | F393: =IFERROR(D393*C393,0) -> 0 | G393: =IFERROR(E393*C393,0) -> 0 | H393: =FCS!AO390 -> Ok
B394: =FCS!G391 -> 46100 | C394: =IF(AND(B394>$C$5,B394<$D$4,H394="OK"),1,0) -> 0 | D394: =FCS!R391 -> 1.7069272 | E394: =FCS!AM391 -> 99.995734 | F394: =IFERROR(D394*C394,0) -> 0 | G394: =IFERROR(E394*C394,0) -> 0 | H394: =FCS!AO391 -> Ok
...

Sheet Sheet1
A1: FIELD COMPACTION SUMMARY
A4: TEST IDENTIFICATION | N4: IN SITU DATA | Y4: LABORATORY TEST DATA | AH4: FIELD AND LABORATORY CORRELATION | AO4: REMARKS
A5: SOURCE (4): CYCLONE STATION
A6: FILL (2): TAILING | P6: Loose lift thickness= | U6: 30 cm | Y6: PROCTOR COMPACTION STANDARD-S (7)
A7: Test No./ code (1) | C7: File No. | D7: Resp. Guar. | E7: Turn | F7: Lift No. | G7: Date | H7: Location | Y7: SPECIFIED COMPACTION: | AC7: 98 | AD7: % | AE7: Proctor Compaction | AH7: One-Point Proctor
H8: Easting | I8: Northing | J8: Elev. | K8: Cancha | L8: Sb/ Sp No. | M8: Depth (cm) | N8: No. Dens | O8: Corr. Moisture | P8: Moisture, % (6) | R8: Dry Density g/cm3 | T8: Wet density Dens | U8: Method (9) | V8: Compactor (5) | W8: Passes | X8: Real Passes | Y8: Specific Gravity | Z8: Max. Particle size | AA8: Percent passing (Control) | AE8: Max. Dry Density | AF8: Optimum Moisture | AG8: Curve Code | AH8: Dry Density | AI8: Wet density | AJ8: Moisture | AK8: Select. Curve | AL8: Moisture | AM8: Compaction % | AO8: Opinion (8) | AP8: Retest from | AQ8: Remarks | AR8: Retest on
A9: MWH-QA | B9: SMCV-QC | O9: k | P9: Oven | Q9: Dens. | R9: Corr. | S9: Dens. | U9: N/S/PR | W9: # | X9: # | Y9: g/cm3 | AA9: No. 30 | AB9: No. 50 | AC9: No. 100 | AD9: No. 200 | AE9: g/cm3 | AF9: % | AH9: g/cm3 | AI9: g/cm3 | AJ9: % | AK9: No. | AL9: +/- | AM9: Pass | AN9: Failure | AU9: A | AV9: B
AT10: =DATE(YEAR(FCS!#REF!),MONTH(FCS!#REF!),1) -> #REF! | AU10: =IFERROR(ROUND(IFERROR(((IFERROR(SUMIFS(FCS!$AM$11:$AM$9931,FCS!$G$11:$G$9931,AT10,FCS!$E$11:$E$9931,$AU$9),""))+(IFERROR(SUMIFS(FCS!$AN$11:$AN$9931,FCS!$G$11:$G$9931,AT10,FCS!$E$11:$E$9931,$AU$9),"")))/((IFERROR((IFERROR(SUMIFS(FCS!$AM$11:$AM$9931,FCS!$G$11:$G$9931,AT10,FCS!$E$11:$E$9931,$AU$9),""))/(IFERROR(AVERAGEIFS(FCS!$AM$11:$AM$9931,FCS!$G$11:$G$9931,AT10,FCS!$E$11:$E$9931,$AU$9),"")),0))+(IFERROR((IFERROR(SUMIFS(FCS!$AN$11:$AN$9931,FCS!$G$11:$G$9931,AT10,FCS!$E$11:$E$9931,$AU$9),""))/(IFERROR(AVERAGEIFS(FCS!$AN$11:$AN$9931,FCS!$G$11:$G$9931,AT10,FCS!$E$11:$E$9931,$AU$9),"")),0))),""),2),"") | AV10: =IFERROR(ROUND(IFERROR(((IFERROR(SUMIFS(FCS!$AM$11:$AM$9931,FCS!$G$11:$G$9931,AT10,FCS!$E$11:$E$9931,$AV$9),""))+(IFERROR(SUMIFS(FCS!$AN$11:$AN$9931,FCS!$G$11:$G$9931,AT10,FCS!$E$11:$E$9931,$AV$9),"")))/((IFERROR((IFERROR(SUMIFS(FCS!$AM$11:$AM$9931,FCS!$G$11:$G$9931,AT10,FCS!$E$11:$E$9931,$AV$9),""))/(IFERROR(AVERAGEIFS(FCS!$AM$11:$AM$9931,FCS!$G$11:$G$9931,AT10,FCS!$E$11:$E$9931,$AV$9),"")),0))+(IFERROR((IFERROR(SUMIFS(FCS!$AN$11:$AN$9931,FCS!$G$11:$G$9931,AT10,FCS!$E$11:$E$9931,$AV$9),""))/(IFERROR(AVERAGEIFS(FCS!$AN$11:$AN$9931,FCS!$G$11:$G$9931,AT10,FCS!$E$11:$E$9931,$AV$9),"")),0))),""),2),"")
AT11: =AT10+1 -> #REF! | AU11: =IFERROR(ROUND(IFERROR(((IFERROR(SUMIFS(FCS!$AM$11:$AM$9931,FCS!$G$11:$G$9931,AT11,FCS!$E$11:$E$9931,$AU$9),""))+(IFERROR(SUMIFS(FCS!$AN$11:$AN$9931,FCS!$G$11:$G$9931,AT11,FCS!$E$11:$E$9931,$AU$9),"")))/((IFERROR((IFERROR(SUMIFS(FCS!$AM$11:$AM$9931,FCS!$G$11:$G$9931,AT11,FCS!$E$11:$E$9931,$AU$9),""))/(IFERROR(AVERAGEIFS(FCS!$AM$11:$AM$9931,FCS!$G$11:$G$9931,AT11,FCS!$E$11:$E$9931,$AU$9),"")),0))+(IFERROR((IFERROR(SUMIFS(FCS!$AN$11:$AN$9931,FCS!$G$11:$G$9931,AT11,FCS!$E$11:$E$9931,$AU$9),""))/(IFERROR(AVERAGEIFS(FCS!$AN$11:$AN$9931,FCS!$G$11:$G$9931,AT11,FCS!$E$11:$E$9931,$AU$9),"")),0))),""),2),"") | AV11: =IFERROR(ROUND(IFERROR(((IFERROR(SUMIFS(FCS!$AM$11:$AM$9931,FCS!$G$11:$G$9931,AT11,FCS!$E$11:$E$9931,$AV$9),""))+(IFERROR(SUMIFS(FCS!$AN$11:$AN$9931,FCS!$G$11:$G$9931,AT11,FCS!$E$11:$E$9931,$AV$9),"")))/((IFERROR((IFERROR(SUMIFS(FCS!$AM$11:$AM$9931,FCS!$G$11:$G$9931,AT11,FCS!$E$11:$E$9931,$AV$9),""))/(IFERROR(AVERAGEIFS(FCS!$AM$11:$AM$9931,FCS!$G$11:$G$9931,AT11,FCS!$E$11:$E$9931,$AV$9),"")),0))+(IFERROR((IFERROR(SUMIFS(FCS!$AN$11:$AN$9931,FCS!$G$11:$G$9931,AT11,FCS!$E$11:$E$9931,$AV$9),""))/(IFERROR(AVERAGEIFS(FCS!$AN$11:$AN$9931,FCS!$G$11:$G$9931,AT11,FCS!$E$11:$E$9931,$AV$9),"")),0))),""),2),"")
AT12: =AT11+1 -> #REF! | AU12: =IFERROR(ROUND(IFERROR(((IFERROR(SUMIFS(FCS!$AM$11:$AM$9931,FCS!$G$11:$G$9931,AT12,FCS!$E$11:$E$9931,$AU$9),""))+(IFERROR(SUMIFS(FCS!$AN$11:$AN$9931,FCS!$G$11:$G$9931,AT12,FCS!$E$11:$E$9931,$AU$9),"")))/((IFERROR((IFERROR(SUMIFS(FCS!$AM$11:$AM$9931,FCS!$G$11:$G$9931,AT12,FCS!$E$11:$E$9931,$AU$9),""))/(IFERROR(AVERAGEIFS(FCS!$AM$11:$AM$9931,FCS!$G$11:$G$9931,AT12,FCS!$E$11:$E$9931,$AU$9),"")),0))+(IFERROR((IFERROR(SUMIFS(FCS!$AN$11:$AN$9931,FCS!$G$11:$G$9931,AT12,FCS!$E$11:$E$9931,$AU$9),""))/(IFERROR(AVERAGEIFS(FCS!$AN$11:$AN$9931,FCS!$G$11:$G$9931,AT12,FCS!$E$11:$E$9931,$AU$9),"")),0))),""),2),"") | AV12: =IFERROR(ROUND(IFERROR(((IFERROR(SUMIFS(FCS!$AM$11:$AM$9931,FCS!$G$11:$G$9931,AT12,FCS!$E$11:$E$9931,$AV$9),""))+(IFERROR(SUMIFS(FCS!$AN$11:$AN$9931,FCS!$G$11:$G$9931,AT12,FCS!$E$11:$E$9931,$AV$9),"")))/((IFERROR((IFERROR(SUMIFS(FCS!$AM$11:$AM$9931,FCS!$G$11:$G$9931,AT12,FCS!$E$11:$E$9931,$AV$9),""))/(IFERROR(AVERAGEIFS(FCS!$AM$11:$AM$9931,FCS!$G$11:$G$9931,AT12,FCS!$E$11:$E$9931,$AV$9),"")),0))+(IFERROR((IFERROR(SUMIFS(FCS!$AN$11:$AN$9931,FCS!$G$11:$G$9931,AT12,FCS!$E$11:$E$9931,$AV$9),""))/(IFERROR(AVERAGEIFS(FCS!$AN$11:$AN$9931,FCS!$G$11:$G$9931,AT12,FCS!$E$11:$E$9931,$AV$9),"")),0))),""),2),"")
AT13: =AT12+1 -> #REF! | AU13: =IFERROR(ROUND(IFERROR(((IFERROR(SUMIFS(FCS!$AM$11:$AM$9931,FCS!$G$11:$G$9931,AT13,FCS!$E$11:$E$9931,$AU$9),""))+(IFERROR(SUMIFS(FCS!$AN$11:$AN$9931,FCS!$G$11:$G$9931,AT13,FCS!$E$11:$E$9931,$AU$9),"")))/((IFERROR((IFERROR(SUMIFS(FCS!$AM$11:$AM$9931,FCS!$G$11:$G$9931,AT13,FCS!$E$11:$E$9931,$AU$9),""))/(IFERROR(AVERAGEIFS(FCS!$AM$11:$AM$9931,FCS!$G$11:$G$9931,AT13,FCS!$E$11:$E$9931,$AU$9),"")),0))+(IFERROR((IFERROR(SUMIFS(FCS!$AN$11:$AN$9931,FCS!$G$11:$G$9931,AT13,FCS!$E$11:$E$9931,$AU$9),""))/(IFERROR(AVERAGEIFS(FCS!$AN$11:$AN$9931,FCS!$G$11:$G$9931,AT13,FCS!$E$11:$E$9931,$AU$9),"")),0))),""),2),"") | AV13: =IFERROR(ROUND(IFERROR(((IFERROR(SUMIFS(FCS!$AM$11:$AM$9931,FCS!$G$11:$G$9931,AT13,FCS!$E$11:$E$9931,$AV$9),""))+(IFERROR(SUMIFS(FCS!$AN$11:$AN$9931,FCS!$G$11:$G$9931,AT13,FCS!$E$11:$E$9931,$AV$9),"")))/((IFERROR((IFERROR(SUMIFS(FCS!$AM$11:$AM$9931,FCS!$G$11:$G$9931,AT13,FCS!$E$11:$E$9931,$AV$9),""))/(IFERROR(AVERAGEIFS(FCS!$AM$11:$AM$9931,FCS!$G$11:$G$9931,AT13,FCS!$E$11:$E$9931,$AV$9),"")),0))+(IFERROR((IFERROR(SUMIFS(FCS!$AN$11:$AN$9931,FCS!$G$11:$G$9931,AT13,FCS!$E$11:$E$9931,$AV$9),""))/(IFERROR(AVERAGEIFS(FCS!$AN$11:$AN$9931,FCS!$G$11:$G$9931,AT13,FCS!$E$11:$E$9931,$AV$9),"")),0))),""),2),"")
AT14: =AT13+1 -> #REF! | AU14: =IFERROR(ROUND(IFERROR(((IFERROR(SUMIFS(FCS!$AM$11:$AM$9931,FCS!$G$11:$G$9931,AT14,FCS!$E$11:$E$9931,$AU$9),""))+(IFERROR(SUMIFS(FCS!$AN$11:$AN$9931,FCS!$G$11:$G$9931,AT14,FCS!$E$11:$E$9931,$AU$9),"")))/((IFERROR((IFERROR(SUMIFS(FCS!$AM$11:$AM$9931,FCS!$G$11:$G$9931,AT14,FCS!$E$11:$E$9931,$AU$9),""))/(IFERROR(AVERAGEIFS(FCS!$AM$11:$AM$9931,FCS!$G$11:$G$9931,AT14,FCS!$E$11:$E$9931,$AU$9),"")),0))+(IFERROR((IFERROR(SUMIFS(FCS!$AN$11:$AN$9931,FCS!$G$11:$G$9931,AT14,FCS!$E$11:$E$9931,$AU$9),""))/(IFERROR(AVERAGEIFS(FCS!$AN$11:$AN$9931,FCS!$G$11:$G$9931,AT14,FCS!$E$11:$E$9931,$AU$9),"")),0))),""),2),"") | AV14: =IFERROR(ROUND(IFERROR(((IFERROR(SUMIFS(FCS!$AM$11:$AM$9931,FCS!$G$11:$G$9931,AT14,FCS!$E$11:$E$9931,$AV$9),""))+(IFERROR(SUMIFS(FCS!$AN$11:$AN$9931,FCS!$G$11:$G$9931,AT14,FCS!$E$11:$E$9931,$AV$9),"")))/((IFERROR((IFERROR(SUMIFS(FCS!$AM$11:$AM$9931,FCS!$G$11:$G$9931,AT14,FCS!$E$11:$E$9931,$AV$9),""))/(IFERROR(AVERAGEIFS(FCS!$AM$11:$AM$9931,FCS!$G$11:$G$9931,AT14,FCS!$E$11:$E$9931,$AV$9),"")),0))+(IFERROR((IFERROR(SUMIFS(FCS!$AN$11:$AN$9931,FCS!$G$11:$G$9931,AT14,FCS!$E$11:$E$9931,$AV$9),""))/(IFERROR(AVERAGEIFS(FCS!$AN$11:$AN$9931,FCS!$G$11:$G$9931,AT14,FCS!$E$11:$E$9931,$AV$9),"")),0))),""),2),"")
AT15: =AT14+1 -> #REF! | AU15: =IFERROR(ROUND(IFERROR(((IFERROR(SUMIFS(FCS!$AM$11:$AM$9931,FCS!$G$11:$G$9931,AT15,FCS!$E$11:$E$9931,$AU$9),""))+(IFERROR(SUMIFS(FCS!$AN$11:$AN$9931,FCS!$G$11:$G$9931,AT15,FCS!$E$11:$E$9931,$AU$9),"")))/((IFERROR((IFERROR(SUMIFS(FCS!$AM$11:$AM$9931,FCS!$G$11:$G$9931,AT15,FCS!$E$11:$E$9931,$AU$9),""))/(IFERROR(AVERAGEIFS(FCS!$AM$11:$AM$9931,FCS!$G$11:$G$9931,AT15,FCS!$E$11:$E$9931,$AU$9),"")),0))+(IFERROR((IFERROR(SUMIFS(FCS!$AN$11:$AN$9931,FCS!$G$11:$G$9931,AT15,FCS!$E$11:$E$9931,$AU$9),""))/(IFERROR(AVERAGEIFS(FCS!$AN$11:$AN$9931,FCS!$G$11:$G$9931,AT15,FCS!$E$11:$E$9931,$AU$9),"")),0))),""),2),"") | AV15: =IFERROR(ROUND(IFERROR(((IFERROR(SUMIFS(FCS!$AM$11:$AM$9931,FCS!$G$11:$G$9931,AT15,FCS!$E$11:$E$9931,$AV$9),""))+(IFERROR(SUMIFS(FCS!$AN$11:$AN$9931,FCS!$G$11:$G$9931,AT15,FCS!$E$11:$E$9931,$AV$9),"")))/((IFERROR((IFERROR(SUMIFS(FCS!$AM$11:$AM$9931,FCS!$G$11:$G$9931,AT15,FCS!$E$11:$E$9931,$AV$9),""))/(IFERROR(AVERAGEIFS(FCS!$AM$11:$AM$9931,FCS!$G$11:$G$9931,AT15,FCS!$E$11:$E$9931,$AV$9),"")),0))+(IFERROR((IFERROR(SUMIFS(FCS!$AN$11:$AN$9931,FCS!$G$11:$G$9931,AT15,FCS!$E$11:$E$9931,$AV$9),""))/(IFERROR(AVERAGEIFS(FCS!$AN$11:$AN$9931,FCS!$G$11:$G$9931,AT15,FCS!$E$11:$E$9931,$AV$9),"")),0))),""),2),"")
AT16: =AT15+1 -> #REF! | AU16: =IFERROR(ROUND(IFERROR(((IFERROR(SUMIFS(FCS!$AM$11:$AM$9931,FCS!$G$11:$G$9931,AT16,FCS!$E$11:$E$9931,$AU$9),""))+(IFERROR(SUMIFS(FCS!$AN$11:$AN$9931,FCS!$G$11:$G$9931,AT16,FCS!$E$11:$E$9931,$AU$9),"")))/((IFERROR((IFERROR(SUMIFS(FCS!$AM$11:$AM$9931,FCS!$G$11:$G$9931,AT16,FCS!$E$11:$E$9931,$AU$9),""))/(IFERROR(AVERAGEIFS(FCS!$AM$11:$AM$9931,FCS!$G$11:$G$9931,AT16,FCS!$E$11:$E$9931,$AU$9),"")),0))+(IFERROR((IFERROR(SUMIFS(FCS!$AN$11:$AN$9931,FCS!$G$11:$G$9931,AT16,FCS!$E$11:$E$9931,$AU$9),""))/(IFERROR(AVERAGEIFS(FCS!$AN$11:$AN$9931,FCS!$G$11:$G$9931,AT16,FCS!$E$11:$E$9931,$AU$9),"")),0))),""),2),"") | AV16: =IFERROR(ROUND(IFERROR(((IFERROR(SUMIFS(FCS!$AM$11:$AM$9931,FCS!$G$11:$G$9931,AT16,FCS!$E$11:$E$9931,$AV$9),""))+(IFERROR(SUMIFS(FCS!$AN$11:$AN$9931,FCS!$G$11:$G$9931,AT16,FCS!$E$11:$E$9931,$AV$9),"")))/((IFERROR((IFERROR(SUMIFS(FCS!$AM$11:$AM$9931,FCS!$G$11:$G$9931,AT16,FCS!$E$11:$E$9931,$AV$9),""))/(IFERROR(AVERAGEIFS(FCS!$AM$11:$AM$9931,FCS!$G$11:$G$9931,AT16,FCS!$E$11:$E$9931,$AV$9),"")),0))+(IFERROR((IFERROR(SUMIFS(FCS!$AN$11:$AN$9931,FCS!$G$11:$G$9931,AT16,FCS!$E$11:$E$9931,$AV$9),""))/(IFERROR(AVERAGEIFS(FCS!$AN$11:$AN$9931,FCS!$G$11:$G$9931,AT16,FCS!$E$11:$E$9931,$AV$9),"")),0))),""),2),"")
AT17: =AT16+1 -> #REF! | AU17: =IFERROR(ROUND(IFERROR(((IFERROR(SUMIFS(FCS!$AM$11:$AM$9931,FCS!$G$11:$G$9931,AT17,FCS!$E$11:$E$9931,$AU$9),""))+(IFERROR(SUMIFS(FCS!$AN$11:$AN$9931,FCS!$G$11:$G$9931,AT17,FCS!$E$11:$E$9931,$AU$9),"")))/((IFERROR((IFERROR(SUMIFS(FCS!$AM$11:$AM$9931,FCS!$G$11:$G$9931,AT17,FCS!$E$11:$E$9931,$AU$9),""))/(IFERROR(AVERAGEIFS(FCS!$AM$11:$AM$9931,FCS!$G$11:$G$9931,AT17,FCS!$E$11:$E$9931,$AU$9),"")),0))+(IFERROR((IFERROR(SUMIFS(FCS!$AN$11:$AN$9931,FCS!$G$11:$G$9931,AT17,FCS!$E$11:$E$9931,$AU$9),""))/(IFERROR(AVERAGEIFS(FCS!$AN$11:$AN$9931,FCS!$G$11:$G$9931,AT17,FCS!$E$11:$E$9931,$AU$9),"")),0))),""),2),"") | AV17: =IFERROR(ROUND(IFERROR(((IFERROR(SUMIFS(FCS!$AM$11:$AM$9931,FCS!$G$11:$G$9931,AT17,FCS!$E$11:$E$9931,$AV$9),""))+(IFERROR(SUMIFS(FCS!$AN$11:$AN$9931,FCS!$G$11:$G$9931,AT17,FCS!$E$11:$E$9931,$AV$9),"")))/((IFERROR((IFERROR(SUMIFS(FCS!$AM$11:$AM$9931,FCS!$G$11:$G$9931,AT17,FCS!$E$11:$E$9931,$AV$9),""))/(IFERROR(AVERAGEIFS(FCS!$AM$11:$AM$9931,FCS!$G$11:$G$9931,AT17,FCS!$E$11:$E$9931,$AV$9),"")),0))+(IFERROR((IFERROR(SUMIFS(FCS!$AN$11:$AN$9931,FCS!$G$11:$G$9931,AT17,FCS!$E$11:$E$9931,$AV$9),""))/(IFERROR(AVERAGEIFS(FCS!$AN$11:$AN$9931,FCS!$G$11:$G$9931,AT17,FCS!$E$11:$E$9931,$AV$9),"")),0))),""),2),"")
AT18: =AT17+1 -> #REF! | AU18: =IFERROR(ROUND(IFERROR(((IFERROR(SUMIFS(FCS!$AM$11:$AM$9931,FCS!$G$11:$G$9931,AT18,FCS!$E$11:$E$9931,$AU$9),""))+(IFERROR(SUMIFS(FCS!$AN$11:$AN$9931,FCS!$G$11:$G$9931,AT18,FCS!$E$11:$E$9931,$AU$9),"")))/((IFERROR((IFERROR(SUMIFS(FCS!$AM$11:$AM$9931,FCS!$G$11:$G$9931,AT18,FCS!$E$11:$E$9931,$AU$9),""))/(IFERROR(AVERAGEIFS(FCS!$AM$11:$AM$9931,FCS!$G$11:$G$9931,AT18,FCS!$E$11:$E$9931,$AU$9),"")),0))+(IFERROR((IFERROR(SUMIFS(FCS!$AN$11:$AN$9931,FCS!$G$11:$G$9931,AT18,FCS!$E$11:$E$9931,$AU$9),""))/(IFERROR(AVERAGEIFS(FCS!$AN$11:$AN$9931,FCS!$G$11:$G$9931,AT18,FCS!$E$11:$E$9931,$AU$9),"")),0))),""),2),"") | AV18: =IFERROR(ROUND(IFERROR(((IFERROR(SUMIFS(FCS!$AM$11:$AM$9931,FCS!$G$11:$G$9931,AT18,FCS!$E$11:$E$9931,$AV$9),""))+(IFERROR(SUMIFS(FCS!$AN$11:$AN$9931,FCS!$G$11:$G$9931,AT18,FCS!$E$11:$E$9931,$AV$9),"")))/((IFERROR((IFERROR(SUMIFS(FCS!$AM$11:$AM$9931,FCS!$G$11:$G$9931,AT18,FCS!$E$11:$E$9931,$AV$9),""))/(IFERROR(AVERAGEIFS(FCS!$AM$11:$AM$9931,FCS!$G$11:$G$9931,AT18,FCS!$E$11:$E$9931,$AV$9),"")),0))+(IFERROR((IFERROR(SUMIFS(FCS!$AN$11:$AN$9931,FCS!$G$11:$G$9931,AT18,FCS!$E$11:$E$9931,$AV$9),""))/(IFERROR(AVERAGEIFS(FCS!$AN$11:$AN$9931,FCS!$G$11:$G$9931,AT18,FCS!$E$11:$E$9931,$AV$9),"")),0))),""),2),"")
AT19: =AT18+1 -> #REF! | AU19: =IFERROR(ROUND(IFERROR(((IFERROR(SUMIFS(FCS!$AM$11:$AM$9931,FCS!$G$11:$G$9931,AT19,FCS!$E$11:$E$9931,$AU$9),""))+(IFERROR(SUMIFS(FCS!$AN$11:$AN$9931,FCS!$G$11:$G$9931,AT19,FCS!$E$11:$E$9931,$AU$9),"")))/((IFERROR((IFERROR(SUMIFS(FCS!$AM$11:$AM$9931,FCS!$G$11:$G$9931,AT19,FCS!$E$11:$E$9931,$AU$9),""))/(IFERROR(AVERAGEIFS(FCS!$AM$11:$AM$9931,FCS!$G$11:$G$9931,AT19,FCS!$E$11:$E$9931,$AU$9),"")),0))+(IFERROR((IFERROR(SUMIFS(FCS!$AN$11:$AN$9931,FCS!$G$11:$G$9931,AT19,FCS!$E$11:$E$9931,$AU$9),""))/(IFERROR(AVERAGEIFS(FCS!$AN$11:$AN$9931,FCS!$G$11:$G$9931,AT19,FCS!$E$11:$E$9931,$AU$9),"")),0))),""),2),"") | AV19: =IFERROR(ROUND(IFERROR(((IFERROR(SUMIFS(FCS!$AM$11:$AM$9931,FCS!$G$11:$G$9931,AT19,FCS!$E$11:$E$9931,$AV$9),""))+(IFERROR(SUMIFS(FCS!$AN$11:$AN$9931,FCS!$G$11:$G$9931,AT19,FCS!$E$11:$E$9931,$AV$9),"")))/((IFERROR((IFERROR(SUMIFS(FCS!$AM$11:$AM$9931,FCS!$G$11:$G$9931,AT19,FCS!$E$11:$E$9931,$AV$9),""))/(IFERROR(AVERAGEIFS(FCS!$AM$11:$AM$9931,FCS!$G$11:$G$9931,AT19,FCS!$E$11:$E$9931,$AV$9),"")),0))+(IFERROR((IFERROR(SUMIFS(FCS!$AN$11:$AN$9931,FCS!$G$11:$G$9931,AT19,FCS!$E$11:$E$9931,$AV$9),""))/(IFERROR(AVERAGEIFS(FCS!$AN$11:$AN$9931,FCS!$G$11:$G$9931,AT19,FCS!$E$11:$E$9931,$AV$9),"")),0))),""),2),"")
AT20: =AT19+1 -> #REF! | AU20: =IFERROR(ROUND(IFERROR(((IFERROR(SUMIFS(FCS!$AM$11:$AM$9931,FCS!$G$11:$G$9931,AT20,FCS!$E$11:$E$9931,$AU$9),""))+(IFERROR(SUMIFS(FCS!$AN$11:$AN$9931,FCS!$G$11:$G$9931,AT20,FCS!$E$11:$E$9931,$AU$9),"")))/((IFERROR((IFERROR(SUMIFS(FCS!$AM$11:$AM$9931,FCS!$G$11:$G$9931,AT20,FCS!$E$11:$E$9931,$AU$9),""))/(IFERROR(AVERAGEIFS(FCS!$AM$11:$AM$9931,FCS!$G$11:$G$9931,AT20,FCS!$E$11:$E$9931,$AU$9),"")),0))+(IFERROR((IFERROR(SUMIFS(FCS!$AN$11:$AN$9931,FCS!$G$11:$G$9931,AT20,FCS!$E$11:$E$9931,$AU$9),""))/(IFERROR(AVERAGEIFS(FCS!$AN$11:$AN$9931,FCS!$G$11:$G$9931,AT20,FCS!$E$11:$E$9931,$AU$9),"")),0))),""),2),"") | AV20: =IFERROR(ROUND(IFERROR(((IFERROR(SUMIFS(FCS!$AM$11:$AM$9931,FCS!$G$11:$G$9931,AT20,FCS!$E$11:$E$9931,$AV$9),""))+(IFERROR(SUMIFS(FCS!$AN$11:$AN$9931,FCS!$G$11:$G$9931,AT20,FCS!$E$11:$E$9931,$AV$9),"")))/((IFERROR((IFERROR(SUMIFS(FCS!$AM$11:$AM$9931,FCS!$G$11:$G$9931,AT20,FCS!$E$11:$E$9931,$AV$9),""))/(IFERROR(AVERAGEIFS(FCS!$AM$11:$AM$9931,FCS!$G$11:$G$9931,AT20,FCS!$E$11:$E$9931,$AV$9),"")),0))+(IFERROR((IFERROR(SUMIFS(FCS!$AN$11:$AN$9931,FCS!$G$11:$G$9931,AT20,FCS!$E$11:$E$9931,$AV$9),""))/(IFERROR(AVERAGEIFS(FCS!$AN$11:$AN$9931,FCS!$G$11:$G$9931,AT20,FCS!$E$11:$E$9931,$AV$9),"")),0))),""),2),"")
AT21: =AT20+1 -> #REF! | AU21: =IFERROR(ROUND(IFERROR(((IFERROR(SUMIFS(FCS!$AM$11:$AM$9931,FCS!$G$11:$G$9931,AT21,FCS!$E$11:$E$9931,$AU$9),""))+(IFERROR(SUMIFS(FCS!$AN$11:$AN$9931,FCS!$G$11:$G$9931,AT21,FCS!$E$11:$E$9931,$AU$9),"")))/((IFERROR((IFERROR(SUMIFS(FCS!$AM$11:$AM$9931,FCS!$G$11:$G$9931,AT21,FCS!$E$11:$E$9931,$AU$9),""))/(IFERROR(AVERAGEIFS(FCS!$AM$11:$AM$9931,FCS!$G$11:$G$9931,AT21,FCS!$E$11:$E$9931,$AU$9),"")),0))+(IFERROR((IFERROR(SUMIFS(FCS!$AN$11:$AN$9931,FCS!$G$11:$G$9931,AT21,FCS!$E$11:$E$9931,$AU$9),""))/(IFERROR(AVERAGEIFS(FCS!$AN$11:$AN$9931,FCS!$G$11:$G$9931,AT21,FCS!$E$11:$E$9931,$AU$9),"")),0))),""),2),"") | AV21: =IFERROR(ROUND(IFERROR(((IFERROR(SUMIFS(FCS!$AM$11:$AM$9931,FCS!$G$11:$G$9931,AT21,FCS!$E$11:$E$9931,$AV$9),""))+(IFERROR(SUMIFS(FCS!$AN$11:$AN$9931,FCS!$G$11:$G$9931,AT21,FCS!$E$11:$E$9931,$AV$9),"")))/((IFERROR((IFERROR(SUMIFS(FCS!$AM$11:$AM$9931,FCS!$G$11:$G$9931,AT21,FCS!$E$11:$E$9931,$AV$9),""))/(IFERROR(AVERAGEIFS(FCS!$AM$11:$AM$9931,FCS!$G$11:$G$9931,AT21,FCS!$E$11:$E$9931,$AV$9),"")),0))+(IFERROR((IFERROR(SUMIFS(FCS!$AN$11:$AN$9931,FCS!$G$11:$G$9931,AT21,FCS!$E$11:$E$9931,$AV$9),""))/(IFERROR(AVERAGEIFS(FCS!$AN$11:$AN$9931,FCS!$G$11:$G$9931,AT21,FCS!$E$11:$E$9931,$AV$9),"")),0))),""),2),"")
AT22: =AT21+1 -> #REF! | AU22: =IFERROR(ROUND(IFERROR(((IFERROR(SUMIFS(FCS!$AM$11:$AM$9931,FCS!$G$11:$G$9931,AT22,FCS!$E$11:$E$9931,$AU$9),""))+(IFERROR(SUMIFS(FCS!$AN$11:$AN$9931,FCS!$G$11:$G$9931,AT22,FCS!$E$11:$E$9931,$AU$9),"")))/((IFERROR((IFERROR(SUMIFS(FCS!$AM$11:$AM$9931,FCS!$G$11:$G$9931,AT22,FCS!$E$11:$E$9931,$AU$9),""))/(IFERROR(AVERAGEIFS(FCS!$AM$11:$AM$9931,FCS!$G$11:$G$9931,AT22,FCS!$E$11:$E$9931,$AU$9),"")),0))+(IFERROR((IFERROR(SUMIFS(FCS!$AN$11:$AN$9931,FCS!$G$11:$G$9931,AT22,FCS!$E$11:$E$9931,$AU$9),""))/(IFERROR(AVERAGEIFS(FCS!$AN$11:$AN$9931,FCS!$G$11:$G$9931,AT22,FCS!$E$11:$E$9931,$AU$9),"")),0))),""),2),"") | AV22: =IFERROR(ROUND(IFERROR(((IFERROR(SUMIFS(FCS!$AM$11:$AM$9931,FCS!$G$11:$G$9931,AT22,FCS!$E$11:$E$9931,$AV$9),""))+(IFERROR(SUMIFS(FCS!$AN$11:$AN$9931,FCS!$G$11:$G$9931,AT22,FCS!$E$11:$E$9931,$AV$9),"")))/((IFERROR((IFERROR(SUMIFS(FCS!$AM$11:$AM$9931,FCS!$G$11:$G$9931,AT22,FCS!$E$11:$E$9931,$AV$9),""))/(IFERROR(AVERAGEIFS(FCS!$AM$11:$AM$9931,FCS!$G$11:$G$9931,AT22,FCS!$E$11:$E$9931,$AV$9),"")),0))+(IFERROR((IFERROR(SUMIFS(FCS!$AN$11:$AN$9931,FCS!$G$11:$G$9931,AT22,FCS!$E$11:$E$9931,$AV$9),""))/(IFERROR(AVERAGEIFS(FCS!$AN$11:$AN$9931,FCS!$G$11:$G$9931,AT22,FCS!$E$11:$E$9931,$AV$9),"")),0))),""),2),"")
