Workbook
Name granver: 'Granulometrias de Verificación'!$B$8:$W$8
Name Slicer_Ensayo_asociado: #N/A
Name Slicer_Semana: #N/A
Name Slicer_Semana1: #N/A
Name Slicer_Semana2: #N/A
Name Slicer_Semana3: #N/A

Sheet Granulometrias Descarga
C2: Control de Calidad
C3: PRESA DE RELAVES | F3: RESUMEN DE GRANULOMETRIAS DE LOS RELAVES EN EL DEPOSITO DERELAVES ENLOZADA | Z3: Sin Formula
F4: =+B9 -> 46082 | Z4: revisar
H5: Datos en Laboratorio | R5: Datos ciclones
I6: Porcentaje acumulado Pasante
I7: Nº 8 | J7: Nº 16 | K7: Nº 30 | L7: Nº 40 | M7: Nº 50 | N7: Nº 70 | O7: Nº 100 | P7: Nº 200
B8: Fecha | C8: Código | D8: Hora | E8: Ejecutor | F8: Cancha | G8: Sp, Sb, A8,A9 | H8: Peso de muestra (g) | I8: 2360 | J8: 1180 | K8: 600 | L8: 425 | M8: 300 | N8: 212 | O8: 150 | P8: 75 | Q8: % sólidos | R8: % finos | S8: % sólidos2 | T8: Resp | U8: Turno | V8: Observaciones | W8: Column2 | X8: Column1 | Y8: Semana | Z8: Fallas
B9: 46082 | C9: GD-260451 | D9: 0.48611111 | E9: SMCV | F9: 3 | G9: JH | H9: 397.7 | I9: 100 | J9: 100 | K9: 98.642193 | L9: 91.249686 | M9: 72.466683 | N9: 48.931355 | O9: 28.589389 | P9: 9.0771939 | Q9: 70.903904 | R9: 10 | S9: 69 | T9: GM | U9: A | V9: Muestreado de descarga | Y9: =IF(Table_GD[[#This Row],[Fecha]]=0,"",_xlfn.CONCAT("Sem ",WEEKNUM(Table_GD[[#This Row],[Fecha]],2))) -> Sem 9 | Z9: =+IF(P9>=12,P9,0) -> 0
B10: 46082 | C10: GD-260452 | D10: 0.61111111 | E10: SMCV | F10: 3 | G10: JH | H10: 407.5 | I10: 100 | J10: 100 | K10: 99.042945 | L10: 92.368098 | M10: 72.588957 | N10: 53.325153 | O10: 34.822086 | P10: 10.06135 | Q10: 69.99313 | R10: 9 | S10: 69 | T10: GM | U10: A | V10: Muestreado de descarga | Y10: =IF(Table_GD[[#This Row],[Fecha]]=0,"",_xlfn.CONCAT("Sem ",WEEKNUM(Table_GD[[#This Row],[Fecha]],2))) -> Sem 9 | Z10: =+IF(P10>=12,P10,0) -> 0
B11: 46082 | C11: GD-260453 | D11: 0.70138889 | E11: SMCV | F11: 3 | G11: JH | H11: 339.2 | I11: 100 | J11: 100 | K11: 98.378538 | L11: 91.037736 | M11: 71.757075 | N11: 49.941038 | O11: 28.213443 | P11: 8.490566 | Q11: 69.794239 | R11: 9.5 | S11: 70 | T11: GM | U11: A | V11: Muestreado de descarga | Y11: =IF(Table_GD[[#This Row],[Fecha]]=0,"",_xlfn.CONCAT("Sem ",WEEKNUM(Table_GD[[#This Row],[Fecha]],2))) -> Sem 9 | Z11: =+IF(P11>=12,P11,0) -> 0
B12: 46082 | C12: GD-260454 | D12: 0.77083333 | E12: SMCV | F12: 3 | G12: 2da.Est. | H12: 347.1 | I12: 100 | J12: 100 | K12: 98.329012 | L12: 89.74359 | M12: 70.556036 | N12: 48.573898 | O12: 27.571305 | P12: 7.8075483 | Q12: 70.40568 | R12: 9.2 | S12: 70 | T12: GM | U12: B | V12: Muestreado de 2da. Estación | Y12: =IF(Table_GD[[#This Row],[Fecha]]=0,"",_xlfn.CONCAT("Sem ",WEEKNUM(Table_GD[[#This Row],[Fecha]],2))) -> Sem 9 | Z12: =+IF(P12>=12,P12,0) -> 0
B13: 46082 | C13: GD-260455 | D13: 0.875 | E13: SMCV | F13: 3 | G13: 2da.Est. | H13: 316.8 | I13: 100 | J13: 100 | K13: 98.106061 | L13: 90.088384 | M13: 72.380051 | N13: 50.789141 | O13: 29.987374 | P13: 7.9229798 | Q13: 67.793709 | R13: 9 | S13: 70 | T13: GM | U13: B | V13: Muestreado de 2da. Estación | Y13: =IF(Table_GD[[#This Row],[Fecha]]=0,"",_xlfn.CONCAT("Sem ",WEEKNUM(Table_GD[[#This Row],[Fecha]],2))) -> Sem 9 | Z13: =+IF(P13>=12,P13,0) -> 0
B14: 46082 | C14: GD-260456 | D14: 0.95833333 | E14: SMCV | F14: 3 | G14: JH | H14: 335.8 | I14: 100 | J14: 100 | K14: 98.600357 | L14: 89.636689 | M14: 70.428827 | N14: 49.16617 | O14: 28.23109 | P14: 8.5169744 | Q14: 68.572595 | R14: 9.2 | S14: 68.5 | T14: GM | U14: B | V14: Muestreado de descarga | Y14: =IF(Table_GD[[#This Row],[Fecha]]=0,"",_xlfn.CONCAT("Sem ",WEEKNUM(Table_GD[[#This Row],[Fecha]],2))) -> Sem 9 | Z14: =+IF(P14>=12,P14,0) -> 0
B15: 46082 | C15: GD-260457 | D15: 0.041666667 | E15: SMCV | F15: 3 | G15: JH | H15: 329.9 | I15: 100 | J15: 100 | K15: 98.181267 | L15: 89.3301 | M15: 70.475902 | N15: 48.105487 | O15: 26.705062 | P15: 8.0630494 | Q15: 67.922586 | R15: 8.7 | S15: 69.2 | T15: GM | U15: B | V15: Muestreado de descarga | Y15: =IF(Table_GD[[#This Row],[Fecha]]=0,"",_xlfn.CONCAT("Sem ",WEEKNUM(Table_GD[[#This Row],[Fecha]],2))) -> Sem 9 | Z15: =+IF(P15>=12,P15,0) -> 0
B16: 46082 | C16: GD-260458 | D16: 0.14583333 | E16: SMCV | F16: 3 | G16: 2da.Est. | H16: 321 | I16: 100 | J16: 100 | K16: 98.380062 | L16: 90.872274 | M16: 74.143302 | N16: 50.716511 | O16: 29.906542 | P16: 8.7227414 | Q16: 68.414322 | R16: 9 | S16: 69 | T16: GM | U16: B | V16: Muestreado de 2da. Estación | Y16: =IF(Table_GD[[#This Row],[Fecha]]=0,"",_xlfn.CONCAT("Sem ",WEEKNUM(Table_GD[[#This Row],[Fecha]],2))) -> Sem 9 | Z16: =+IF(P16>=12,P16,0) -> 0
B17: 46083 | C17: GD-260459 | D17: 0.27083333 | E17: SMCV | F17: 3 | G17: 2da.Est. | H17: 279.1 | I17: 100 | J17: 100 | K17: 98.101039 | L17: 89.967753 | M17: 71.694733 | N17: 50.734504 | O17: 29.810104 | P17: 8.7065568 | Q17: 69.307177 | R17: 9 | S17: 70 | T17: GM | U17: A | V17: Muestreado de 2da. Estación | Y17: =IF(Table_GD[[#This Row],[Fecha]]=0,"",_xlfn.CONCAT("Sem ",WEEKNUM(Table_GD[[#This Row],[Fecha]],2))) -> Sem 10 | Z17: =+IF(P17>=12,P17,0) -> 0
B18: 46083 | C18: GD-260460 | D18: 0.85416667 | E18: SMCV | F18: 3 | G18: 2da.Est. | H18: 316.2 | I18: 100 | J18: 100 | K18: 98.197343 | L18: 90.25933 | M18: 71.252372 | N18: 49.841872 | O18: 28.747628 | P18: 9.1081594 | Q18: 70.501672 | R18: 9 | S18: 70 | T18: GM | U18: A | V18: Muestreado de 2da. Estación | Y18: =IF(Table_GD[[#This Row],[Fecha]]=0,"",_xlfn.CONCAT("Sem ",WEEKNUM(Table_GD[[#This Row],[Fecha]],2))) -> Sem 10 | Z18: =+IF(P18>=12,P18,0) -> 0
B19: 46083 | C19: GD-260461 | D19: 0.47916667 | E19: SMCV | F19: 2C-M | G19: Sb | H19: 351.9 | I19: 100 | J19: 100 | K19: 98.323387 | L19: 90.622336 | M19: 71.810173 | N19: 50.639386 | O19: 29.497016 | P19: 9.5481671 | Q19: 70.691041 | R19: 9 | S19: 70.5 | T19: GM | U19: A | V19: Muestreado de descarga | Y19: =IF(Table_GD[[#This Row],[Fecha]]=0,"",_xlfn.CONCAT("Sem ",WEEKNUM(Table_GD[[#This Row],[Fecha]],2))) -> Sem 10 | Z19: =+IF(P19>=12,P19,0) -> 0
B20: 46083 | C20: GD-260462 | D20: 0.57291667 | E20: SMCV | F20: 3A-M | G20: Sb | H20: 356.4 | I20: 100 | J20: 100 | K20: 99.186308 | L20: 96.156004 | M20: 85.578002 | N20: 65.852974 | O20: 42.620651 | P20: 11.026936 | Q20: 71.208791 | R20: 9.2 | S20: 71.5 | T20: GM | U20: A | V20: Muestreado de descarga | Y20: =IF(Table_GD[[#This Row],[Fecha]]=0,"",_xlfn.CONCAT("Sem ",WEEKNUM(Table_GD[[#This Row],[Fecha]],2))) -> Sem 10 | Z20: =+IF(P20>=12,P20,0) -> 0
B21: 46083 | C21: GD-260463 | D21: 0.66666667 | E21: SMCV | F21: 3 | G21: 2da.Est. | H21: 401.4 | I21: 100 | J21: 100 | K21: 99.003488 | L21: 93.348281 | M21: 77.130045 | N21: 55.68012 | O21: 33.134031 | P21: 8.9935227 | Q21: 71.296625 | R21: 9.3 | S21: 71.5 | T21: GM | U21: A | V21: Muestreado de 2da. Estación | Y21: =IF(Table_GD[[#This Row],[Fecha]]=0,"",_xlfn.CONCAT("Sem ",WEEKNUM(Table_GD[[#This Row],[Fecha]],2))) -> Sem 10 | Z21: =+IF(P21>=12,P21,0) -> 0
B22: 46083 | C22: GD-260464 | D22: 0.77083333 | E22: SMCV | F22: 3 | G22: 2da.Est. | H22: 357.6 | I22: 100 | J22: 100 | K22: 99.384787 | L22: 95.553691 | M22: 83.44519 | N22: 64.065996 | O22: 41.918345 | P22: 10.458613 | Q22: 71.121718 | R22: 10 | S22: 71 | T22: GT | U22: B | V22: Muestreado de 2da. Estación | Y22: =IF(Table_GD[[#This Row],[Fecha]]=0,"",_xlfn.CONCAT("Sem ",WEEKNUM(Table_GD[[#This Row],[Fecha]],2))) -> Sem 10 | Z22: =+IF(P22>=12,P22,0) -> 0
B23: 46083 | C23: GD-260465 | D23: 0.85416667 | E23: SMCV | F23: 3 | G23: 2da.Est. | H23: 355.5 | I23: 100 | J23: 100 | K23: 98.509142 | L23: 90.098453 | M23: 70.773558 | N23: 48.663854 | O23: 26.891702 | P23: 9.8734177 | Q23: 71.19968 | R23: 10.3 | S23: 71 | T23: GT | U23: B | V23: Muestreado de 2da. Estación | Y23: =IF(Table_GD[[#This Row],[Fecha]]=0,"",_xlfn.CONCAT("Sem ",WEEKNUM(Table_GD[[#This Row],[Fecha]],2))) -> Sem 10 | Z23: =+IF(P23>=12,P23,0) -> 0
B24: 46083 | C24: GD-260466 | D24: 0.45833333 | E24: SMCV | F24: 3A-M | G24: Sb | H24: 266.7 | I24: 100 | J24: 100 | K24: 98.80015 | L24: 92.313461 | M24: 76.452943 | N24: 56.280465 | O24: 35.433071 | P24: 10.273716 | Q24: 71.157951 | R24: 10 | S24: 71 | T24: GT | U24: B | V24: Muestreado de descarga | Y24: =IF(Table_GD[[#This Row],[Fecha]]=0,"",_xlfn.CONCAT("Sem ",WEEKNUM(Table_GD[[#This Row],[Fecha]],2))) -> Sem 10 | Z24: =+IF(P24>=12,P24,0) -> 0
B25: 46083 | C25: GD-260467 | D25: 0.041666667 | E25: SMCV | F25: 2C-M | G25: Sb | H25: 268.9 | I25: 100 | J25: 100 | K25: 98.884344 | L25: 92.711045 | M25: 79.360357 | N25: 57.344738 | O25: 35.440684 | P25: 9.743399 | Q25: 71.250662 | R25: 10 | S25: 71 | T25: GT | U25: B | V25: Muestreado de descarga | Y25: =IF(Table_GD[[#This Row],[Fecha]]=0,"",_xlfn.CONCAT("Sem ",WEEKNUM(Table_GD[[#This Row],[Fecha]],2))) -> Sem 10 | Z25: =+IF(P25>=12,P25,0) -> 0
B26: 46083 | C26: GD-260468 | D26: 0.66666667 | E26: SMCV | F26: 2 | G26: 2da.Est. | H26: 356.6 | I26: 100 | J26: 100 | K26: 98.653954 | L26: 90.185081 | M26: 70.330903 | N26: 48.710039 | O26: 27.173303 | P26: 10.03926 | Q26: 71.462926 | R26: 10.3 | S26: 71.5 | T26: GT | U26: B | V26: Muestreado de 2da. Estación | Y26: =IF(Table_GD[[#This Row],[Fecha]]=0,"",_xlfn.CONCAT("Sem ",WEEKNUM(Table_GD[[#This Row],[Fecha]],2))) -> Sem 10 | Z26: =+IF(P26>=12,P26,0) -> 0
B27: 46084 | C27: GD-260469 | D27: 0.28472222 | E27: SMCV | F27: 3 | G27: 2da.Est. | H27: 278.69333 | I27: 100 | J27: 100 | K27: 98.026505 | L27: 89.414888 | M27: 70.720504 | N27: 49.263227 | O27: 28.451821 | P27: 8.286286 | Q27: 70.129171 | R27: 10 | S27: 70.3 | T27: GT | U27: A | V27: Muestreado de 2da. Estación | Y27: =IF(Table_GD[[#This Row],[Fecha]]=0,"",_xlfn.CONCAT("Sem ",WEEKNUM(Table_GD[[#This Row],[Fecha]],2))) -> Sem 10 | Z27: =+IF(P27>=12,P27,0) -> 0
B28: 46084 | C28: GD-260470 | D28: 0.35416667 | E28: SMCV | F28: 2 | G28: 2da.Est. | H28: 396.29733 | I28: 100 | J28: 100 | K28: 98.183182 | L28: 90.461707 | M28: 72.116895 | N28: 51.046856 | O28: 29.674015 | P28: 9.0581803 | Q28: 71.122995 | R28: 9.2 | S28: 70 | T28: GT | U28: A | V28: Muestreado de 2da. Estación | Y28: =IF(Table_GD[[#This Row],[Fecha]]=0,"",_xlfn.CONCAT("Sem ",WEEKNUM(Table_GD[[#This Row],[Fecha]],2))) -> Sem 10 | Z28: =+IF(P28>=12,P28,0) -> 0
B29: 46084 | C29: GD-260471 | D29: 0.45833333 | E29: SMCV | F29: 3A | G29: Sb | H29: 339.83314 | I29: 100 | J29: 100 | K29: 98.616968 | L29: 91.172138 | M29: 72.54535 | N29: 49.916598 | O29: 27.964649 | P29: 9.0730246 | Q29: 70.039807 | R29: 9 | S29: 70.5 | T29: GT | U29: A | V29: Muestreado de descarga | Y29: =IF(Table_GD[[#This Row],[Fecha]]=0,"",_xlfn.CONCAT("Sem ",WEEKNUM(Table_GD[[#This Row],[Fecha]],2))) -> Sem 10 | Z29: =+IF(P29>=12,P29,0) -> 0
B30: 46084 | C30: GD-260472 | D30: 0.57083333 | E30: SMCV | F30: 2C | G30: Sb | H30: 285.6 | I30: 100 | J30: 100 | K30: 98.179272 | L30: 89.845938 | M30: 70.938375 | N30: 49.404762 | O30: 28.431373 | P30: 9.0686275 | Q30: 66.034682 | R30: 9 | S30: 72.2 | T30: GT | U30: A | V30: Muestreado de descarga | Y30: =IF(Table_GD[[#This Row],[Fecha]]=0,"",_xlfn.CONCAT("Sem ",WEEKNUM(Table_GD[[#This Row],[Fecha]],2))) -> Sem 10 | Z30: =+IF(P30>=12,P30,0) -> 0
B31: 46084 | C31: GD-260473 | D31: 0.66666667 | E31: SMCV | F31: 2 | G31: 2da.Est. | H31: 379.37588 | I31: 100 | J31: 99.920923 | K31: 98.339378 | L31: 90.80068 | M31: 73.772713 | N31: 52.922679 | O31: 32.599827 | P31: 9.2456801 | Q31: 72.621723 | R31: 9.9 | S31: 70.8 | T31: GT | U31: A | V31: Muestreado de 2da. Estación | Y31: =IF(Table_GD[[#This Row],[Fecha]]=0,"",_xlfn.CONCAT("Sem ",WEEKNUM(Table_GD[[#This Row],[Fecha]],2))) -> Sem 10 | Z31: =+IF(P31>=12,P31,0) -> 0
B32: 46084 | C32: GD-260474 | D32: 0.45486111 | E32: SMCV | F32: 2 | G32: 2da.Est. | H32: 232.80538 | I32: 100 | J32: 100 | K32: 98.281827 | L32: 89.819823 | M32: 70.705144 | N32: 48.755479 | O32: 27.06354 | P32: 8.1636326 | Q32: 71.544369 | R32: 8.8 | S32: 70.5 | T32: GT | U32: B | V32: Muestreado de 2da. Estación | Y32: =IF(Table_GD[[#This Row],[Fecha]]=0,"",_xlfn.CONCAT("Sem ",WEEKNUM(Table_GD[[#This Row],[Fecha]],2))) -> Sem 10 | Z32: =+IF(P32>=12,P32,0) -> 0
B33: 46084 | C33: GD-260475 | D33: 0.069444444 | E33: SMCV | F33: 2A-M | G33: Sb | H33: 220.56073 | I33: 100 | J33: 100 | K33: 98.458474 | L33: 90.705508 | M33: 72.29788 | N33: 50.081777 | O33: 29.044487 | P33: 8.2792316 | Q33: 70.152905 | R33: 9.2 | S33: 70.2 | T33: GT | U33: B | V33: Muestreado de descarga | Y33: =IF(Table_GD[[#This Row],[Fecha]]=0,"",_xlfn.CONCAT("Sem ",WEEKNUM(Table_GD[[#This Row],[Fecha]],2))) -> Sem 10 | Z33: =+IF(P33>=12,P33,0) -> 0
B34: 46084 | C34: GD-260476 | D34: 0.16666667 | E34: SMCV | F34: 2 | G34: 2da.Est. | H34: 232.37741 | I34: 100 | J34: 100 | K34: 98.364729 | L34: 90.618709 | M34: 71.25366 | N34: 49.048403 | O34: 27.230447 | P34: 8.1666321 | Q34: 70.2471 | R34: 9 | S34: 70.2 | T34: GT | U34: B | V34: Muestreado de 2da. Estación | Y34: =IF(Table_GD[[#This Row],[Fecha]]=0,"",_xlfn.CONCAT("Sem ",WEEKNUM(Table_GD[[#This Row],[Fecha]],2))) -> Sem 10 | Z34: =+IF(P34>=12,P34,0) -> 0
B35: 46085 | C35: GD-260477 | D35: 0.26736111 | E35: SMCV | F35: 2 | G35: 2da.Est. | H35: 191.33571 | I35: 100 | J35: 100 | K35: 97.909434 | L35: 88.919998 | M35: 70.575278 | N35: 49.512821 | O35: 29.286591 | P35: 9.1126249 | Q35: 72.229409 | R35: 8.9 | S35: 70.2 | T35: GT | U35: A | V35: Muestreado de 2da. Estación | Y35: =IF(Table_GD[[#This Row],[Fecha]]=0,"",_xlfn.CONCAT("Sem ",WEEKNUM(Table_GD[[#This Row],[Fecha]],2))) -> Sem 10 | Z35: =+IF(P35>=12,P35,0) -> 0
B36: 46085 | C36: GD-260478 | D36: 0.35416667 | E36: SMCV | F36: 2 | G36: 2da.Est. | H36: 323.51459 | I36: 100 | J36: 100 | K36: 97.867175 | L36: 88.810397 | M36: 70.418645 | N36: 50.110442 | O36: 30.111344 | P36: 9.0921995 | Q36: 71.844235 | R36: 9 | S36: 70.3 | T36: GT | U36: A | V36: Muestreado de 2da. Estación | Y36: =IF(Table_GD[[#This Row],[Fecha]]=0,"",_xlfn.CONCAT("Sem ",WEEKNUM(Table_GD[[#This Row],[Fecha]],2))) -> Sem 10 | Z36: =+IF(P36>=12,P36,0) -> 0
B37: 46085 | C37: GD-260479 | D37: 0.64583333 | E37: SMCV | F37: 2 | G37: Sb | H37: 392.30562 | I37: 100 | J37: 100 | K37: 98.929406 | L37: 93.347024 | M37: 78.639103 | N37: 60.184103 | O37: 40.225174 | P37: 13.307385 | Q37: 71.510321 | R37: 9 | S37: 70 | T37: GT | U37: A | V37: Muestreado de descarga | Y37: =IF(Table_GD[[#This Row],[Fecha]]=0,"",_xlfn.CONCAT("Sem ",WEEKNUM(Table_GD[[#This Row],[Fecha]],2))) -> Sem 10 | Z37: =+IF(P37>=12,P37,0) -> 13.307385
B38: 46085 | C38: GD-260480 | D38: 0.71527778 | E38: SMCV | F38: 2 | G38: 2da.Est. | H38: 372.12034 | I38: 100 | J38: 100 | K38: 99.11319 | L38: 94.222299 | M38: 80.624548 | N38: 62.189651 | O38: 41.416801 | P38: 12.340186 | Q38: 71.520343 | R38: 9.8 | S38: 70 | T38: GT | U38: A | V38: Muestreado de 2da. Estación | Y38: =IF(Table_GD[[#This Row],[Fecha]]=0,"",_xlfn.CONCAT("Sem ",WEEKNUM(Table_GD[[#This Row],[Fecha]],2))) -> Sem 10 | Z38: =+IF(P38>=12,P38,0) -> 12.340186
B39: 46085 | C39: GD-260481 | D39: 0.48263889 | E39: SMCV | F39: 2 | G39: 2da.Est. | H39: 192.46012 | I39: 100 | J39: 99.896082 | K39: 98.2334 | L39: 91.167001 | M39: 74.332344 | N39: 53.600776 | O39: 32.193743 | P39: 8.4485638 | Q39: 71.387283 | R39: 91 | S39: 70.2 | T39: GT | U39: B | V39: Muestreado de 2da. Estación | Y39: =IF(Table_GD[[#This Row],[Fecha]]=0,"",_xlfn.CONCAT("Sem ",WEEKNUM(Table_GD[[#This Row],[Fecha]],2))) -> Sem 10 | Z39: =+IF(P39>=12,P39,0) -> 0
B40: 46085 | C40: GD-260482 | D40: 0.076388889 | E40: SMCV | F40: 2A-M | G40: Sb | H40: 308.26691 | I40: 100 | J40: 100 | K40: 98.799741 | L40: 93.674313 | M40: 80.503908 | N40: 61.299771 | O40: 39.046328 | P40: 10.369879 | Q40: 71.606715 | R40: 9.3 | S40: 69.9 | T40: GT | U40: B | V40: Muestreado de descarga | Y40: =IF(Table_GD[[#This Row],[Fecha]]=0,"",_xlfn.CONCAT("Sem ",WEEKNUM(Table_GD[[#This Row],[Fecha]],2))) -> Sem 10 | Z40: =+IF(P40>=12,P40,0) -> 0
B41: 46085 | C41: GD-260483 | D41: 0.1875 | E41: SMCV | F41: 2 | G41: 2da.Est. | H41: 288.29941 | I41: 100 | J41: 99.861255 | K41: 99.306277 | L41: 96.219208 | M41: 84.876833 | N41: 65.799444 | O41: 43.704359 | P41: 11.793089 | Q41: 67.564895 | R41: 9.4 | S41: 69.4 | T41: GT | U41: B | V41: Muestreado de 2da. Estación | Y41: =IF(Table_GD[[#This Row],[Fecha]]=0,"",_xlfn.CONCAT("Sem ",WEEKNUM(Table_GD[[#This Row],[Fecha]],2))) -> Sem 10 | Z41: =+IF(P41>=12,P41,0) -> 0
...

Sheet Granulometrias de Verificación
C2: Control de Calidad
C3: PRESA DE RELAVES | F3: RESUMEN DE GRANULOMETRIAS DE LOS RELAVES EN EL DIQUE DE LA PRESA | AD3: Sin Formula
F4: =+B9 -> 46082 | AD4: revisar
K5: Datos en Laboratorio
L7: Nº 8 | M7: Nº 16 | N7: Nº 30 | O7: Nº 40 | P7: Nº 50 | Q7: Nº 70 | R7: Nº 100 | S7: Nº 200
B8: Fecha | C8: Código | D8: Hora | E8: Ejecutor | F8: Cancha | G8: Sp, Sb, A8,A9 | H8: Este-Oeste | I8: Sur-Norte | J8: Cota | K8: Peso de muestra (g) | L8: 2360 | M8: 1180 | N8: 600 | O8: 425 | P8: 300 | Q8: 212 | R8: 150 | S8: 75 | T8: Turno | U8: Ensayo asociado | V8: Tipo | W8: Resp. | X8: Observaciones | Y8: Column4 | Z8: Column2 | AA8: Column3 | AB8: Column1 | AC8: Semana | AD8: Fallas
B9: 46082 | C9: GV-260251 | E9: SMCV | F9: 4A-H | G9: Sp 51 | H9: 1700.27 | I9: 129.83 | J9: 2604.08 | K9: 308.4 | L9: 100 | M9: 100 | N9: 98.702983 | O9: 92.801556 | P9: 77.464332 | Q9: 56.906615 | R9: 35.667964 | S9: 13.845655 | T9: A | U9: DN-261022 | V9: - | W9: GM | AC9: =IF(Table_GV[[#This Row],[Fecha]]=0,"",_xlfn.CONCAT("Sem ",WEEKNUM(Table_GV[[#This Row],[Fecha]],2))) -> Sem 9 | AD9: =+IF(S9>=15.05,S9,0) -> 0
B10: 46082 | C10: GV-260252 | E10: SMCV | F10: 4B-H | G10: Sp 55 | H10: 1801.93 | I10: 190.9 | J10: 2573.74 | K10: 303.3 | L10: 100 | M10: 100 | N10: 98.120673 | O10: 90.273656 | P10: 72.33762 | Q10: 50.74184 | R10: 30.728652 | S10: 10.451698 | T10: A | U10: DN-261024 | V10: - | W10: GM | AC10: =IF(Table_GV[[#This Row],[Fecha]]=0,"",_xlfn.CONCAT("Sem ",WEEKNUM(Table_GV[[#This Row],[Fecha]],2))) -> Sem 9 | AD10: =+IF(S10>=15.05,S10,0) -> 0
B11: 46082 | C11: GV-260253 | E11: SMCV | F11: 3C-H | G11: Sp 45 | H11: 1475.25 | I11: 190.77 | J11: 2589.265 | K11: 291.1 | L11: 100 | M11: 100 | N11: 98.900721 | O11: 92.854689 | P11: 77.327379 | Q11: 56.338028 | R11: 34.077637 | S11: 11.301958 | T11: B | U11: DN-261033 | V11: - | W11: GM | AC11: =IF(Table_GV[[#This Row],[Fecha]]=0,"",_xlfn.CONCAT("Sem ",WEEKNUM(Table_GV[[#This Row],[Fecha]],2))) -> Sem 9 | AD11: =+IF(S11>=15.05,S11,0) -> 0
B12: 46083 | C12: GV-260254 | E12: SMCV | F12: 2A-H | G12: SA-UF | H12: 660.94 | I12: 84.9 | J12: 2635.54 | K12: 334.7 | L12: 100 | M12: 100 | N12: 98.595757 | O12: 93.128174 | P12: 78.577831 | Q12: 58.022109 | R12: 38.15357 | S12: 14.610099 | T12: A | U12: DN-261039 | V12: - | W12: GM | AC12: =IF(Table_GV[[#This Row],[Fecha]]=0,"",_xlfn.CONCAT("Sem ",WEEKNUM(Table_GV[[#This Row],[Fecha]],2))) -> Sem 10 | AD12: =+IF(S12>=15.05,S12,0) -> 0
B13: 46083 | C13: GV-260255 | E13: SMCV | F13: 3A-H | G13: Sp 38 | H13: 1244.03 | I13: 54.69 | J13: 2628.41 | K13: 282.3 | L13: 100 | M13: 100 | N13: 98.618491 | O13: 93.234148 | P13: 78.816861 | Q13: 57.49203 | R13: 36.308891 | S13: 13.248317 | T13: B | U13: DN-261044 | V13: - | W13: GT | AC13: =IF(Table_GV[[#This Row],[Fecha]]=0,"",_xlfn.CONCAT("Sem ",WEEKNUM(Table_GV[[#This Row],[Fecha]],2))) -> Sem 10 | AD13: =+IF(S13>=15.05,S13,0) -> 0
B14: 46084 | C14: GV-260256 | E14: SMCV | F14: 3B-H | G14: Sp 40 | H14: 1310.39 | I14: 33.1 | J14: 2634.28 | K14: 349.3 | L14: 100 | M14: 99.914114 | N14: 98.68308 | O14: 92.298883 | P14: 75.236187 | Q14: 54.394503 | R14: 33.839107 | S14: 12.453478 | T14: A | U14: DN-261048 | V14: - | W14: GT | AC14: =IF(Table_GV[[#This Row],[Fecha]]=0,"",_xlfn.CONCAT("Sem ",WEEKNUM(Table_GV[[#This Row],[Fecha]],2))) -> Sem 10 | AD14: =+IF(S14>=15.05,S14,0) -> 0
B15: 46084 | C15: GV-260257 | E15: SMCV | F15: 2C-M | G15: Sp 29 | H15: 940.81 | I15: 389.14 | J15: 2532.09 | K15: 345.8 | L15: 100 | M15: 100 | N15: 98.525159 | O15: 91.41122 | P15: 74.146906 | Q15: 53.528051 | R15: 32.301909 | S15: 11.017929 | T15: B | U15: DN-261055 | V15: - | W15: GT | AC15: =IF(Table_GV[[#This Row],[Fecha]]=0,"",_xlfn.CONCAT("Sem ",WEEKNUM(Table_GV[[#This Row],[Fecha]],2))) -> Sem 10 | AD15: =+IF(S15>=15.05,S15,0) -> 0
B16: 46084 | C16: GV-260258 | E16: SMCV | F16: 3A-L | G16: Sp 38 | H16: 1252.08 | I16: 531.59 | J16: 2489.66 | K16: 331 | L16: 100 | M16: 100 | N16: 99.033233 | O16: 93.897281 | P16: 79.637462 | Q16: 60.030211 | R16: 38.519637 | S16: 12.65861 | T16: B | U16: DN-261064 | V16: - | W16: GT | AC16: =IF(Table_GV[[#This Row],[Fecha]]=0,"",_xlfn.CONCAT("Sem ",WEEKNUM(Table_GV[[#This Row],[Fecha]],2))) -> Sem 10 | AD16: =+IF(S16>=15.05,S16,0) -> 0
B17: 46085 | C17: GV-260259 | E17: SMCV | F17: 3A-H | G17: Plataforma | H17: 1171 | I17: -2.73 | J17: 2635.9 | K17: 262.9 | L17: 100 | M17: 100 | N17: 99.049068 | O17: 94.256371 | P17: 79.878281 | Q17: 60.098897 | R17: 37.42868 | S17: 13.046786 | T17: A | U17: DN-261069 | V17: - | W17: GT | AC17: =IF(Table_GV[[#This Row],[Fecha]]=0,"",_xlfn.CONCAT("Sem ",WEEKNUM(Table_GV[[#This Row],[Fecha]],2))) -> Sem 10 | AD17: =+IF(S17>=15.05,S17,0) -> 0
B18: 46085 | C18: GV-260260 | E18: SMCV | F18: 3A-H | G18: Sp 36 | H18: 1183.5 | I18: 231.38 | J18: 2577.64 | K18: 328.55943 | L18: 100 | M18: 100 | N18: 98.721692 | O18: 92.238847 | P18: 74.829516 | Q18: 53.859185 | R18: 32.036649 | S18: 8.8749338 | T18: A | U18: DN-261072 | V18: - | W18: GT | AC18: =IF(Table_GV[[#This Row],[Fecha]]=0,"",_xlfn.CONCAT("Sem ",WEEKNUM(Table_GV[[#This Row],[Fecha]],2))) -> Sem 10 | AD18: =+IF(S18>=15.05,S18,0) -> 0
B19: 46085 | C19: GV-260261 | E19: SMCV | F19: 2C-M | G19: Sp 34 | H19: 1113.07 | I19: 340.75 | J19: 2547.51 | K19: 293.5 | L19: 100 | M19: 100 | N19: 98.739353 | O19: 92.197615 | P19: 76.524702 | Q19: 56.115843 | R19: 35.775128 | S19: 12.129472 | T19: A | U19: DN-261074 | V19: - | W19: GT | AC19: =IF(Table_GV[[#This Row],[Fecha]]=0,"",_xlfn.CONCAT("Sem ",WEEKNUM(Table_GV[[#This Row],[Fecha]],2))) -> Sem 10 | AD19: =+IF(S19>=15.05,S19,0) -> 0
B20: 46085 | C20: GV-260262 | E20: SMCV | F20: 3A-M | G20: Sp 38 | H20: 1239.12 | I20: 391.5 | J20: 2530.86 | K20: 365.04052 | L20: 100 | M20: 100 | N20: 99.452116 | O20: 95.808685 | P20: 83.946988 | Q20: 66.442082 | R20: 44.855437 | S20: 14.776585 | T20: A | U20: FN-517 | V20: Delimitación | W20: GT | X20: Asociado a FN-517 | AC20: =IF(Table_GV[[#This Row],[Fecha]]=0,"",_xlfn.CONCAT("Sem ",WEEKNUM(Table_GV[[#This Row],[Fecha]],2))) -> Sem 10 | AD20: =+IF(S20>=15.05,S20,0) -> 0
B21: 46085 | C21: GV-260263 | E21: SMCV | F21: 2A-H | G21: SA-03 | H21: 649.46 | I21: 61.67 | J21: 2636.33 | K21: 383.8 | L21: 100 | M21: 99.869724 | N21: 98.540907 | O21: 92.053153 | P21: 74.335591 | Q21: 53.491402 | R21: 32.751433 | S21: 11.907243 | T21: B | U21: DN-261077 | V21: - | W21: GT | AC21: =IF(Table_GV[[#This Row],[Fecha]]=0,"",_xlfn.CONCAT("Sem ",WEEKNUM(Table_GV[[#This Row],[Fecha]],2))) -> Sem 10 | AD21: =+IF(S21>=15.05,S21,0) -> 0
B22: 46085 | C22: GV-260264 | E22: SMCV | F22: 2C-M | G22: Sp 33 | H22: 1088.78 | I22: 425.41 | J22: 2521.38 | K22: 345.4 | L22: 100 | M22: 100 | N22: 98.81297 | O22: 93.080486 | P22: 77.562247 | Q22: 57.932831 | R22: 36.653156 | S22: 12.825709 | T22: B | U22: DN-261084 | V22: - | W22: GT | AC22: =IF(Table_GV[[#This Row],[Fecha]]=0,"",_xlfn.CONCAT("Sem ",WEEKNUM(Table_GV[[#This Row],[Fecha]],2))) -> Sem 10 | AD22: =+IF(S22>=15.05,S22,0) -> 0
B23: 46085 | C23: GV-260265 | E23: SMCV | F23: 2B-M | G23: Sp 29 | H23: 935.19 | I23: 382.2 | J23: 2533.7 | K23: 438.7 | L23: 100 | M23: 100 | N23: 98.81468 | O23: 92.819695 | P23: 77.50171 | Q23: 57.305676 | R23: 36.995669 | S23: 13.106907 | T23: B | U23: DN-261088 | V23: - | W23: GT | AC23: =IF(Table_GV[[#This Row],[Fecha]]=0,"",_xlfn.CONCAT("Sem ",WEEKNUM(Table_GV[[#This Row],[Fecha]],2))) -> Sem 10 | AD23: =+IF(S23>=15.05,S23,0) -> 0
B24: 46086 | C24: GV-260266 | E24: SMCV | F24: 2B-H | G24: Sp 27 | H24: 884.28 | I24: 236.13 | J24: 2574.05 | K24: 314.36344 | L24: 100 | M24: 100 | N24: 98.854829 | O24: 92.715438 | P24: 76.683039 | Q24: 55.815472 | R24: 35.234198 | S24: 10.326721 | T24: A | U24: DN-261092 | V24: - | W24: GT | AC24: =IF(Table_GV[[#This Row],[Fecha]]=0,"",_xlfn.CONCAT("Sem ",WEEKNUM(Table_GV[[#This Row],[Fecha]],2))) -> Sem 10 | AD24: =+IF(S24>=15.05,S24,0) -> 0
B25: 46086 | C25: GV-260267 | E25: SMCV | F25: 2A-M | G25: Sp 23 | H25: 739.73 | I25: 306.61 | J25: 2561.65 | K25: 346.42615 | L25: 100 | M25: 100 | N25: 98.672156 | O25: 92.119533 | P25: 75.146218 | Q25: 54.304835 | R25: 33.001594 | S25: 11.294226 | T25: A | U25: DN-261094 | V25: - | W25: GT | AC25: =IF(Table_GV[[#This Row],[Fecha]]=0,"",_xlfn.CONCAT("Sem ",WEEKNUM(Table_GV[[#This Row],[Fecha]],2))) -> Sem 10 | AD25: =+IF(S25>=15.05,S25,0) -> 0
B26: 46086 | C26: GV-260268 | E26: SMCV | F26: 2B-M | G26: Sp 28 | H26: 912.23 | I26: 429.7 | J26: 2520.41 | K26: 306.53524 | L26: 100 | M26: 100 | N26: 98.466734 | O26: 91.387613 | P26: 74.65218 | Q26: 54.263007 | R26: 34.395797 | S26: 12.179754 | T26: A | U26: DN-261096 | V26: - | W26: GT | AC26: =IF(Table_GV[[#This Row],[Fecha]]=0,"",_xlfn.CONCAT("Sem ",WEEKNUM(Table_GV[[#This Row],[Fecha]],2))) -> Sem 10 | AD26: =+IF(S26>=15.05,S26,0) -> 0
B27: 46086 | C27: GV-260269 | E27: SMCV | F27: 2A-H | G27: SA-03 | H27: 648.7 | I27: 60.65 | J27: 2636.71 | K27: 337.3 | L27: 100 | M27: 99.940706 | N27: 98.339757 | O27: 91.10584 | P27: 74.206937 | Q27: 53.602135 | R27: 31.900385 | S27: 7.471094 | T27: B | U27: DN-261101 | V27: - | W27: GT | AC27: =IF(Table_GV[[#This Row],[Fecha]]=0,"",_xlfn.CONCAT("Sem ",WEEKNUM(Table_GV[[#This Row],[Fecha]],2))) -> Sem 10 | AD27: =+IF(S27>=15.05,S27,0) -> 0
B28: 46086 | C28: GV-260270 | E28: SMCV | F28: 1C-M | G28: Sp 15 | H28: 483.66 | I28: 304.12 | J28: 2576.56 | K28: 326.6 | L28: 100 | M28: 99.846908 | N28: 98.683405 | O28: 92.620943 | P28: 76.944274 | Q28: 56.91978 | R28: 35.609308 | S28: 12.737293 | T28: B | U28: DN-261112 | V28: - | W28: GT | AC28: =IF(Table_GV[[#This Row],[Fecha]]=0,"",_xlfn.CONCAT("Sem ",WEEKNUM(Table_GV[[#This Row],[Fecha]],2))) -> Sem 10 | AD28: =+IF(S28>=15.05,S28,0) -> 0
B29: 46086 | C29: GV-260271 | E29: SMCV | F29: 1C-M | G29: Sp 16 | H29: 514.18 | I29: 374.13 | J29: 2558.32 | K29: 346.9 | L29: 100 | M29: 99.91352 | N29: 98.616316 | O29: 92.332084 | P29: 76.419717 | Q29: 56.500432 | R29: 36.754108 | S29: 12.539637 | T29: B | U29: DN-261114 | V29: - | W29: GT | AC29: =IF(Table_GV[[#This Row],[Fecha]]=0,"",_xlfn.CONCAT("Sem ",WEEKNUM(Table_GV[[#This Row],[Fecha]],2))) -> Sem 10 | AD29: =+IF(S29>=15.05,S29,0) -> 0
B30: 46087 | C30: GV-260272 | E30: SMCV | F30: 2A-H | G30: Sp 21 | H30: 672.16 | I30: 240.06 | J30: 2591.73 | K30: 400.4 | L30: 100 | M30: 100 | N30: 98.776224 | O30: 92.882118 | P30: 77.772228 | Q30: 58.991009 | R30: 38.236763 | S30: 13.786214 | T30: A | U30: DN-261117 | V30: - | W30: GT | AC30: =IF(Table_GV[[#This Row],[Fecha]]=0,"",_xlfn.CONCAT("Sem ",WEEKNUM(Table_GV[[#This Row],[Fecha]],2))) -> Sem 10 | AD30: =+IF(S30>=15.05,S30,0) -> 0
B31: 46087 | C31: GV-260273 | E31: SMCV | F31: 1C-M | G31: Sp 15 | H31: 492.2 | I31: 272.4 | J31: 2586.39 | K31: 474.9 | L31: 100 | M31: 100 | N31: 98.799747 | O31: 93.724995 | P31: 79.279848 | Q31: 60.391661 | R31: 39.945252 | S31: 15.055801 | T31: A | U31: FN-518 | V31: Adyacente | W31: GT | X31: Asociado a FN-518 | AC31: =IF(Table_GV[[#This Row],[Fecha]]=0,"",_xlfn.CONCAT("Sem ",WEEKNUM(Table_GV[[#This Row],[Fecha]],2))) -> Sem 10 | AD31: =+IF(S31>=15.05,S31,0) -> 15.055801
B32: 46087 | C32: GV-260274 | E32: SMCV | F32: 1C-M | G32: Sp 15 | H32: 501.62 | I32: 277.38 | J32: 2585.1 | K32: 360.9 | L32: 100 | M32: 100 | N32: 98.088113 | O32: 90.274314 | P32: 73.261291 | Q32: 52.701579 | R32: 32.335827 | S32: 10.778609 | T32: B | U32: FN-518 | V32: Delimitación | W32: GT | X32: Asociado a FN-518 | AC32: =IF(Table_GV[[#This Row],[Fecha]]=0,"",_xlfn.CONCAT("Sem ",WEEKNUM(Table_GV[[#This Row],[Fecha]],2))) -> Sem 10 | AD32: =+IF(S32>=15.05,S32,0) -> 0
B33: 46088 | C33: GV-260275 | E33: SMCV | F33: 1A-H | G33: Sp 6 | H33: 173.47 | I33: 96.44 | J33: 2632.54 | K33: 355.8 | L33: 100 | M33: 99.718943 | N33: 99.072513 | O33: 95.362563 | P33: 82.686903 | Q33: 62.394604 | R33: 40.697021 | S33: 13.827993 | T33: B | U33: DN-261126 | V33: - | W33: GM | AC33: =IF(Table_GV[[#This Row],[Fecha]]=0,"",_xlfn.CONCAT("Sem ",WEEKNUM(Table_GV[[#This Row],[Fecha]],2))) -> Sem 10 | AD33: =+IF(S33>=15.05,S33,0) -> 0
B34: 46088 | C34: GV-260276 | E34: SMCV | F34: 1B-H | G34: Plataforma | H34: 343.08 | I34: 62.01 | J34: 2635.9 | K34: 384.2 | L34: 100 | M34: 99.921916 | N34: 99.557522 | O34: 97.058824 | P34: 86.595523 | Q34: 66.501822 | R34: 42.581989 | S34: 14.497657 | T34: B | U34: DN-261132 | V34: - | W34: GM | AC34: =IF(Table_GV[[#This Row],[Fecha]]=0,"",_xlfn.CONCAT("Sem ",WEEKNUM(Table_GV[[#This Row],[Fecha]],2))) -> Sem 10 | AD34: =+IF(S34>=15.05,S34,0) -> 0
B35: 46089 | C35: GV-260277 | E35: SMCV | F35: 1A-H | G35: Sp 3 | H35: 79.09 | I35: 54.36 | J35: 2633.986 | K35: 340.9 | L35: 100 | M35: 100 | N35: 99.295981 | O35: 96.421238 | P35: 86.212966 | Q35: 67.028454 | R35: 43.531828 | S35: 14.520387 | T35: A | U35: CA-260113 | V35: Adyacente | W35: GM | X35: Asociado a FN-519 | AC35: =IF(Table_GV[[#This Row],[Fecha]]=0,"",_xlfn.CONCAT("Sem ",WEEKNUM(Table_GV[[#This Row],[Fecha]],2))) -> Sem 10 | AD35: =+IF(S35>=15.05,S35,0) -> 0
B36: 46089 | C36: GV-260278 | E36: SMCV | F36: 1A-H | G36: Sp 8 | H36: 242.03 | I36: 59.44 | J36: 2635.901 | K36: 413.6 | L36: 100 | M36: 100 | N36: 99.468085 | O36: 95.98646 | P36: 82.857834 | Q36: 61.750484 | R36: 40.062863 | S36: 13.902321 | T36: A | U36: FN-519 | V36: Adyacente | W36: GM | X36: Asociado a FN-519 | AC36: =IF(Table_GV[[#This Row],[Fecha]]=0,"",_xlfn.CONCAT("Sem ",WEEKNUM(Table_GV[[#This Row],[Fecha]],2))) -> Sem 10 | AD36: =+IF(S36>=15.05,S36,0) -> 0
B37: 46089 | C37: GV-260279 | E37: SMCV | F37: 1C-H | G37: Plataforma | H37: 517.29 | I37: 68.62 | J37: 2635.899 | K37: 347.5 | L37: 100 | M37: 100 | N37: 99.568345 | O37: 97.611511 | P37: 87.568345 | Q37: 66.589928 | R37: 40.863309 | S37: 12.57554 | T37: A | U37: DN-261136 | V37: - | W37: GM | AC37: =IF(Table_GV[[#This Row],[Fecha]]=0,"",_xlfn.CONCAT("Sem ",WEEKNUM(Table_GV[[#This Row],[Fecha]],2))) -> Sem 10 | AD37: =+IF(S37>=15.05,S37,0) -> 0
B38: 46089 | C38: GV-260280 | E38: SMCV | F38: 4B-H | G38: Sp 58 | H38: 1874.82 | I38: 145.31 | J38: 2576.827 | K38: 392.9 | L38: 100 | M38: 100 | N38: 98.091117 | O38: 91.168236 | P38: 74.217358 | Q38: 52.405192 | R38: 32.451005 | S38: 11.376941 | T38: A | U38: DN-261137 | V38: - | W38: GM | AC38: =IF(Table_GV[[#This Row],[Fecha]]=0,"",_xlfn.CONCAT("Sem ",WEEKNUM(Table_GV[[#This Row],[Fecha]],2))) -> Sem 10 | AD38: =+IF(S38>=15.05,S38,0) -> 0
B39: 46089 | C39: GV-260281 | E39: SMCV | F39: 1A-H | G39: Sp 3 | H39: 90.62 | I39: 59.7 | J39: 2633.49 | K39: 283.9 | L39: 100 | M39: 100 | N39: 99.154632 | O39: 94.610778 | P39: 81.155336 | Q39: 61.71187 | R39: 39.697076 | S39: 14.512152 | T39: B | U39: FN-519 | V39: Delimitación | W39: GM | X39: Asociado a FN-519 | AC39: =IF(Table_GV[[#This Row],[Fecha]]=0,"",_xlfn.CONCAT("Sem ",WEEKNUM(Table_GV[[#This Row],[Fecha]],2))) -> Sem 10 | AD39: =+IF(S39>=15.05,S39,0) -> 0
B40: 46089 | C40: GV-260282 | E40: SMCV | F40: 3C-M | G40: Sp 45 | H40: 1474.59 | I40: 366.51 | J40: 2538.05 | K40: 284.1 | L40: 100 | M40: 100 | N40: 98.592045 | O40: 92.361844 | P40: 75.712777 | Q40: 54.38226 | R40: 34.811686 | S40: 14.396339 | T40: B | U40: DN-261145 | V40: - | W40: GM | AC40: =IF(Table_GV[[#This Row],[Fecha]]=0,"",_xlfn.CONCAT("Sem ",WEEKNUM(Table_GV[[#This Row],[Fecha]],2))) -> Sem 10 | AD40: =+IF(S40>=15.05,S40,0) -> 0
B41: 46089 | C41: GV-260283 | E41: SMCV | F41: 3C-M | G41: Sp 48 | H41: 1597.64 | I41: 403.68 | J41: 2525.36 | K41: 296.6 | L41: 100 | M41: 100 | N41: 98.718813 | O41: 93.054619 | P41: 76.803776 | Q41: 56.169926 | R41: 36.210384 | S41: 14.699933 | T41: B | U41: DN-261146 | V41: - | W41: GM | AC41: =IF(Table_GV[[#This Row],[Fecha]]=0,"",_xlfn.CONCAT("Sem ",WEEKNUM(Table_GV[[#This Row],[Fecha]],2))) -> Sem 10 | AD41: =+IF(S41>=15.05,S41,0) -> 0
B42: 46089 | C42: GV-260284 | E42: SMCV | F42: 3B-M | G42: Sp 41 | H42: 1335.09 | I42: 303.69 | J42: 2556.74 | K42: 248.3 | L42: 100 | M42: 100 | N42: 98.429319 | O42: 92.227145 | P42: 75.513492 | Q42: 53.483689 | R42: 33.427306 | S42: 12.72654 | T42: B | U42: DN-261152 | V42: - | W42: GM | AC42: =IF(Table_GV[[#This Row],[Fecha]]=0,"",_xlfn.CONCAT("Sem ",WEEKNUM(Table_GV[[#This Row],[Fecha]],2))) -> Sem 10 | AD42: =+IF(S42>=15.05,S42,0) -> 0
...

Sheet Granulometrias Cono de Arena
C2: Control de Calidad
C3: PRESA DE RELAVES | F3: RESUMEN DE GRANULOMETRIAS DE LOS RELAVES EN EL DIQUE DE LA PRESA | Y3: Sin Formula
F4: =+B9 -> 46082 | Y4: revisar
M7: Nº 8 | N7: Nº 16 | O7: Nº 30 | P7: Nº 40 | Q7: Nº 50 | R7: Nº 70 | S7: Nº 100 | T7: Nº 200
B8: Fecha | C8: Código | D8: Hora | E8: Ejecutor | F8: Cancha | G8: Sp, Sb | H8: Este-Oeste | I8: Sur-Norte | J8: Cota | K8: Ensayo | L8: Peso de muestra (g) | M8: 2360 | N8: 1180 | O8: 600 | P8: 425 | Q8: 300 | R8: 212 | S8: 150 | T8: 75 | U8: Resp | V8: Turno | W8: Observaciones | X8: Semana | Y8: Falla
B9: 46082 | C9: CA-260102 | E9: SMCV | F9: 4B-H | G9: Sp 57 | H9: 1845.17 | I9: 98.61 | J9: 2590.66 | K9: Cono de arena | L9: 332.1 | M9: 100 | N9: 100 | O9: 98.614875 | P9: 92.622704 | Q9: 76.96477 | R9: 56.519121 | S9: 35.350798 | T9: 13.158687 | U9: GM | V9: A | X9: =IF(Table_GCA[[#This Row],[Fecha]]=0,"",_xlfn.CONCAT("Sem ",WEEKNUM(Table_GCA[[#This Row],[Fecha]],2))) -> Sem 9 | Y9: =+IF(T9>=15.05,T9,0) -> 0
B10: 46082 | C10: CA-260103 | E10: SMCV | F10: 2A-H | G10: Plataforma | H10: 661.66 | I10: 45.54 | J10: 2635.6 | K10: Cono de arena | L10: 319.6 | M10: 100 | N10: 100 | O10: 98.998748 | P10: 93.585732 | Q10: 77.377972 | R10: 55.97622 | S10: 35.294118 | T10: 11.98373 | U10: GM | V10: A1 | X10: =IF(Table_GCA[[#This Row],[Fecha]]=0,"",_xlfn.CONCAT("Sem ",WEEKNUM(Table_GCA[[#This Row],[Fecha]],2))) -> Sem 9 | Y10: =+IF(T10>=15.05,T10,0) -> 0
B11: 46083 | C11: CA-260104 | E11: SMCV | F11: 2B-H | G11: P.76 UF | H11: 818.24 | I11: 19.36 | J11: 2635.61 | K11: Cono de arena | L11: 293.3 | M11: 100 | N11: 100 | O11: 98.772588 | P11: 91.783157 | Q11: 72.690078 | R11: 50.937607 | S11: 29.526083 | T11: 10.398909 | U11: GM | V11: A | X11: =IF(Table_GCA[[#This Row],[Fecha]]=0,"",_xlfn.CONCAT("Sem ",WEEKNUM(Table_GCA[[#This Row],[Fecha]],2))) -> Sem 10 | Y11: =+IF(T11>=15.05,T11,0) -> 0
B12: 46084 | C12: CA-260105 | E12: SMCV | F12: 3C-H | G12: Sp 45 | H12: 1478.91 | I12: 48.98 | J12: 2630.09 | K12: Cono de arena | L12: 338.3 | M12: 100 | N12: 99.940881 | O12: 98.64026 | P12: 92.284954 | Q12: 76.32279 | R12: 55.365061 | S12: 34.525569 | T12: 10.8188 | U12: GT | V12: A | X12: =IF(Table_GCA[[#This Row],[Fecha]]=0,"",_xlfn.CONCAT("Sem ",WEEKNUM(Table_GCA[[#This Row],[Fecha]],2))) -> Sem 10 | Y12: =+IF(T12>=15.05,T12,0) -> 0
B13: 46084 | C13: CA-260106 | E13: SMCV | F13: 2C-L | G13: Sp 33 | H13: 1085.92 | I13: 590.98 | J13: 2472.27 | K13: Cono de arena | L13: 359.81933 | M13: 100 | N13: 100 | O13: 98.443663 | P13: 91.968191 | Q13: 74.237071 | R13: 52.698484 | S13: 32.549483 | T13: 11.06648 | U13: GT | V13: B | X13: =IF(Table_GCA[[#This Row],[Fecha]]=0,"",_xlfn.CONCAT("Sem ",WEEKNUM(Table_GCA[[#This Row],[Fecha]],2))) -> Sem 10 | Y13: =+IF(T13>=15.05,T13,0) -> 0
B14: 46085 | C14: CA-260107 | E14: SMCV | F14: 2C-L | G14: Sp 33 | H14: 1085.92 | I14: 590.98 | J14: 2472.27 | K14: Cono de arena | L14: 359.81933 | M14: 100 | N14: 100 | O14: 98.443663 | P14: 91.968191 | Q14: 74.237071 | R14: 52.698484 | S14: 32.549483 | T14: 11.06648 | U14: GT | V14: A | X14: =IF(Table_GCA[[#This Row],[Fecha]]=0,"",_xlfn.CONCAT("Sem ",WEEKNUM(Table_GCA[[#This Row],[Fecha]],2))) -> Sem 10 | Y14: =+IF(T14>=15.05,T14,0) -> 0
B15: 46085 | C15: CA-260108 | E15: SMCV | F15: 2C-H | G15: Sp 30 | H15: 972.92 | I15: 228.97 | J15: 2577.48 | K15: Cono de arena | L15: 428.99511 | M15: 100 | N15: 99.930069 | O15: 98.997658 | P15: 94.219048 | Q15: 80.489288 | R15: 60.675543 | S15: 40.022627 | T15: 14.614412 | U15: GT | V15: B | X15: =IF(Table_GCA[[#This Row],[Fecha]]=0,"",_xlfn.CONCAT("Sem ",WEEKNUM(Table_GCA[[#This Row],[Fecha]],2))) -> Sem 10 | Y15: =+IF(T15>=15.05,T15,0) -> 0
B16: 46086 | C16: CA-260109 | E16: SMCV | F16: 2C-L | G16: Sp 33 | H16: 1543.86 | I16: -25.24 | J16: 2635.9 | K16: Cono de arena | L16: 359.81933 | M16: 100 | N16: 100 | O16: 98.443663 | P16: 91.968191 | Q16: 74.237071 | R16: 52.698484 | S16: 32.549483 | T16: 11.06648 | U16: GT | V16: A | X16: =IF(Table_GCA[[#This Row],[Fecha]]=0,"",_xlfn.CONCAT("Sem ",WEEKNUM(Table_GCA[[#This Row],[Fecha]],2))) -> Sem 10 | Y16: =+IF(T16>=15.05,T16,0) -> 0
B17: 46086 | C17: CA-260110 | E17: SMCV | F17: 2C-L | G17: Sp 33 | H17: 883.1 | I17: 612.92 | J17: 2469.85 | K17: Cono de arena | L17: 359.81933 | M17: 100 | N17: 100 | O17: 98.443663 | P17: 91.968191 | Q17: 74.237071 | R17: 52.698484 | S17: 32.549483 | T17: 11.06648 | U17: GT | V17: A1 | X17: =IF(Table_GCA[[#This Row],[Fecha]]=0,"",_xlfn.CONCAT("Sem ",WEEKNUM(Table_GCA[[#This Row],[Fecha]],2))) -> Sem 10 | Y17: =+IF(T17>=15.05,T17,0) -> 0
B18: 46086 | C18: CA-260111 | E18: SMCV | F18: 1C-M | G18: Sp 17 | H18: 565.53 | I18: 298.68 | J18: 2578.52 | K18: Cono de arena | L18: 395.50079 | M18: 100 | N18: 99.898862 | O18: 98.887486 | P18: 93.729469 | Q18: 79.696627 | R18: 60.783896 | S18: 41.239055 | T18: 13.198655 | U18: GT | V18: B | X18: =IF(Table_GCA[[#This Row],[Fecha]]=0,"",_xlfn.CONCAT("Sem ",WEEKNUM(Table_GCA[[#This Row],[Fecha]],2))) -> Sem 10 | Y18: =+IF(T18>=15.05,T18,0) -> 0
B19: 46087 | C19: CA-260112 | E19: SMCV | F19: 2A-M | G19: Sp 21 | H19: 676.36 | I19: 321.32 | J19: 2570.06 | K19: Cono de arena | L19: 433.5 | M19: 100 | N19: 100 | O19: 98.800461 | P19: 93.171857 | Q19: 78.93887 | R19: 59.377163 | S19: 39.331027 | T19: 13.61015 | U19: GT | V19: A | X19: =IF(Table_GCA[[#This Row],[Fecha]]=0,"",_xlfn.CONCAT("Sem ",WEEKNUM(Table_GCA[[#This Row],[Fecha]],2))) -> Sem 10 | Y19: =+IF(T19>=15.05,T19,0) -> 0
B20: 46088 | C20: CA-260113 | E20: SMCV | F20: 1A-H | G20: Plataforma | H20: 242.4 | I20: 59.97 | J20: 2635.9 | K20: Cono de arena | L20: 437.9 | M20: 100 | N20: 99.931491 | O20: 99.474766 | P20: 95.775291 | Q20: 81.66248 | R20: 61.269696 | S20: 39.392555 | T20: 15.277461 | U20: GM | V20: B | X20: =IF(Table_GCA[[#This Row],[Fecha]]=0,"",_xlfn.CONCAT("Sem ",WEEKNUM(Table_GCA[[#This Row],[Fecha]],2))) -> Sem 10 | Y20: =+IF(T20>=15.05,T20,0) -> 15.277461
... B34: 46096 | C34: CA-260127 | E34: SMCV | F34: 4B-H | G34: Sp 57 | H34: 1836.33 | I34: 188.01 | J34: 2571.45 | K34: Cono de arena | L34: 338.74257 | M34: 100 | N34: 100 | O34: 99.173414 | P34: 94.331979 | Q34: 79.453424 | R34: 59.083974 | S34: 36.559495 | T34: 12.175196 | U34: GT | V34: B | X34: =IF(Table_GCA[[#This Row],[Fecha]]=0,"",_xlfn.CONCAT("Sem ",WEEKNUM(Table_GCA[[#This Row],[Fecha]],2))) -> Sem 11 | Y34: =+IF(T34>=15.05,T34,0) -> 0
B35: 46097 | C35: CA-260128 | E35: SMCV | F35: 3A-M | G35: Sp 39 | H35: 1278.24 | I35: 331.44 | J35: 2548.62 | K35: Cono de arena | L35: 366.95402 | M35: 100 | N35: 100 | O35: 98.882694 | P35: 93.023649 | Q35: 76.700078 | R35: 56.016288 | S35: 34.460453 | T35: 11.596553 | U35: GT | V35: A | X35: =IF(Table_GCA[[#This Row],[Fecha]]=0,"",_xlfn.CONCAT("Sem ",WEEKNUM(Table_GCA[[#This Row],[Fecha]],2))) -> Sem 12 | Y35: =+IF(T35>=15.05,T35,0) -> 0 | AN35: B
B36: 46097 | C36: CA-260129 | E36: SMCV | F36: 3C-M | G36: Sp 45 | H36: 1475.88 | I36: 324.65 | J36: 2550.83 | K36: Cono de arena | L36: 272.61456 | M36: 100 | N36: 100 | O36: 98.606091 | P36: 92.37018 | Q36: 76.670358 | R36: 56.532035 | S36: 36.246985 | T36: 11.560116 | U36: GT | V36: A1 | X36: =IF(Table_GCA[[#This Row],[Fecha]]=0,"",_xlfn.CONCAT("Sem ",WEEKNUM(Table_GCA[[#This Row],[Fecha]],2))) -> Sem 12 | Y36: =+IF(T36>=15.05,T36,0) -> 0
B37: 46097 | C37: CA-260130 | E37: SMCV | F37: 3A-L | G37: Sp 38 | H37: 1263.49 | I37: 590.74 | J37: 2471.93 | K37: Cono de arena | L37: 418.00173 | M37: 100 | N37: 100 | O37: 98.803833 | P37: 91.291902 | Q37: 75.04795 | R37: 53.995405 | S37: 32.273007 | T37: 10.765919 | U37: GT | V37: B | X37: =IF(Table_GCA[[#This Row],[Fecha]]=0,"",_xlfn.CONCAT("Sem ",WEEKNUM(Table_GCA[[#This Row],[Fecha]],2))) -> Sem 12 | Y37: =+IF(T37>=15.05,T37,0) -> 0
B38: 46098 | C38: CA-260131 | E38: SMCV | F38: 2B-M | G38: Sp 29 | H38: 931.78 | I38: 313.88 | J38: 2554.14 | K38: Cono de arena | L38: 495.8752 | M38: 100 | N38: 100 | O38: 98.689186 | P38: 92.437613 | Q38: 75.921361 | R38: 55.089506 | S38: 33.652661 | T38: 11.409161 | U38: GT | V38: A | X38: =IF(Table_GCA[[#This Row],[Fecha]]=0,"",_xlfn.CONCAT("Sem ",WEEKNUM(Table_GCA[[#This Row],[Fecha]],2))) -> Sem 12 | Y38: =+IF(T38>=15.05,T38,0) -> 0
B39: 46098 | C39: CA-260132 | E39: SMCV | F39: 3A-M | G39: Sp 38 | H39: 1256.59 | I39: 274.48 | J39: 2565.697 | K39: Cono de arena | L39: 333.9532 | M39: 100 | N39: 100 | O39: 98.981893 | P39: 93.352362 | Q39: 77.601652 | R39: 57.598849 | S39: 36.188663 | T39: 13.371095 | U39: GM | V39: B | X39: =IF(Table_GCA[[#This Row],[Fecha]]=0,"",_xlfn.CONCAT("Sem ",WEEKNUM(Table_GCA[[#This Row],[Fecha]],2))) -> Sem 12 | Y39: =+IF(T39>=15.05,T39,0) -> 0
B40: 46099 | C40: CA-260133 | E40: SMCV | F40: 2B-L | G40: Sp 29 | H40: 926.65 | I40: 500.76 | J40: 2500.28 | K40: Cono de arena | L40: 377.1 | M40: 100 | N40: 100 | O40: 98.859719 | P40: 93.21135 | Q40: 77.75126 | R40: 57.2262 | S40: 36.648104 | T40: 12.224874 | U40: GM | V40: A | X40: =IF(Table_GCA[[#This Row],[Fecha]]=0,"",_xlfn.CONCAT("Sem ",WEEKNUM(Table_GCA[[#This Row],[Fecha]],2))) -> Sem 12 | Y40: =+IF(T40>=15.05,T40,0) -> 0
B41: 46099 | C41: CA-260134 | E41: SMCV | F41: 4B-H | G41: Sp 58 | H41: 1873.25 | I41: 30.07 | J41: 2602.461 | K41: Cono de arena | L41: 315.8 | M41: 100 | N41: 100 | O41: 98.923369 | P41: 93.223559 | Q41: 76.757441 | R41: 55.319823 | S41: 34.103863 | T41: 12.951235 | U41: GM | V41: B | X41: =IF(Table_GCA[[#This Row],[Fecha]]=0,"",_xlfn.CONCAT("Sem ",WEEKNUM(Table_GCA[[#This Row],[Fecha]],2))) -> Sem 12 | Y41: =+IF(T41>=15.05,T41,0) -> 0
B42: 46100 | C42: CA-260135 | E42: SMCV | F42: 3B-H | G42: Sp 41 | H42: 1347.77 | I42: -5.33 | J42: 2636.218 | K42: Cono de arena | L42: 333 | M42: 100 | N42: 100 | O42: 98.528529 | P42: 94.054054 | Q42: 77.297297 | R42: 56.726727 | S42: 36.696697 | T42: 14.474474 | U42: GM | V42: B | X42: =IF(Table_GCA[[#This Row],[Fecha]]=0,"",_xlfn.CONCAT("Sem ",WEEKNUM(Table_GCA[[#This Row],[Fecha]],2))) -> Sem 12 | Y42: =+IF(T42>=15.05,T42,0) -> 0
B43: 46101 | C43: CA-260136 | E43: SMCV | F43: 3C-H | G43: SA-UF | H43: 1509.76 | I43: 26.7 | J43: 2636.18 | K43: Cono de arena | L43: 302.1 | M43: 100 | N43: 100 | O43: 98.278716 | P43: 91.161867 | Q43: 74.08143 | R43: 53.823237 | S43: 33.200927 | T43: 12.44621 | U43: GM | V43: A | X43: =IF(Table_GCA[[#This Row],[Fecha]]=0,"",_xlfn.CONCAT("Sem ",WEEKNUM(Table_GCA[[#This Row],[Fecha]],2))) -> Sem 12 | Y43: =+IF(T43>=15.05,T43,0) -> 0
B44: 46101 | C44: CA-260137 | E44: SMCV | F44: 2A-L | G44: Sp 23 | H44: 736.67 | I44: 526.93 | J44: 2508.448 | K44: Cono de arena | L44: 345.2 | M44: 100 | N44: 99.913094 | O44: 98.899189 | P44: 94.032445 | Q44: 79.692932 | R44: 58.922364 | S44: 37.485516 | T44: 12.630359 | U44: GM | V44: A | X44: =IF(Table_GCA[[#This Row],[Fecha]]=0,"",_xlfn.CONCAT("Sem ",WEEKNUM(Table_GCA[[#This Row],[Fecha]],2))) -> Sem 12 | Y44: =+IF(T44>=15.05,T44,0) -> 0
B45: 46101 | C45: CA-260138 | E45: SMCV | F45: 1C-H | G45: Sp 14 | H45: 463.91 | I45: 161.04 | J45: 2620.23 | K45: Cono de arena | L45: 324.6 | M45: 100 | N45: 100 | O45: 98.92175 | P45: 94.177449 | Q45: 79.359211 | R45: 59.365373 | S45: 39.279113 | T45: 13.647566 | U45: GM | V45: B | X45: =IF(Table_GCA[[#This Row],[Fecha]]=0,"",_xlfn.CONCAT("Sem ",WEEKNUM(Table_GCA[[#This Row],[Fecha]],2))) -> Sem 12 | Y45: =+IF(T45>=15.05,T45,0) -> 0
B46: 46102 | C46: CA-260139 | E46: SMCV | F46: 2A-H | G46: Sp 21 | H46: 693.25 | I46: 209.34 | J46: 2598.42 | K46: Cono de arena | L46: 366.2 | M46: 100 | N46: 100 | O46: 98.853086 | P46: 93.227744 | Q46: 76.67941 | R46: 53.304205 | S46: 31.103222 | T46: 9.9945385 | U46: GM | V46: A | X46: =IF(Table_GCA[[#This Row],[Fecha]]=0,"",_xlfn.CONCAT("Sem ",WEEKNUM(Table_GCA[[#This Row],[Fecha]],2))) -> Sem 12 | Y46: =+IF(T46>=15.05,T46,0) -> 0
B47: 46102 | C47: CA-260140 | E47: SMCV | F47: 3B-H | G47: Sp 42 | H47: 1372.06 | I47: 232.42 | J47: 2579.132 | K47: Cono de arena | L47: 391 | M47: 100 | N47: 100 | O47: 99.232737 | P47: 95.11509 | Q47: 82.531969 | R47: 63.42711 | S47: 40.511509 | T47: 14.88491 | U47: GM | V47: B | X47: =IF(Table_GCA[[#This Row],[Fecha]]=0,"",_xlfn.CONCAT("Sem ",WEEKNUM(Table_GCA[[#This Row],[Fecha]],2))) -> Sem 12 | Y47: =+IF(T47>=15.05,T47,0) -> 0
... B70: 46112 | C70: CA-260163 | E70: SMCV | F70: 2A-M | G70: Sp 20 | H70: 652.55 | I70: 401.2 | J70: 2548.422 | K70: Cono de arena | L70: 401.3 | M70: 100 | N70: 100 | O70: 98.704211 | P70: 90.90456 | Q70: 71.46773 | R70: 46.822826 | S70: 27.53551 | T70: 11.761774 | U70: GM | V70: A | X70: =IF(Table_GCA[[#This Row],[Fecha]]=0,"",_xlfn.CONCAT("Sem ",WEEKNUM(Table_GCA[[#This Row],[Fecha]],2))) -> Sem 14 | Y70: =+IF(T70>=15.05,T70,0) -> 0
B71: 46112 | C71: CA-260164 | E71: SMCV | F71: 1C-M | G71: Sp 14 | H71: 443.32 | I71: 314.65 | J71: 2573.81 | K71: Cono de arena | L71: 300.06731 | M71: 100 | N71: 100 | O71: 99.43346 | P71: 96.467459 | Q71: 86.269747 | R71: 67.307335 | S71: 46.578652 | T71: 14.919089 | U71: GM | V71: B | X71: =IF(Table_GCA[[#This Row],[Fecha]]=0,"",_xlfn.CONCAT("Sem ",WEEKNUM(Table_GCA[[#This Row],[Fecha]],2))) -> Sem 14
X72: =IF(Table_GCA[[#This Row],[Fecha]]=0,"",_xlfn.CONCAT("Sem ",WEEKNUM(Table_GCA[[#This Row],[Fecha]],2)))
X73: =IF(Table_GCA[[#This Row],[Fecha]]=0,"",_xlfn.CONCAT("Sem ",WEEKNUM(Table_GCA[[#This Row],[Fecha]],2)))
X74: =IF(Table_GCA[[#This Row],[Fecha]]=0,"",_xlfn.CONCAT("Sem ",WEEKNUM(Table_GCA[[#This Row],[Fecha]],2)))
X75: =IF(Table_GCA[[#This Row],[Fecha]]=0,"",_xlfn.CONCAT("Sem ",WEEKNUM(Table_GCA[[#This Row],[Fecha]],2)))
X76: =IF(Table_GCA[[#This Row],[Fecha]]=0,"",_xlfn.CONCAT("Sem ",WEEKNUM(Table_GCA[[#This Row],[Fecha]],2)))
X77: =IF(Table_GCA[[#This Row],[Fecha]]=0,"",_xlfn.CONCAT("Sem ",WEEKNUM(Table_GCA[[#This Row],[Fecha]],2)))
X78: =IF(Table_GCA[[#This Row],[Fecha]]=0,"",_xlfn.CONCAT("Sem ",WEEKNUM(Table_GCA[[#This Row],[Fecha]],2)))
...

Sheet Granulometrias Proctor
C2: Control de Calidad
C3: PRESA DE RELAVES | J3: RESUMEN DE GRANULOMETRIAS DE LOS RELAVES AGUAS EN EL DIQUE DE LA PRESA | Y3: Sin Formula
F4: ='Granulometrias Descarga'!F4:V4 -> 46082 | Y4: revisar
M7: Nº 8 | N7: Nº 16 | O7: Nº 30 | P7: Nº 40 | Q7: Nº 50 | R7: Nº 70 | S7: Nº 100 | T7: Nº 200
B8: Fecha | C8: Código | D8: Hora | E8: Ejecutor | F8: Cancha | G8: Sp, Sb, A8,A9 | H8: Este-Oeste | I8: Sur-Norte | J8: Cota | K8: Ensayo | L8: Peso de muestra (g) | M8: 2360 | N8: 1180 | O8: 600 | P8: 425 | Q8: 300 | R8: 212 | S8: 150 | T8: 75 | U8: Resp | V8: Turno | W8: Observaciones | X8: Semana | Y8: Falla
B9: 46085 | C9: PR-260032 | E9: SMCV | F9: 2C-M | G9: Sp 32 | H9: 1056.445 | I9: 264.17 | J9: 2567.79 | K9: Proctor | L9: 475.5 | M9: 100 | N9: 99.663512 | O9: 98.065195 | P9: 92.3449 | Q9: 78.338591 | R9: 59.57939 | S9: 38.759201 | T9: 14.44795 | U9: GT | V9: B | W9: Material Compactado correspondiente a Talud 2C-M | X9: =IF(Table_GP[[#This Row],[Fecha]]=0,"",_xlfn.CONCAT("Sem ",WEEKNUM(Table_GP[[#This Row],[Fecha]],2))) -> Sem 10 | Y9: =+IF(T9>=15.05,T9,0) -> 0
B10: 46087 | C10: PR-260033 | E10: SMCV | F10: 1B-H | G10: Plataforma | H10: 320.15 | I10: 64.7 | J10: 2635.95 | K10: Proctor | L10: 495.5 | M10: 100 | N10: 99.778002 | O10: 99.313824 | P10: 96.831483 | Q10: 86.579213 | R10: 66.659939 | S10: 41.735621 | T10: 13.158426 | U10: GT | V10: B | W10: Material Conformado correspondiente a Corona 1B-H | X10: =IF(Table_GP[[#This Row],[Fecha]]=0,"",_xlfn.CONCAT("Sem ",WEEKNUM(Table_GP[[#This Row],[Fecha]],2))) -> Sem 10 | Y10: =+IF(T10>=15.05,T10,0) -> 0
B11: 46088 | C11: PR-260034 | E11: SMCV | F11: 4B-H | G11: Sp 56 | H11: 1821.24 | I11: 199.45 | J11: 2569.89 | K11: Proctor | L11: 465.2 | M11: 100 | N11: 99.892519 | O11: 98.538263 | P11: 93.72313 | Q11: 77.214101 | R11: 56.083405 | S11: 34.565778 | T11: 12.725709 | U11: GM | V11: B | W11: Material Conformado correspondiente a Talud 4B-H | X11: =IF(Table_GP[[#This Row],[Fecha]]=0,"",_xlfn.CONCAT("Sem ",WEEKNUM(Table_GP[[#This Row],[Fecha]],2))) -> Sem 10 | Y11: =+IF(T11>=15.05,T11,0) -> 0
B12: 46090 | C12: PR-260035 | E12: SMCV | F12: 4A-H | G12: Sp 51 | H12: 1694.27 | I12: 18.9 | J12: 2635.22 | K12: Proctor | L12: 374.9 | M12: 100 | N12: 100 | O12: 98.132835 | P12: 90.984262 | Q12: 73.779675 | R12: 52.387303 | S12: 32.435316 | T12: 10.856228 | U12: GM | V12: B | W12: Material Conformado correspondiente a Talud 4A-H | X12: =IF(Table_GP[[#This Row],[Fecha]]=0,"",_xlfn.CONCAT("Sem ",WEEKNUM(Table_GP[[#This Row],[Fecha]],2))) -> Sem 11 | Y12: =+IF(T12>=15.05,T12,0) -> 0
B13: 46093 | C13: PR-260036 | E13: SMCV | F13: 2B-H | G13: Sp 27 | H13: 863.17 | I13: 44.4 | J13: 2631.88 | K13: Proctor | L13: 227 | M13: 100 | N13: 100 | O13: 98.590308 | P13: 91.718062 | Q13: 75.418502 | R13: 54.537445 | S13: 33.788546 | T13: 9.7356828 | U13: GM | V13: A | W13: Material Conformado correspondiente a Talud 2B-H | X13: =IF(Table_GP[[#This Row],[Fecha]]=0,"",_xlfn.CONCAT("Sem ",WEEKNUM(Table_GP[[#This Row],[Fecha]],2))) -> Sem 11 | Y13: =+IF(T13>=15.05,T13,0) -> 0
B14: 46094 | C14: PR-260037 | E14: SMCV | F14: 2A-M | G14: Sp 21 | H14: 675.18 | I14: 477.8 | J14: 2607.74 | K14: Proctor | L14: 371.9 | M14: 100 | N14: 99.973111 | O14: 99.005109 | P14: 93.519763 | Q14: 77.816617 | R14: 57.112127 | S14: 35.0363 | T14: 12.718473 | U14: GT | V14: A | W14: Material Conformado correspondiente a Talud 2A-M | X14: =IF(Table_GP[[#This Row],[Fecha]]=0,"",_xlfn.CONCAT("Sem ",WEEKNUM(Table_GP[[#This Row],[Fecha]],2))) -> Sem 11 | Y14: =+IF(T14>=15.05,T14,0) -> 0
B15: 46095 | C15: PR-260038 | E15: SMCV | F15: 3C-H | G15: Sp 48 | H15: 1580.2 | I15: 160.21 | J15: 2597.6 | K15: Proctor | L15: 580.4 | M15: 100 | N15: 100 | O15: 99.552033 | P15: 96.295658 | Q15: 84.269469 | R15: 64.955203 | S15: 41.10958 | T15: 13.542385 | U15: GT | V15: B | W15: Material Conformado correspondiente a Talud 3C-H | X15: =IF(Table_GP[[#This Row],[Fecha]]=0,"",_xlfn.CONCAT("Sem ",WEEKNUM(Table_GP[[#This Row],[Fecha]],2))) -> Sem 11 | Y15: =+IF(T15>=15.05,T15,0) -> 0
B16: 46097 | C16: PR-260039 | E16: SMCV | F16: 3A-M | G16: Sp 34 | H16: 1124.81 | I16: 476.06 | J16: 2506.18 | K16: Proctor | L16: 411.9 | M16: 100 | N16: 100 | O16: 98.858946 | P16: 93.299345 | Q16: 77.276038 | R16: 56.785628 | S16: 35.032775 | T16: 12.23598 | U16: GT | V16: B | W16: Material Conformado correspondiente a Talud 3A-M | X16: =IF(Table_GP[[#This Row],[Fecha]]=0,"",_xlfn.CONCAT("Sem ",WEEKNUM(Table_GP[[#This Row],[Fecha]],2))) -> Sem 12 | Y16: =+IF(T16>=15.05,T16,0) -> 0
B17: 46099 | C17: PR-260040 | E17: SMCV | F17: 4A-H | G17: Sp 50 | H17: 1661.24 | I17: 39.48 | J17: 2631.22 | K17: Proctor | L17: 411.9 | M17: 100 | N17: 100 | O17: 98.761835 | P17: 93.736344 | Q17: 78.417092 | R17: 57.319738 | S17: 35.372663 | T17: 12.138869 | U17: GM | V17: A | W17: Material Conformado correspondiente a Talud 4A-H | X17: =IF(Table_GP[[#This Row],[Fecha]]=0,"",_xlfn.CONCAT("Sem ",WEEKNUM(Table_GP[[#This Row],[Fecha]],2))) -> Sem 12 | Y17: =+IF(T17>=15.05,T17,0) -> 0
B18: 46099 | C18: PR-260041 | E18: SMCV | F18: 3C-H | G18: Sp 45 | H18: 1495.65 | I18: -3.25 | J18: 2636.25 | K18: Proctor | L18: 346 | M18: 100 | N18: 100 | O18: 98.757225 | P18: 92.745665 | Q18: 75.895954 | R18: 55.606936 | S18: 35.375723 | T18: 11.156069 | U18: GM | V18: B | W18: Material Conformado correspondiente a Talud 3C-H | X18: =IF(Table_GP[[#This Row],[Fecha]]=0,"",_xlfn.CONCAT("Sem ",WEEKNUM(Table_GP[[#This Row],[Fecha]],2))) -> Sem 12 | Y18: =+IF(T18>=15.05,T18,0) -> 0
B19: 46100 | C19: PR-260042 | E19: SMCV | F19: 2B-M | G19: Sp 28 | H19: 0+902.21 | I19: 0+339.48 | J19: 2517.89 | K19: Proctor | L19: 381.9 | M19: 100 | N19: 100 | O19: 98.716942 | P19: 93.008641 | Q19: 78.188007 | R19: 56.768788 | S19: 34.87824 | T19: 10.081173 | U19: GM | V19: A | W19: Material Conformado correspondiente a Talud 2B-M | X19: =IF(Table_GP[[#This Row],[Fecha]]=0,"",_xlfn.CONCAT("Sem ",WEEKNUM(Table_GP[[#This Row],[Fecha]],2))) -> Sem 12 | Y19: =+IF(T19>=15.05,T19,0) -> 0
B20: 46101 | C20: PR-260043 | E20: SMCV | F20: 4A-M | G20: Sp 51 | H20: 1700.25 | I20: 360.01 | J20: 2537.93 | K20: Proctor | L20: 362 | M20: 100 | N20: 100 | O20: 99.309392 | P20: 95.441989 | Q20: 82.513812 | R20: 62.292818 | S20: 41.160221 | T20: 13.370166 | U20: GM | V20: B | W20: Material Conformado correspondiente a Talud 4A-M | X20: =IF(Table_GP[[#This Row],[Fecha]]=0,"",_xlfn.CONCAT("Sem ",WEEKNUM(Table_GP[[#This Row],[Fecha]],2))) -> Sem 12 | Y20: =+IF(T20>=15.05,T20,0) -> 0
B21: 46103 | C21: PR-260044 | E21: SMCV | F21: 1C-M | G21: Sp 18 | H21: 580.21 | I21: 340.1 | J21: 2567.05 | K21: Proctor | L21: 285.9 | M21: 100 | N21: 100 | O21: 99.195523 | P21: 95.033228 | Q21: 82.47639 | R21: 62.924099 | S21: 41.168241 | T21: 13.04652 | U21: GM | V21: A | W21: Material Conformado correspondiente a Talud 1C-M | X21: =IF(Table_GP[[#This Row],[Fecha]]=0,"",_xlfn.CONCAT("Sem ",WEEKNUM(Table_GP[[#This Row],[Fecha]],2))) -> Sem 12 | Y21: =+IF(T21>=15.05,T21,0) -> 0
B22: 46104 | C22: PR-260045 | E22: SMCV | F22: 2C-M | G22: Sp 32 | H22: 1041.55 | I22: 304.17 | J22: 2558.44 | K22: Proctor | L22: 490.4 | M22: 100 | N22: 99.959217 | O22: 98.633768 | P22: 93.14845 | Q22: 77.569331 | R22: 56.056281 | S22: 34.787928 | T22: 11.888254 | U22: FV | V22: B | W22: Material Conformado correspondiente a Talud 2C-M | X22: =IF(Table_GP[[#This Row],[Fecha]]=0,"",_xlfn.CONCAT("Sem ",WEEKNUM(Table_GP[[#This Row],[Fecha]],2))) -> Sem 13 | Y22: =+IF(T22>=15.05,T22,0) -> 0
B23: 46107 | C23: PR-260046 | E23: SMCV | F23: 2B-H | G23: Sp 28 | H23: 900.1 | I23: 60.26 | J23: 2626.7 | K23: Proctor | L23: 410.6 | M23: 100 | N23: 99.951291 | O23: 98.78227 | P23: 92.717974 | Q23: 76.522163 | R23: 55.358013 | S23: 34.510472 | T23: 11.836337 | U23: FV | V23: A | W23: Material Conformado correspondiente a Talud 2B-H | X23: =IF(Table_GP[[#This Row],[Fecha]]=0,"",_xlfn.CONCAT("Sem ",WEEKNUM(Table_GP[[#This Row],[Fecha]],2))) -> Sem 13 | Y23: =+IF(T23>=15.05,T23,0) -> 0
B24: 46108 | C24: PR-260047 | E24: SMCV | F24: 4B-L | G24: Sp 54 | H24: 1780.35 | I24: 520.01 | J24: 2490.2 | K24: Proctor | L24: 478.5 | M24: 100 | N24: 100 | O24: 98.996865 | P24: 93.416928 | Q24: 77.722048 | R24: 55.987461 | S24: 34.085684 | T24: 10.449321 | U24: FV | V24: A | W24: Material Conformado correspondiente a Talud 4B-L | X24: =IF(Table_GP[[#This Row],[Fecha]]=0,"",_xlfn.CONCAT("Sem ",WEEKNUM(Table_GP[[#This Row],[Fecha]],2))) -> Sem 13 | Y24: =+IF(T24>=15.05,T24,0) -> 0
B25: 46112 | C25: PR-260048 | E25: SMCV | F25: 2A-M | G25: Sp 22 | H25: 720.36 | I25: 480.01 | J25: 2521.7 | K25: Proctor | L25: 334.3 | M25: 100 | N25: 99.940173 | O25: 99.222255 | P25: 95.183966 | Q25: 81.005085 | R25: 60.454681 | S25: 36.793299 | T25: 12.084954 | U25: GM | V25: A | W25: Material Conformado correspondiente a Talud 2A-M | X25: =IF(Table_GP[[#This Row],[Fecha]]=0,"",_xlfn.CONCAT("Sem ",WEEKNUM(Table_GP[[#This Row],[Fecha]],2))) -> Sem 14 | Y25: =+IF(T25>=15.05,T25,0) -> 0
X26: =IF(Table_GP[[#This Row],[Fecha]]=0,"",_xlfn.CONCAT("Sem ",WEEKNUM(Table_GP[[#This Row],[Fecha]],2))) | Y26: =+IF(T26>=15.05,T26,0) -> 0
X27: =IF(Table_GP[[#This Row],[Fecha]]=0,"",_xlfn.CONCAT("Sem ",WEEKNUM(Table_GP[[#This Row],[Fecha]],2))) | Y27: =+IF(T27>=15.05,T27,0) -> 0
X28: =IF(Table_GP[[#This Row],[Fecha]]=0,"",_xlfn.CONCAT("Sem ",WEEKNUM(Table_GP[[#This Row],[Fecha]],2))) | Y28: =+IF(T28>=15.05,T28,0) -> 0
X29: =IF(Table_GP[[#This Row],[Fecha]]=0,"",_xlfn.CONCAT("Sem ",WEEKNUM(Table_GP[[#This Row],[Fecha]],2))) | Y29: =+IF(T29>=15.05,T29,0) -> 0
X30: =IF(Table_GP[[#This Row],[Fecha]]=0,"",_xlfn.CONCAT("Sem ",WEEKNUM(Table_GP[[#This Row],[Fecha]],2))) | Y30: =+IF(T30>=15.05,T30,0) -> 0
X31: =IF(Table_GP[[#This Row],[Fecha]]=0,"",_xlfn.CONCAT("Sem ",WEEKNUM(Table_GP[[#This Row],[Fecha]],2))) | Y31: =+IF(T31>=15.05,T31,0) -> 0
M33: Laboratorio
M34: Porcentaje Acumulado Pasante
M35: Nº 8 | N35: Nº 16 | O35: Nº 30 | P35: Nº 40 | Q35: Nº 50 | R35: Nº 70 | S35: Nº 100 | T35: Nº 200
F36: =+"Estadísticas "&(TEXT(F4,"mmmm yyyy")) -> Estadísticas Marzo 2026 | L36: Mínimo | M36: =MIN(M9:M31) -> 100 | N36: =MIN(N9:N31) -> 99.663512 | O36: =MIN(O9:O31) -> 98.065195 | P36: =MIN(P9:P31) -> 90.984262 | Q36: =MIN(Q9:Q31) -> 73.779675 | R36: =MIN(R9:R31) -> 52.387303 | S36: =MIN(S9:S31) -> 32.435316 | T36: =MIN(T9:T31) -> 9.7356828
L37: Máximo | M37: =MAX(M9:M31) -> 100 | N37: =MAX(N9:N31) -> 100 | O37: =MAX(O9:O31) -> 99.552033 | P37: =MAX(P9:P31) -> 96.831483 | Q37: =MAX(Q9:Q31) -> 86.579213 | R37: =MAX(R9:R31) -> 66.659939 | S37: =MAX(S9:S31) -> 41.735621 | T37: =MAX(T9:T31) -> 14.44795
L38: Promedio | M38: =AVERAGE(M9:M31) -> 100 | N38: =AVERAGE(N9:N31) -> 99.95046 | O38: =AVERAGE(O9:O31) -> 98.848976 | P38: =AVERAGE(P9:P31) -> 93.714693 | Q38: =AVERAGE(Q9:Q31) -> 78.882476 | R38: =AVERAGE(R9:R31) -> 58.286427 | S38: =AVERAGE(S9:S31) -> 36.505623 | T38: =AVERAGE(T9:T31) -> 12.086617
L39: Max. Esp. | T39: 15.04
B69: RESUMEN | E69: PROMEDIO M200 | H69: =+SUBTOTAL(1,Table_GP[75]) -> 12.086617
E70: CANTIDAD | H70: =+SUBTOTAL(2,Table_GP[75]) -> 17
E71: PASA | H71: =+DCOUNTA(Table_GP[#All],"75",B75:D76) -> 0
E72: FALLA | H72: =+DCOUNTA(Table_GP[#All],"75",B77:D78) -> 0
E73: % FALLAS | H73: =+H72/H70 -> 0
...

Sheet GD sem
D2: Control de Calidad
D3: PRESA DE RELAVES
B6: Fecha | C6: Turno | D6: Código | E6: Cancha | F6: Sp, Sb, A8,A9 | G6: Nº 200
B7: ='Granulometrias Descarga'!B9 -> 46082 | C7: ='Granulometrias Descarga'!U9 -> A | D7: ='Granulometrias Descarga'!C9 -> GD-260451 | E7: ='Granulometrias Descarga'!F9 -> 3 | F7: ='Granulometrias Descarga'!G9 -> JH | G7: ='Granulometrias Descarga'!P9 -> 9.0771939
B8: ='Granulometrias Descarga'!B10 -> 46082 | C8: ='Granulometrias Descarga'!U10 -> A | D8: ='Granulometrias Descarga'!C10 -> GD-260452 | E8: ='Granulometrias Descarga'!F10 -> 3 | F8: ='Granulometrias Descarga'!G10 -> JH | G8: ='Granulometrias Descarga'!P10 -> 10.06135
B9: ='Granulometrias Descarga'!B11 -> 46082 | C9: ='Granulometrias Descarga'!U11 -> A | D9: ='Granulometrias Descarga'!C11 -> GD-260453 | E9: ='Granulometrias Descarga'!F11 -> 3 | F9: ='Granulometrias Descarga'!G11 -> JH | G9: ='Granulometrias Descarga'!P11 -> 8.490566
B10: ='Granulometrias Descarga'!B12 -> 46082 | C10: ='Granulometrias Descarga'!U12 -> B | D10: ='Granulometrias Descarga'!C12 -> GD-260454 | E10: ='Granulometrias Descarga'!F12 -> 3 | F10: ='Granulometrias Descarga'!G12 -> 2da.Est. | G10: ='Granulometrias Descarga'!P12 -> 7.8075483
B11: ='Granulometrias Descarga'!B13 -> 46082 | C11: ='Granulometrias Descarga'!U13 -> B | D11: ='Granulometrias Descarga'!C13 -> GD-260455 | E11: ='Granulometrias Descarga'!F13 -> 3 | F11: ='Granulometrias Descarga'!G13 -> 2da.Est. | G11: ='Granulometrias Descarga'!P13 -> 7.9229798
B12: ='Granulometrias Descarga'!B14 -> 46082 | C12: ='Granulometrias Descarga'!U14 -> B | D12: ='Granulometrias Descarga'!C14 -> GD-260456 | E12: ='Granulometrias Descarga'!F14 -> 3 | F12: ='Granulometrias Descarga'!G14 -> JH | G12: ='Granulometrias Descarga'!P14 -> 8.5169744
B13: ='Granulometrias Descarga'!B15 -> 46082 | C13: ='Granulometrias Descarga'!U15 -> B | D13: ='Granulometrias Descarga'!C15 -> GD-260457 | E13: ='Granulometrias Descarga'!F15 -> 3 | F13: ='Granulometrias Descarga'!G15 -> JH | G13: ='Granulometrias Descarga'!P15 -> 8.0630494
B14: ='Granulometrias Descarga'!B16 -> 46082 | C14: ='Granulometrias Descarga'!U16 -> B | D14: ='Granulometrias Descarga'!C16 -> GD-260458 | E14: ='Granulometrias Descarga'!F16 -> 3 | F14: ='Granulometrias Descarga'!G16 -> 2da.Est. | G14: ='Granulometrias Descarga'!P16 -> 8.7227414
B15: ='Granulometrias Descarga'!B17 -> 46083 | C15: ='Granulometrias Descarga'!U17 -> A | D15: ='Granulometrias Descarga'!C17 -> GD-260459 | E15: ='Granulometrias Descarga'!F17 -> 3 | F15: ='Granulometrias Descarga'!G17 -> 2da.Est. | G15: ='Granulometrias Descarga'!P17 -> 8.7065568
