Workbook
Name _: #REF!
Name __DAT1: #REF!
Name _DAT1: #REF!
Name A: #REF!
Name A_impresión_IM: #REF!
Name AA: #REF!
Name AA00: #REF!
Name AAA: #REF!
Name AAAA: '[1]#¡REF'!$A$2:$D$17
Name Aaaaa: #REF!
Name AABB: #REF!
Name AALL: #REF!
Name abcd: #REF!
Name ABRASION: #REF!
Name AC: #REF!
Name AGUACEMEN: #REF!
Name AGUACEMEN: #REF!
Name AGUAUNIT: #REF!
Name AGUAUNIT: #REF!
Name AIREATRAP: #REF!
Name AIREATRAP: #REF!
Name Arena: 'D6913'!$T$60
Name B: #REF!
Name borrado: [3]!borrado
Name C.H.: #REF!
Name C.H.: #REF!
Name CA: #REF!
Name Caras: [4]BGA!$H$9
Name CC: 'SUCS N° 03'!$L$6
Name CC: [5]SUCS!$L$6
Name cddd: #REF!
Name CF: #REF!
Name CH: 'SUCS N° 03'!$L$21
Name CH: #REF!
Name CHA: #REF!
Name chancada: #REF!
Name Chatas: #REF!
Name CL: 'SUCS N° 03'!$L$18
Name CL: #REF!
Name CLML: 'SUCS N° 03'!$L$23
Name CLML: #REF!
Name CM: [6]BGA!$H$9
Name CM: [7]BGA!$H$9
Name COE0G3: #REF!
Name COE0G4: #REF!
Name COE1G3: #REF!
Name COE1G4: #REF!
Name COE2G3: #REF!
Name COE2G4: #REF!
Name COE3G3: #REF!
Name COE3G4: #REF!
Name COE4G4: #REF!
Name COLUMNITAS: #REF!
Name COMPACT: #REF!
Name CU: 'SUCS N° 03'!$L$5
Name CU: [5]SUCS!$L$5
Name D: #REF!
Name datitos: #REF!
Name Dato: #REF!
Name Dato: #REF!

Sheet SUCS N° 01
B2: Tamiz | C2: Pasa | D2: Pasante
B3: (mm) | C3: (%) | D3: (%) | M3: Sistema unificado de clasificación de suelos (S.U.C.S.) | W3: D60 | X3: D30 | Y3: D10
A4: 4" | B4: 100 | C4: ='D6913'!F24 -> 100 | D4: =IF(C4="",100,C4) -> 100 | F4: D60: | I4: =X24 -> 4.2500873 | J4: mm | W4: =IF(AND(D4=60,D5=60),((B4+B5)/2),IF(AND(D4>=60,D5<=60),FORECAST(60,B4:B5,D4:D5),"")) | X4: =IF(AND(D4=30,D5=30),((B4+B5)/2),IF(AND(D4>=30,D5<=30),FORECAST(30,B4:B5,D4:D5),"")) | Y4: =IF(AND(D4=10,D5=10),((B4+B5)/2),IF(AND(D4>=10,D5<=10),FORECAST(10,B4:B5,D4:D5),""))
A5: 3" | B5: 80 | C5: ='D6913'!F25 -> 96.337257 | D5: =IF(C5="",100,C5) -> 96.337257 | F5: D30: | I5: =X25 -> 0.42955569 | J5: mm | P5: =IF(D19<50,"Suelo de partículas gruesas.","") -> Suelo de partículas gruesas. | W5: =IF(AND(D5=60,D6=60),((B5+B6)/2),IF(AND(D5>=60,D6<=60),FORECAST(60,B5:B6,D5:D6),"")) | X5: =IF(AND(D5=30,D6=30),((B5+B6)/2),IF(AND(D5>=30,D6<=30),FORECAST(30,B5:B6,D5:D6),"")) | Y5: =IF(AND(D5=10,D6=10),((B5+B6)/2),IF(AND(D5>=10,D6<=10),FORECAST(10,B5:B6,D5:D6),""))
A6: 2 1/2" | B6: 63 | C6: ='D6913'!F26 -> 93.104579 | D6: =IF(C6="",100,C6) -> 93.104579 | F6: D10 (diámetro efectivo): | I6: =X26 | J6: mm | P6: =IF(D19<5," Suelo limpio.","") | W6: =IF(AND(D6=60,D7=60),((B6+B7)/2),IF(AND(D6>=60,D7<=60),FORECAST(60,B6:B7,D6:D7),"")) | X6: =IF(AND(D6=30,D7=30),((B6+B7)/2),IF(AND(D6>=30,D7<=30),FORECAST(30,B6:B7,D6:D7),"")) | Y6: =IF(AND(D6=10,D7=10),((B6+B7)/2),IF(AND(D6>=10,D7<=10),FORECAST(10,B6:B7,D6:D7),""))
A7: 2" | B7: 50 | C7: ='D6913'!F27 -> 90.28 | D7: =IF(C7="",100,C7) -> 90.28 | F7: Coeficiente de uniformidad (Cu): | I7: =X27 | P7: =IF(AND(D19>12,D19<50)," Suelo de partículas gruesas con finos (suelo sucio).","") -> Suelo de partículas gruesas con finos (suelo sucio). | W7: =IF(AND(D7=60,D8=60),((B7+B8)/2),IF(AND(D7>=60,D8<=60),FORECAST(60,B7:B8,D7:D8),"")) | X7: =IF(AND(D7=30,D8=30),((B7+B8)/2),IF(AND(D7>=30,D8<=30),FORECAST(30,B7:B8,D7:D8),"")) | Y7: =IF(AND(D7=10,D8=10),((B7+B8)/2),IF(AND(D7>=10,D8<=10),FORECAST(10,B7:B8,D7:D8),""))
A8: 1 1/2" | B8: 40 | C8: ='D6913'!F28 -> 86.400956 | D8: =IF(C8="",100,C8) -> 86.400956 | F8: Grado de curvatura (Cc): | I8: =X28 | P8: =IF(AND(D19>=5,D19<=12),"( Nomenclatura con símbolo doble).","") | W8: =IF(AND(D8=60,D9=60),((B8+B9)/2),IF(AND(D8>=60,D9<=60),FORECAST(60,B8:B9,D8:D9),"")) | X8: =IF(AND(D8=30,D9=30),((B8+B9)/2),IF(AND(D8>=30,D9<=30),FORECAST(30,B8:B9,D8:D9),"")) | Y8: =IF(AND(D8=10,D9=10),((B8+B9)/2),IF(AND(D8>=10,D9<=10),FORECAST(10,B8:B9,D8:D9),""))
A9: 1" | B9: 25 | C9: ='D6913'!F29 -> 81.448014 | D9: =IF(C9="",100,C9) -> 81.448014 | M9: =IF(X23<50,"SI","No") -> SI | N9: =IF(W42>W47/2,"SI","No") -> No | O9: =AND(M9="SI",N9="SI") -> FALSE | P9: =IF(O9=TRUE,"Grava","") | U9: =IF(OR(X32>0,X33>0)," con bloques","") -> con bloques | W9: =IF(AND(D9=60,D10=60),((B9+B10)/2),IF(AND(D9>=60,D10<=60),FORECAST(60,B9:B10,D9:D10),"")) | X9: =IF(AND(D9=30,D10=30),((B9+B10)/2),IF(AND(D9>=30,D10<=30),FORECAST(30,B9:B10,D9:D10),"")) | Y9: =IF(AND(D9=10,D10=10),((B9+B10)/2),IF(AND(D9>=10,D10<=10),FORECAST(10,B9:B10,D9:D10),""))
A10: 3/4" | B10: 20 | C10: ='D6913'!F30 -> 78.326022 | D10: =IF(C10="",100,C10) -> 78.326022 | Q10: =AND(D19<5,X27>=4,X28>=1,X28<=3) -> FALSE | R10: =AND(P9="Grava",Q10=TRUE) -> FALSE | S10: =IF(R10=TRUE," bien graduada","") | T10: =IF(S10=" bien graduada"," GW","") | W10: =IF(AND(D10=60,D11=60),((B10+B11)/2),IF(AND(D10>=60,D11<=60),FORECAST(60,B10:B11,D10:D11),"")) | X10: =IF(AND(D10=30,D11=30),((B10+B11)/2),IF(AND(D10>=30,D11<=30),FORECAST(30,B10:B11,D10:D11),"")) | Y10: =IF(AND(D10=10,D11=10),((B10+B11)/2),IF(AND(D10>=10,D11<=10),FORECAST(10,B10:B11,D10:D11),""))
A11: 1/2" | B11: 12.5 | C11: ='D6913'!F31 -> 72.830639 | D11: =IF(C11="",100,C11) -> 72.830639 | Q11: =AND(D19<5,OR(X27<4,X28<1,X28>3)) -> FALSE | R11: =AND(P9="Grava",Q11=TRUE) -> FALSE | S11: =IF(R11=TRUE," mal graduada","") | T11: =IF(S11=" mal graduada"," GP","") | W11: =IF(AND(D11=60,D12=60),((B11+B12)/2),IF(AND(D11>=60,D12<=60),FORECAST(60,B11:B12,D11:D12),"")) | X11: =IF(AND(D11=30,D12=30),((B11+B12)/2),IF(AND(D11>=30,D12<=30),FORECAST(30,B11:B12,D11:D12),"")) | Y11: =IF(AND(D11=10,D12=10),((B11+B12)/2),IF(AND(D11>=10,D12<=10),FORECAST(10,B11:B12,D11:D12),""))
A12: 3/8" | B12: 10 | C12: ='D6913'!F32 -> 70.05591 | D12: =IF(C12="",100,C12) -> 70.05591 | Q12: =AND(D19>12,OR(AND(C21<=30,C23>7),AND(C21>30,C23>(0.73*(C21-20))))) -> FALSE | R12: =AND(P9="Grava",Q12=TRUE) -> FALSE | S12: =IF(R12=TRUE," arcillosa","") | T12: =IF(S12=" arcillosa"," GC","") | W12: =IF(AND(D12=60,D13=60),((B12+B13)/2),IF(AND(D12>=60,D13<=60),FORECAST(60,B12:B13,D12:D13),"")) | X12: =IF(AND(D12=30,D13=30),((B12+B13)/2),IF(AND(D12>=30,D13<=30),FORECAST(30,B12:B13,D12:D13),"")) | Y12: =IF(AND(D12=10,D13=10),((B12+B13)/2),IF(AND(D12>=10,D13<=10),FORECAST(10,B12:B13,D12:D13),""))
A13: 1/4" | B13: 6.3 | C13: ='D6913'!F33 -> 65.444318 | D13: =IF(C13="",100,C13) -> 65.444318 | Q13: =AND(D19>12,OR(C23<4,C23<(0.73*(C21-20)))) -> TRUE | R13: =AND(P9="Grava",Q13=TRUE) -> FALSE | S13: =IF(R13=TRUE," limosa","") | T13: =IF(S13=" limosa"," GM","") | W13: =IF(AND(D13=60,D14=60),((B13+B14)/2),IF(AND(D13>=60,D14<=60),FORECAST(60,B13:B14,D13:D14),"")) | X13: =IF(AND(D13=30,D14=30),((B13+B14)/2),IF(AND(D13>=30,D14<=30),FORECAST(30,B13:B14,D13:D14),"")) | Y13: =IF(AND(D13=10,D14=10),((B13+B14)/2),IF(AND(D13>=10,D14<=10),FORECAST(10,B13:B14,D13:D14),""))
A14: Nº 4 | B14: 5 | C14: ='D6913'!F34 -> 62.475257 | D14: =IF(C14="",100,C14) -> 62.475257 | Q14: =AND(D19>12,C23>(0.73*(C21-20)),C23>=4,C23<=7) -> FALSE | R14: =AND(P9="Grava",Q14=TRUE) -> FALSE | S14: =IF(R14=TRUE," arcilloso-limosa","") | T14: =IF(S14=" arcilloso-limosa"," GC-GM","") | W14: =IF(AND(D14=60,D15=60),((B14+B15)/2),IF(AND(D14>=60,D15<=60),FORECAST(60,B14:B15,D14:D15),"")) -> 4.2500873 | X14: =IF(AND(D14=30,D15=30),((B14+B15)/2),IF(AND(D14>=30,D15<=30),FORECAST(30,B14:B15,D14:D15),"")) | Y14: =IF(AND(D14=10,D15=10),((B14+B15)/2),IF(AND(D14>=10,D15<=10),FORECAST(10,B14:B15,D14:D15),""))
A15: Nº 10 | B15: 2 | C15: ='D6913'!F36 -> 52.573078 | D15: =IF(C15="",100,C15) -> 52.573078 | Q15: =AND(D19>=5,D19<=12,X27>=4,X28>=1,X28<=3) -> FALSE | R15: =AND(P9="Grava",Q15=TRUE) -> FALSE | S15: =IF(R15=TRUE," bien graduada","") | T15: =IF(S15=" bien graduada"," GW","") | W15: =IF(AND(D15=60,D16=60),((B15+B16)/2),IF(AND(D15>=60,D16<=60),FORECAST(60,B15:B16,D15:D16),"")) | X15: =IF(AND(D15=30,D16=30),((B15+B16)/2),IF(AND(D15>=30,D16<=30),FORECAST(30,B15:B16,D15:D16),"")) | Y15: =IF(AND(D15=10,D16=10),((B15+B16)/2),IF(AND(D15>=10,D16<=10),FORECAST(10,B15:B16,D15:D16),""))
A16: Nº 16 | B16: 1.25 | C16: ='D6913'!F37 -> 43.726901 | D16: =IF(C16="",100,C16) -> 43.726901 | Q16: =AND(D19>=5,D19<=12,OR(X27<4,X28<1,X28>3)) -> FALSE | R16: =AND(P9="Grava",Q16=TRUE) -> FALSE | S16: =IF(R16=TRUE," mal graduada","") | T16: =IF(S16=" mal graduada"," GP","") | W16: =IF(AND(D16=60,D17=60),((B16+B17)/2),IF(AND(D16>=60,D17<=60),FORECAST(60,B16:B17,D16:D17),"")) | X16: =IF(AND(D16=30,D17=30),((B16+B17)/2),IF(AND(D16>=30,D17<=30),FORECAST(30,B16:B17,D16:D17),"")) -> 0.42955569 | Y16: =IF(AND(D16=10,D17=10),((B16+B17)/2),IF(AND(D16>=10,D17<=10),FORECAST(10,B16:B17,D16:D17),""))
A17: Nº 40 | B17: 0.4 | C17: ='D6913'!F40 -> 29.505502 | D17: =IF(C17="",100,C17) -> 29.505502 | F17: Sistema unificado de clasificación de suelos (S.U.C.S.) | Q17: =AND(D19>=5,D19<=12,OR(AND(C21<=30,C23>7),AND(C21>30,C23>(0.73*(C21-20))))) -> FALSE | R17: =AND(P9="Grava",Q17=TRUE) -> FALSE | S17: =IF(R17=TRUE," con arcilla","") | T17: =IF(S17=" con arcilla"," GC","") | W17: =IF(AND(D17=60,D18=60),((B17+B18)/2),IF(AND(D17>=60,D18<=60),FORECAST(60,B17:B18,D17:D18),"")) | X17: =IF(AND(D17=30,D18=30),((B17+B18)/2),IF(AND(D17>=30,D18<=30),FORECAST(30,B17:B18,D17:D18),"")) | Y17: =IF(AND(D17=10,D18=10),((B17+B18)/2),IF(AND(D17>=10,D18<=10),FORECAST(10,B17:B18,D17:D18),""))
A18: Nº 100 | B18: 0.16 | C18: ='D6913'!F44 -> 21.066145 | D18: =IF(C18="",100,C18) -> 21.066145 | F18: =IF(AND(C4="",C5="",C6="",C7="",C8="",C9="",C10="",C11="",C12="",C13="",C14="",C15="",C16="",C17="",C18="",C19=""),"",M42) -> Suelo de partículas gruesas. Suelo de partículas gruesas con finos (suelo sucio). | Q18: =AND(D19>=5,D19<=12,OR(C23<4,C23<(0.73*(C21-20)))) -> FALSE | R18: =AND(P9="Grava",Q18=TRUE) -> FALSE | S18: =IF(R18=TRUE," con limo","") | T18: =IF(S18=" con limo"," GM","") | W18: =IF(AND(D18=60,D19=60),((B18+B19)/2),IF(AND(D18>=60,D19<=60),FORECAST(60,B18:B19,D18:D19),"")) | X18: =IF(AND(D18=30,D19=30),((B18+B19)/2),IF(AND(D18>=30,D19<=30),FORECAST(30,B18:B19,D18:D19),"")) | Y18: =IF(AND(D18=10,D19=10),((B18+B19)/2),IF(AND(D18>=10,D19<=10),FORECAST(10,B18:B19,D18:D19),""))
A19: Nº 200 | B19: 0.08 | C19: ='D6913'!F46 -> 17.326861 | D19: =IF(C19="",100,C19) -> 17.326861 | F19: =IF(AND(C4="",C5="",C6="",C7="",C8="",C9="",C10="",C11="",C12="",C13="",C14="",C15="",C16="",C17="",C18="",C19=""),"",Q43) -> Arena limosa con grava con bloques SM | Q19: =AND(D19>=5,D19<=12,C23>(0.73*(C21-20)),C23>=4,C23<=7) -> FALSE | R19: =AND(P9="Grava",Q19=TRUE) -> FALSE | S19: =IF(R19=TRUE," con arcilla y limo","") | T19: =IF(S19=" con arcilla y limo"," GC","") | W19: =AVERAGE(W4:W18) -> 4.2500873 | X19: =AVERAGE(X4:X18) -> 0.42955569 | Y19: =AVERAGE(Y4:Y18) -> #DIV/0!
R20: =AND(P9="Grava",(X43+X44+X45+X46+X47)>15) -> FALSE | S20: =IF(R20=TRUE," con arena","") | W20: =ISNUMBER(W19) -> TRUE | X20: =ISNUMBER(X19) -> TRUE | Y20: =ISNUMBER(Y19) -> FALSE
B21: Límite líquido, LL: | C21: =IF('D6913'!L34="NP",0,'D6913'!K34) -> 0 | D21: % | F21: =IF(AND(C4="",C5="",C6="",C7="",C8="",C9="",C10="",C11="",C12="",C13="",C14="",C15="",C16="",C17="",C18="",C19=""),"",F19) -> Arena limosa con grava con bloques SM | M21: =IF(X23<50,"SI","No") -> SI | N21: =IF(W42<W47/2,"SI","No") -> SI | O21: =AND(M21="SI",N21="SI") -> TRUE | P21: =IF(O21=TRUE,"Arena","") -> Arena
B22: Límite plastico, LP: | C22: =IF('D6913'!L35="NP",0,'D6913'!K35) -> 0 | D22: % | Q22: =AND(D19<5,X27>=6,X28>=1,X28<=3) -> FALSE | R22: =AND(P21="Arena",Q22=TRUE) -> FALSE | S22: =IF(AND(R22=TRUE,D19<=12,D19<50)," bien graduada","") | T22: =IF(S22=" bien graduada"," SW","") | W22: Pasa tamiz Nº 4 (5mm): | X22: =D14 -> 62.475257 | Y22: %
B23: Índice plasticidad, IP: | C23: =C21-C22 -> 0 | D23: % | Q23: =AND(D19<5,OR(X27<6,X28<1,X28>3)) -> FALSE | R23: =AND(P21="Arena",Q23=TRUE) -> FALSE | S23: =IF(AND(R23=TRUE,D19<=12,D19<50)," mal graduada","") | T23: =IF(S23=" mal graduada"," SP","") | W23: Pasa tamiz Nº 200 (0,080 mm): | X23: =D19 -> 17.326861 | Y23: %
Q24: =AND(D19>12,OR(AND(C21<=30,C23>7),AND(C21>30,C23>(0.73*(C21-20))))) -> FALSE | R24: =AND(P21="Arena",Q24=TRUE) -> FALSE | S24: =IF(AND(R24=TRUE,D19>12,D19<50)," arcillosa","") | T24: =IF(S24=" arcillosa"," SC","") | W24: D60: | X24: =IF(W20=TRUE,W19,"") -> 4.2500873 | Y24: mm
Q25: =AND(D19>12,OR(C23<4,C23<(0.73*(C21-20)))) -> TRUE | R25: =AND(P21="Arena",Q25=TRUE) -> TRUE | S25: =IF(AND(R25=TRUE,D19>12,D19<50)," limosa","") -> limosa | T25: =IF(S25=" limosa"," SM","") -> SM | W25: D30: | X25: =IF(X20=TRUE,X19,"") -> 0.42955569 | Y25: mm
Q26: =AND(D19>12,C23>(0.73*(C21-20)),C23>=4,C23<=7) -> FALSE | R26: =AND(P21="Arena",Q26=TRUE) -> FALSE | S26: =IF(AND(R26=TRUE,D19>12,D19<50)," arcilloso-limosa","") | T26: =IF(S26=" arcilloso-limosa"," SC-SM","") | W26: D10 (diámetro efectivo): | X26: =IF(Y20=TRUE,Y19,"") | Y26: mm
Q27: =AND(D19>=5,D19<=12,X27>=4,X28>=1,X28<=3) -> FALSE | R27: =AND(P21="Arena",Q27=TRUE) -> FALSE | S27: =IF(R27=TRUE," bien graduada","") | T27: =IF(S27=" bien graduada"," SW","") | W27: Coeficiente de uniformidad (Cu): | X27: =IF(OR(X24="",X25="",X26=""),"",X24/X26)
Q28: =AND(D19>=5,D19<=12,OR(X27<4,X28<1,X28>3)) -> FALSE | R28: =AND(P21="Arena",Q28=TRUE) -> FALSE | S28: =IF(R28=TRUE," mal graduada","") | T28: =IF(S28=" mal graduada"," SP","") | W28: Grado de curvatura (Cc): | X28: =IF(OR(X24="",X25="",X26=""),"",(X25*X25)/(X26*X24))
Q29: =AND(D19>=5,D19<=12,OR(AND(C21<=30,C23>7),AND(C21>30,C23>(0.73*(C21-20))))) -> FALSE | R29: =AND(P21="Arena",Q29=TRUE) -> FALSE | S29: =IF(R29=TRUE," con arcilla","") | T29: =IF(S29=" con arcilla"," SC","")
Q30: =AND(D19>=5,D19<=12,OR(C23<4,C23<(0.73*(C21-20)))) -> FALSE | R30: =AND(P21="Arena",Q30=TRUE) -> FALSE | S30: =IF(R30=TRUE," con limo","") | T30: =IF(S30=" con limo"," SM","") | W30: Retenido | X30: Retenido
Q31: =AND(D19>=5,D19<=12,C23>(0.73*(C21-20)),C23>=4,C23<=7) -> FALSE | R31: =AND(P21="Arena",Q31=TRUE) -> FALSE | S31: =IF(R31=TRUE," con arcilla y limo","") | T31: =IF(S31=" con arcilla y limo"," SC","") | W31: acumulado (%) | X31: parcial (%)
R32: =AND(P21="Arena",(X32+X33+X34+X35+X36+X37+X38+X39+X40+X41+X42)>15) -> TRUE | S32: =IF(R32=TRUE," con grava","") -> con grava | W32: =100-D4 -> 0 | X32: =100-D4 -> 0
W33: =100-D5 -> 3.6627435 | X33: =D4-D5 -> 3.6627435
P34: =IF(D19>=50,"Suelo de partículas finas.","") | W34: =100-D6 -> 6.8954208 | X34: =D5-D6 -> 3.2326774
M35: =IF(X23>=50,"SI","No") -> No | Q35: =AND(C23>(0.73*(C21-20)),C23>7,C21<30) -> FALSE | R35: =AND(M35="SI",Q35=TRUE) -> FALSE | S35: =IF(R35=TRUE,"Arcilla baja plasticidad","") | T35: =IF(S35="Arcilla baja plasticidad"," CL","") | U35: =IF(AND(D19>=50,W47<30,W47>15,(X32+X33+X34+X35+X36+X37+X38+X39+X40+X41+X42)<=(X43+X44+X45+X46+X47))," con arena","") | W35: =100-D7 -> 9.7200002 | X35: =D6-D7 -> 2.8245793
Q36: =AND(C23>(0.73*(C21-20)),C23>4,C21>=50) -> FALSE | R36: =AND(M35="SI",Q36=TRUE) -> FALSE | S36: =IF(R36=TRUE,"Arcilla alta plasticidad","") | T36: =IF(S36="Arcilla alta plasticidad"," CH","") | U36: =IF(AND(D19>=50,W47<30,W47>15,(X32+X33+X34+X35+X36+X37+X38+X39+X40+X41+X42)>(X43+X44+X45+X46+X47))," con grava","") | W36: =100-D8 -> 13.599044 | X36: =D7-D8 -> 3.8790439
Q37: =AND(C23>=(0.73*(C21-20)),C23>=4,C23<=7) -> FALSE | R37: =AND(M35="SI",Q37=TRUE) -> FALSE | S37: =IF(R37=TRUE,"Arcilla limosa","") | T37: =IF(S37="Arcilla limosa"," CL-ML","") | U37: =IF(AND(D19>=50,W47>=30,(X32+X33+X34+X35+X36+X37+X38+X39+X40+X41+X42)<=(X43+X44+X45+X46+X47),OR(S35="Arcilla baja plasticidad",S36="Arcilla alta plasticidad",S37="Arcilla limosa",S40="Arcilla media plasticidad"))," arenosa","") | W37: =100-D9 -> 18.551986 | X37: =D8-D9 -> 4.9529417
Q38: =AND(OR(C23<(0.73*(C21-20)),C23<4),C21<30) -> TRUE | R38: =AND(M35="SI",Q38=TRUE) -> FALSE | S38: =IF(R38=TRUE,"Limo baja plasticidad","") | T38: =IF(S38="Limo baja plasticidad"," ML","") | U38: =IF(AND(D19>=50,W47>=30,(X32+X33+X34+X35+X36+X37+X38+X39+X40+X41+X42)>(X43+X44+X45+X46+X47),OR(S35="Arcilla baja plasticidad",S36="Arcilla alta plasticidad",S37="Arcilla limosa",S40="Arcilla media plasticidad"))," gravosa","") | W38: =100-D10 -> 21.673978 | X38: =D9-D10 -> 3.1219924
Q39: =AND(OR(C23<(0.73*(C21-20)),C23<4),C21>=50) -> FALSE | R39: =AND(M35="SI",Q39=TRUE) -> FALSE | S39: =IF(R39=TRUE,"Limo alta plasticidad","") | T39: =IF(S39="Limo alta plasticidad"," MH","") | U39: =IF(AND(D19>=50,W47>=30,(X32+X33+X34+X35+X36+X37+X38+X39+X40+X41+X42)<=(X43+X44+X45+X46+X47),OR(S38="Limo baja plasticidad",S39="Limo alta plasticidad",S41="Limo baja plasticidad"))," arenoso","") | W39: =100-D11 -> 27.169361 | X39: =D10-D11 -> 5.4953826
Q40: =AND(C23>(0.73*(C21-20)),C23>7,AND(C21>=30,C21<50)) -> FALSE | R40: =AND(M35="SI",Q40=TRUE) -> FALSE | S40: =IF(R40=TRUE,"Arcilla media plasticidad","") | T40: =IF(S40="Arcilla media plasticidad"," CL","") | U40: =IF(AND(D19>=50,W47>=30,(X32+X33+X34+X35+X36+X37+X38+X39+X40+X41+X42)>(X43+X44+X45+X46+X47),OR(S38="Limo baja plasticidad",S39="Limo alta plasticidad",S41="Limo baja plasticidad"))," gravoso","") | W40: =100-D12 -> 29.94409 | X40: =D11-D12 -> 2.7747288
Q41: =AND(OR(C23<(0.73*(C21-20)),C23<4),AND(C21>30,C21<50)) -> FALSE | R41: =AND(M35="SI",Q41=TRUE) -> FALSE | S41: =IF(R41=TRUE,"Limo baja plasticidad","") | T41: =IF(S41="Limo baja plasticidad"," ML","") | W41: =100-D13 -> 34.555682 | X41: =D12-D13 -> 4.6115926
...

Sheet SUCS N° 02
A2: SISTEMA UNIFICADO DE CLASIFICACION
A3: TIPO | B3: VISIONES MAYORES | E3: SIMBOLO | F3: NOMBRES TIPICOS | G3: CRITERIOS DE CLASIFICACION | M3: NOMBRE TIPICO DESGREGADO | AF3: CLASIFICACION SIMPLE | AO3: CLASIFICACION DOBLE (Influ. 4) | AX3: CLASIFICACION DOBLE (Influ. 6 con 3) | BG3: CLASIFICACION DOBLE (Influ. 6 con 4) | BR3: CLASIFICACION COMPLETA
A4: SUELOS | E4: DE GRUPO | G4: Indices y Coef. | I4: Fraccionamiento de Pacticulas | N4: 1 | O4: 2 | P4: 3 | Q4: 4 | R4: 4.1 | S4: 4.2 | T4: 4.3 | U4: 5 | V4: 5.1 | W4: 5.2 | X4: 5.3 | Y4: 6 | Z4: 6.1 | AA4: 6.2 | AB4: 6.3 | AC4: 7 | AD4: 8 | AF4: =N4 -> 1 | AG4: =O4 -> 2 | AH4: =P4 -> 3 | AI4: =Q4 -> 4 | AJ4: =U4 -> 5 | AK4: =AD4 -> 8 | AL4: SUM. | AM4: CLAS. | AO4: =N4 -> 1 | AP4: =O4 -> 2 | AQ4: =P4 -> 3 | AR4: 4 | AS4: =U4 -> 5 | AT4: =AD4 -> 8 | AU4: SUM. | AV4: CLAS. | AX4: =N4 -> 1 | AY4: =AG4 -> 2 | AZ4: =AH4 -> 3 | BA4: =AI4 -> 4 | BB4: =Y4 -> 6 | BC4: =AT4 -> 8 | BD4: SUM. | BE4: CLAS. | BG4: =N4 -> 1 | BH4: =O4 -> 2 | BI4: =AQ4 -> 3 | BJ4: =AR4 -> 4 | BK4: =Y4 -> 6 | BL4: =AD4 -> 8 | BM4: SUM. | BN4: CLAS. | BR4: SIMBOLO | BS4: NOMBRE TIPICO
A5: GRANO GRUESO | E5: GW | F5: Gravas bien gradadas, mezclas gravosas, poco o ningun fino | G5: Cu ≥ 4 | H5: 1 ≤ Cc ≤ 3 | I5: Pasante Nº 200 menos del 5% | L5: Frac Arena < 15% | M5: Grava bien graduada | N5: =IF(C90<50,1,0) -> 1 | O5: =IF((B82/2)<C89,1,0) -> 0 | P5: =IF(C95>=4,1,0) -> 1 | Q5: =IF(T5=2,1,0) -> 1 | R5: =IF(C96>=1,1,0) -> 1 | S5: =IF(C96<=3,1,0) -> 1 | T5: =R5+S5 -> 2 | U5: =IF(C90<5,1,0) -> 0 | V5: - | W5: - | X5: - | Y5: =IF(AB5=2,1,0) -> 0 | Z5: =IF(C90>=5,1,0) -> 1 | AA5: =IF(C90<=12,1,0) -> 0 | AB5: =Z5+AA5 -> 1 | AC5: - | AD5: =IF(C85<15,1,0) -> 0 | AF5: =N5 -> 1 | AG5: =O5 -> 0 | AH5: =P5 -> 1 | AI5: =Q5 -> 1 | AJ5: =U5 -> 0 | AK5: =AD5 -> 0 | AL5: =SUM(AF5:AK5) -> 3 | AM5: =IF(AL5=6,E5,"") | AN5: =IF(AM5="",0,1) -> 0 | AO5: =N5 -> 1 | AP5: =O5 -> 0 | AQ5: =P5 -> 1 | AR5: =Q5 -> 1 | AS5: =U5 -> 0 | AT5: =AD5 -> 0 | AU5: =SUM(AO5:AT5) -> 3 | AV5: =IF(AU5=6,E5,"") | AW5: =IF(AV5="",0,1) -> 0 | AX5: =N5 -> 1 | AY5: =AG5 -> 0 | AZ5: =AH5 -> 1 | BA5: =AI5 -> 1 | BB5: =Y5 -> 0 | BC5: =AT5 -> 0 | BD5: =SUM(AX5:BC5) -> 3 | BE5: =IF(BD5=6,E5,"") | BF5: =IF(BE5="",0,1) -> 0 | BG5: =N5 -> 1 | BH5: =O5 -> 0 | BI5: =AQ5 -> 1 | BJ5: =AR5 -> 1 | BK5: =Y5 -> 0 | BL5: =AD5 -> 0 | BM5: =SUM(BG5:BL5) -> 3 | BN5: =IF(BM5=6,E5,"") | BO5: =IF(BN5="",0,1) -> 0 | BQ5: =AN5+AW5+BF5+BO5 -> 0 | BR5: =IF(BQ5=0,"",E5) | BS5: =IF(BQ5=0,"",M5) | BT5: =IF(BR5="",0,1) -> 0 | BU5: =BT5+BT6 -> 0 | BV5: =IF(BW5="",0,1) -> 0 | BW5: =IF(BU5=0,"",E5)
L6: Frac Arena ≥ 15% | M6: Grava bien graduada con arena | N6: =IF(C90<50,1,0) -> 1 | O6: =IF((B82/2)<C89,1,0) -> 0 | P6: =IF(C95>=4,1,0) -> 1 | Q6: =IF(T6=2,1,0) -> 1 | R6: =IF(C96>=1,1,0) -> 1 | S6: =IF(C96<=3,1,0) -> 1 | T6: =R6+S6 -> 2 | U6: =IF(C90<5,1,0) -> 0 | V6: - | W6: - | X6: - | Y6: =IF(AB6=2,1,0) -> 0 | Z6: =IF(C90>=5,1,0) -> 1 | AA6: =IF(C90<=12,1,0) -> 0 | AB6: =Z6+AA6 -> 1 | AC6: - | AD6: =IF(C85>=15,1,0) -> 1 | AF6: =N6 -> 1 | AG6: =O6 -> 0 | AH6: =P6 -> 1 | AI6: =Q6 -> 1 | AJ6: =U6 -> 0 | AK6: =AD6 -> 1 | AL6: =SUM(AF6:AK6) -> 4 | AM6: =IF(AL6=6,E5,"") | AN6: =IF(AM6="",0,1) -> 0 | AO6: =N6 -> 1 | AP6: =O6 -> 0 | AQ6: =P6 -> 1 | AR6: =Q6 -> 1 | AS6: =U6 -> 0 | AT6: =AD6 -> 1 | AU6: =SUM(AO6:AT6) -> 4 | AV6: =IF(AU6=6,E5,"") | AW6: =IF(AV6="",0,1) -> 0 | AX6: =N6 -> 1 | AY6: =AG6 -> 0 | AZ6: =AH6 -> 1 | BA6: =AI6 -> 1 | BB6: =Y6 -> 0 | BC6: =AT6 -> 1 | BD6: =SUM(AX6:BC6) -> 4 | BE6: =IF(BD6=6,E5,"") | BF6: =IF(BE6="",0,1) -> 0 | BG6: =N6 -> 1 | BH6: =O6 -> 0 | BI6: =AQ6 -> 1 | BJ6: =AR6 -> 1 | BK6: =Y6 -> 0 | BL6: =AD6 -> 1 | BM6: =SUM(BG6:BL6) -> 4 | BN6: =IF(BM6=6,E5,"") | BO6: =IF(BN6="",0,1) -> 0 | BQ6: =AN6+AW6+BF6+BO6 -> 0 | BR6: =IF(BQ6=0,"",E5) | BS6: =IF(BQ6=0,"",M6) | BT6: =IF(BR6="",0,1) -> 0
D7: Gravas (mas de a | E7: GP | F7: Gravas pobremente gradadas, mezcla grava - arena, pocos o ningun fino | G7: No cumple todos los requisitos de gradacion para GW | I7: Pasante Nº 200 menos del 5% | L7: Frac Arena < 15% | M7: Grava mal graduada | N7: =IF(C90<50,1,0) -> 1 | O7: =IF((B82/2)<C89,1,0) -> 0 | P7: =IF((P5+Q5=2),0,1) -> 0 | Q7: =IF((P5+Q5=2),0,1) -> 0 | R7: - | S7: - | T7: - | U7: =IF(C90<5,1,0) -> 0 | V7: - | W7: - | X7: - | Y7: =IF(AB7=2,1,0) -> 0 | Z7: =IF(C90>=5,1,0) -> 1 | AA7: =IF(C90<=12,1,0) -> 0 | AB7: =Z7+AA7 -> 1 | AC7: - | AD7: =IF(C85<15,1,0) -> 0 | AF7: =N7 -> 1 | AG7: =O7 -> 0 | AH7: =P7 -> 0 | AI7: =Q7 -> 0 | AJ7: =U7 -> 0 | AK7: =AD7 -> 0 | AL7: =SUM(AF7:AK7) -> 1 | AM7: =IF(AL7=6,E7,"") | AN7: =IF(AM7="",0,1) -> 0 | AO7: =N7 -> 1 | AP7: =O7 -> 0 | AQ7: =P7 -> 0 | AR7: =Q7 -> 0 | AS7: =U7 -> 0 | AT7: =AD7 -> 0 | AU7: =SUM(AO7:AT7) -> 1 | AV7: =IF(AU7=6,E7,"") | AW7: =IF(AV7="",0,1) -> 0 | AX7: =N7 -> 1 | AY7: =AG7 -> 0 | AZ7: =AH7 -> 0 | BA7: =AI7 -> 0 | BB7: =Y7 -> 0 | BC7: =AT7 -> 0 | BD7: =SUM(AX7:BC7) -> 1 | BE7: =IF(BD7=6,E7,"") | BF7: =IF(BE7="",0,1) -> 0 | BG7: =N7 -> 1 | BH7: =O7 -> 0 | BI7: =AQ7 -> 0 | BJ7: =AR7 -> 0 | BK7: =Y7 -> 0 | BL7: =AD7 -> 0 | BM7: =SUM(BG7:BL7) -> 1 | BN7: =IF(BM7=6,E7,"") | BO7: =IF(BN7="",0,1) -> 0 | BQ7: =AN7+AW7+BF7+BO7 -> 0 | BR7: =IF(BQ7=0,"",E7) | BS7: =IF(BQ7=0,"",M7) | BT7: =IF(BR7="",0,1) -> 0 | BU7: =BT7+BT8 -> 0 | BV7: =IF(BW7="",0,1) -> 0 | BW7: =IF(BU7=0,"",E7)
D8: mitad de la fraccion | L8: Frac Arena ≥ 15% | M8: Grava mal graduada con arena | N8: =IF(C90<50,1,0) -> 1 | O8: =IF((B82/2)<C89,1,0) -> 0 | P8: =IF((P5+Q5=2),0,1) -> 0 | Q8: =IF((P5+Q5=2),0,1) -> 0 | R8: - | S8: - | T8: - | U8: =IF(C90<5,1,0) -> 0 | V8: - | W8: - | X8: - | Y8: =IF(AB8=2,1,0) -> 0 | Z8: =IF(C90>=5,1,0) -> 1 | AA8: =IF(C90<=12,1,0) -> 0 | AB8: =Z8+AA8 -> 1 | AC8: - | AD8: =IF(C85>=15,1,0) -> 1 | AF8: =N8 -> 1 | AG8: =O8 -> 0 | AH8: =P8 -> 0 | AI8: =Q8 -> 0 | AJ8: =U8 -> 0 | AK8: =AD8 -> 1 | AL8: =SUM(AF8:AK8) -> 2 | AM8: =IF(AL8=6,E7,"") | AN8: =IF(AM8="",0,1) -> 0 | AO8: =N8 -> 1 | AP8: =O8 -> 0 | AQ8: =P8 -> 0 | AR8: =Q8 -> 0 | AS8: =U8 -> 0 | AT8: =AD8 -> 1 | AU8: =SUM(AO8:AT8) -> 2 | AV8: =IF(AU8=6,E7,"") | AW8: =IF(AV8="",0,1) -> 0 | AX8: =N8 -> 1 | AY8: =AG8 -> 0 | AZ8: =AH8 -> 0 | BA8: =AI8 -> 0 | BB8: =Y8 -> 0 | BC8: =AT8 -> 1 | BD8: =SUM(AX8:BC8) -> 2 | BE8: =IF(BD8=6,E7,"") | BF8: =IF(BE8="",0,1) -> 0 | BG8: =N8 -> 1 | BH8: =O8 -> 0 | BI8: =AQ8 -> 0 | BJ8: =AR8 -> 0 | BK8: =Y8 -> 0 | BL8: =AD8 -> 1 | BM8: =SUM(BG8:BL8) -> 2 | BN8: =IF(BM8=6,E7,"") | BO8: =IF(BN8="",0,1) -> 0 | BQ8: =AN8+AW8+BF8+BO8 -> 0 | BR8: =IF(BQ8=0,"",E7) | BS8: =IF(BQ8=0,"",M8) | BT8: =IF(BR8="",0,1) -> 0
D9: gruesa es mayor | E9: GM | F9: Gravas limosas, mezcla grava - arena - limo | G9: IP < 4 | I9: Pasante Nº 200 mas del 12% | L9: Frac Arena < 15% | M9: Grava limosa | N9: =IF(C90<50,1,0) -> 1 | O9: =IF((B82/2)<C89,1,0) -> 0 | P9: =IF(C94<4,1,0) -> 0 | Q9: =IF(T9=2,1,0) -> 0 | R9: =IF(C94>=4,1,0) -> 1 | S9: =IF(C94<=7,1,0) -> 0 | T9: =R9+S9 -> 1 | U9: =IF(C90>12,1,0) -> 1 | V9: - | W9: - | X9: - | Y9: =IF(AB9=2,1,0) -> 0 | Z9: =IF(C90>=5,1,0) -> 1 | AA9: =IF(C90<=12,1,0) -> 0 | AB9: =Z9+AA9 -> 1 | AC9: - | AD9: =IF(C85<15,1,0) -> 0 | AF9: =N9 -> 1 | AG9: =O9 -> 0 | AH9: =P9 -> 0 | AI9: - | AJ9: =U9 -> 1 | AK9: =AD9 -> 0 | AL9: =SUM(AF9:AK9) -> 2 | AM9: =IF(AL9=5,E9,"") | AN9: =IF(AM9="",0,1) -> 0 | AO9: =N9 -> 1 | AP9: =O9 -> 0 | AQ9: - | AR9: =Q9 -> 0 | AS9: =U9 -> 1 | AT9: =AD9 -> 0 | AU9: =SUM(AO9:AT9) -> 2 | AV9: =IF(AU9=5,E9,"") | AW9: =IF(AV9="",0,1) -> 0 | AX9: =N9 -> 1 | AY9: =AG9 -> 0 | AZ9: =AH9 -> 0 | BA9: =AI9 -> - | BB9: =Y9 -> 0 | BC9: =AT9 -> 0 | BD9: =SUM(AX9:BC9) -> 1 | BE9: =IF(BD9=5,E9,"") | BF9: =IF(BE9="",0,1) -> 0 | BG9: =N9 -> 1 | BH9: =O9 -> 0 | BI9: =AQ9 -> - | BJ9: =AR9 -> 0 | BK9: =Y9 -> 0 | BL9: =AD9 -> 0 | BM9: =SUM(BG9:BL9) -> 1 | BN9: =IF(BM9=5,E9,"") | BO9: =IF(BN9="",0,1) -> 0 | BQ9: =AN9+AW9+BF9+BO9 -> 0 | BR9: =IF(BQ9=0,"",E9) | BS9: =IF(BQ9=0,"",M9) | BT9: =IF(BR9="",0,1) -> 0 | BU9: =BT9+BT10 -> 0 | BV9: =IF(BW9="",0,1) -> 0 | BW9: =IF(BU9=0,"",E9)
D10: que el tamiz Nº 4 | H10: 4 ≤ IP ≤ 7 | L10: Frac Arena ≥ 15% | M10: Grava limosa con arena | N10: =IF(C90<50,1,0) -> 1 | O10: =IF((B82/2)<C89,1,0) -> 0 | P10: =IF(C94<4,1,0) -> 0 | Q10: =IF(T10=2,1,0) -> 0 | R10: =IF(C94>=4,1,0) -> 1 | S10: =IF(C94<=7,1,0) -> 0 | T10: =R10+S10 -> 1 | U10: =IF(C90>12,1,0) -> 1 | V10: - | W10: - | X10: - | Y10: =IF(AB10=2,1,0) -> 0 | Z10: =IF(C90>=5,1,0) -> 1 | AA10: =IF(C90<=12,1,0) -> 0 | AB10: =Z10+AA10 -> 1 | AC10: - | AD10: =IF(C85>=15,1,0) -> 1 | AF10: =N10 -> 1 | AG10: =O10 -> 0 | AH10: =P10 -> 0 | AI10: - | AJ10: =U10 -> 1 | AK10: =AD10 -> 1 | AL10: =SUM(AF10:AK10) -> 3 | AM10: =IF(AL10=5,E9,"") | AN10: =IF(AM10="",0,1) -> 0 | AO10: =N10 -> 1 | AP10: =O10 -> 0 | AQ10: - | AR10: =Q10 -> 0 | AS10: =U10 -> 1 | AT10: =AD10 -> 1 | AU10: =SUM(AO10:AT10) -> 3 | AV10: =IF(AU10=5,E9,"") | AW10: =IF(AV10="",0,1) -> 0 | AX10: =N10 -> 1 | AY10: =AG10 -> 0 | AZ10: =AH10 -> 0 | BA10: =AI10 -> - | BB10: =Y10 -> 0 | BC10: =AT10 -> 1 | BD10: =SUM(AX10:BC10) -> 2 | BE10: =IF(BD10=5,E9,"") | BF10: =IF(BE10="",0,1) -> 0 | BG10: =N10 -> 1 | BH10: =O10 -> 0 | BI10: =AQ10 -> - | BJ10: =AR10 -> 0 | BK10: =Y10 -> 0 | BL10: =AD10 -> 1 | BM10: =SUM(BG10:BL10) -> 2 | BN10: =IF(BM10=5,E9,"") | BO10: =IF(BN10="",0,1) -> 0 | BQ10: =AN10+AW10+BF10+BO10 -> 0 | BR10: =IF(BQ10=0,"",E9) | BS10: =IF(BQ10=0,"",M10) | BT10: =IF(BR10="",0,1) -> 0
B11: Mas del 50% de | E11: GC | F11: Gravas arcillosas, mezcla grava - arena - arcillosas | G11: IP > 7 | H11: Se les asigna doble simbolo | I11: Pasante Nº 200 mas del 12% | J11: De 5% a 12% | L11: Frac Arena < 15% | M11: Grava arcillosa | N11: =IF(C90<50,1,0) -> 1 | O11: =IF((B82/2)<C89,1,0) -> 0 | P11: =IF(C94>7,1,0) -> 1 | Q11: =IF(T11=2,1,0) -> 0 | R11: =IF(C94>=4,1,0) -> 1 | S11: =IF(C94<=7,1,0) -> 0 | T11: =R11+S11 -> 1 | U11: =IF(C90>12,1,0) -> 1 | V11: - | W11: - | X11: - | Y11: =IF(AB11=2,1,0) -> 0 | Z11: =IF(C90>=5,1,0) -> 1 | AA11: =IF(C90<=12,1,0) -> 0 | AB11: =Z11+AA11 -> 1 | AC11: - | AD11: =IF(C85<15,1,0) -> 0 | AF11: =N11 -> 1 | AG11: =O11 -> 0 | AH11: =P11 -> 1 | AI11: - | AJ11: =U11 -> 1 | AK11: =AD11 -> 0 | AL11: =SUM(AF11:AK11) -> 3 | AM11: =IF(AL11=5,E11,"") | AN11: =IF(AM11="",0,1) -> 0 | AO11: =N11 -> 1 | AP11: =O11 -> 0 | AQ11: - | AR11: =Q11 -> 0 | AS11: =U11 -> 1 | AT11: =AD11 -> 0 | AU11: =SUM(AO11:AT11) -> 2 | AV11: =IF(AU11=5,E11,"") | AW11: =IF(AV11="",0,1) -> 0 | AX11: =N11 -> 1 | AY11: =AG11 -> 0 | AZ11: =AH11 -> 1 | BA11: =AI11 -> - | BB11: =Y11 -> 0 | BC11: =AT11 -> 0 | BD11: =SUM(AX11:BC11) -> 2 | BE11: =IF(BD11=5,E11,"") | BF11: =IF(BE11="",0,1) -> 0 | BG11: =N11 -> 1 | BH11: =O11 -> 0 | BI11: =AQ11 -> - | BJ11: =AR11 -> 0 | BK11: =Y11 -> 0 | BL11: =AD11 -> 0 | BM11: =SUM(BG11:BL11) -> 1 | BN11: =IF(BM11=5,E11,"") | BO11: =IF(BN11="",0,1) -> 0 | BQ11: =AN11+AW11+BF11+BO11 -> 0 | BR11: =IF(BQ11=0,"",E11) | BS11: =IF(BQ11=0,"",M11) | BT11: =IF(BR11="",0,1) -> 0 | BU11: =BT11+BT12 -> 0 | BV11: =IF(BW11="",0,1) -> 0 | BW11: =IF(BU11=0,"",E11)
B12: la muestra es | L12: Frac Arena ≥ 15% | M12: Grava arcillosa con arena | N12: =IF(C90<50,1,0) -> 1 | O12: =IF((B82/2)<C89,1,0) -> 0 | P12: =IF(C94>7,1,0) -> 1 | Q12: =IF(T12=2,1,0) -> 0 | R12: =IF(C94>=4,1,0) -> 1 | S12: =IF(C94<=7,1,0) -> 0 | T12: =R12+S12 -> 1 | U12: =IF(C90>12,1,0) -> 1 | V12: - | W12: - | X12: - | Y12: =IF(AB12=2,1,0) -> 0 | Z12: =IF(C90>=5,1,0) -> 1 | AA12: =IF(C90<=12,1,0) -> 0 | AB12: =Z12+AA12 -> 1 | AC12: - | AD12: =IF(C85>=15,1,0) -> 1 | AF12: =N12 -> 1 | AG12: =O12 -> 0 | AH12: =P12 -> 1 | AI12: - | AJ12: =U12 -> 1 | AK12: =AD12 -> 1 | AL12: =SUM(AF12:AK12) -> 4 | AM12: =IF(AL12=5,E11,"") | AN12: =IF(AM12="",0,1) -> 0 | AO12: =N12 -> 1 | AP12: =O12 -> 0 | AQ12: - | AR12: =Q12 -> 0 | AS12: =U12 -> 1 | AT12: =AD12 -> 1 | AU12: =SUM(AO12:AT12) -> 3 | AV12: =IF(AU12=5,E11,"") | AW12: =IF(AV12="",0,1) -> 0 | AX12: =N12 -> 1 | AY12: =AG12 -> 0 | AZ12: =AH12 -> 1 | BA12: =AI12 -> - | BB12: =Y12 -> 0 | BC12: =AT12 -> 1 | BD12: =SUM(AX12:BC12) -> 3 | BE12: =IF(BD12=5,E11,"") | BF12: =IF(BE12="",0,1) -> 0 | BG12: =N12 -> 1 | BH12: =O12 -> 0 | BI12: =AQ12 -> - | BJ12: =AR12 -> 0 | BK12: =Y12 -> 0 | BL12: =AD12 -> 1 | BM12: =SUM(BG12:BL12) -> 2 | BN12: =IF(BM12=5,E11,"") | BO12: =IF(BN12="",0,1) -> 0 | BQ12: =AN12+AW12+BF12+BO12 -> 0 | BR12: =IF(BQ12=0,"",E11) | BS12: =IF(BQ12=0,"",M12) | BT12: =IF(BR12="",0,1) -> 0
B13: retenido por el | E13: SW | F13: Arenas bien gradadas, arenas - gravosas, pocos o ningun fino | G13: Cu ≥ 6 | H13: 1 ≤ Cc ≤ 3 | I13: Pasante Nº 200 menos del 5% | J13: Doble Simbolo | L13: Frac Grava < 15% | M13: Arena bien graduada | N13: =IF(C90<50,1,0) -> 1 | O13: =IF((B82/2)>C89,1,0) -> 1 | P13: =IF(C95>=6,1,0) -> 1 | Q13: =IF(T13=2,1,0) -> 1 | R13: =IF(C96>=1,1,0) -> 1 | S13: =IF(C96<=3,1,0) -> 1 | T13: =R13+S13 -> 2 | U13: =IF(C90<5,1,0) -> 0 | V13: - | W13: - | X13: - | Y13: =IF(AB13=2,1,0) -> 0 | Z13: =IF(C90>=5,1,0) -> 1 | AA13: =IF(C90<=12,1,0) -> 0 | AB13: =Z13+AA13 -> 1 | AC13: - | AD13: =IF(C85<15,1,0) -> 0 | AF13: =N13 -> 1 | AG13: =O13 -> 1 | AH13: =P13 -> 1 | AI13: =Q13 -> 1 | AJ13: =U13 -> 0 | AK13: =AD13 -> 0 | AL13: =SUM(AF13:AK13) -> 4 | AM13: =IF(AL13=6,E13,"") | AN13: =IF(AM13="",0,1) -> 0 | AO13: =N13 -> 1 | AP13: =O13 -> 1 | AQ13: =P13 -> 1 | AR13: =Q13 -> 1 | AS13: =U13 -> 0 | AT13: =AD13 -> 0 | AU13: =SUM(AO13:AT13) -> 4 | AV13: =IF(AU13=6,E13,"") | AW13: =IF(AV13="",0,1) -> 0 | AX13: =N13 -> 1 | AY13: =AG13 -> 1 | AZ13: =AH13 -> 1 | BA13: =AI13 -> 1 | BB13: =Y13 -> 0 | BC13: =AT13 -> 0 | BD13: =SUM(AX13:BC13) -> 4 | BE13: =IF(BD13=6,E13,"") | BF13: =IF(BE13="",0,1) -> 0 | BG13: =N13 -> 1 | BH13: =O13 -> 1 | BI13: =AQ13 -> 1 | BJ13: =AR13 -> 1 | BK13: =Y13 -> 0 | BL13: =AD13 -> 0 | BM13: =SUM(BG13:BL13) -> 4 | BN13: =IF(BM13=6,E13,"") | BO13: =IF(BN13="",0,1) -> 0 | BQ13: =AN13+AW13+BF13+BO13 -> 0 | BR13: =IF(BQ13=0,"",E13) | BS13: =IF(BQ13=0,"",M13) | BT13: =IF(BR13="",0,1) -> 0 | BU13: =BT13+BT14 -> 0 | BV13: =IF(BW13="",0,1) -> 0 | BW13: =IF(BU13=0,"",E13)
B14: tamiz Nº 200 | L14: Frac Grava ≥ 15% | M14: Arena bien graduada con arena | N14: =IF(C90<50,1,0) -> 1 | O14: =IF((B82/2)>C89,1,0) -> 1 | P14: =IF(C95>=6,1,0) -> 1 | Q14: =IF(T14=2,1,0) -> 1 | R14: =IF(C96>=1,1,0) -> 1 | S14: =IF(C96<=3,1,0) -> 1 | T14: =R14+S14 -> 2 | U14: =IF(C90<5,1,0) -> 0 | V14: - | W14: - | X14: - | Y14: =IF(AB14=2,1,0) -> 0 | Z14: =IF(C90>=5,1,0) -> 1 | AA14: =IF(C90<=12,1,0) -> 0 | AB14: =Z14+AA14 -> 1 | AC14: - | AD14: =IF(C85>=15,1,0) -> 1 | AF14: =N14 -> 1 | AG14: =O14 -> 1 | AH14: =P14 -> 1 | AI14: =Q14 -> 1 | AJ14: =U14 -> 0 | AK14: =AD14 -> 1 | AL14: =SUM(AF14:AK14) -> 5 | AM14: =IF(AL14=6,E13,"") | AN14: =IF(AM14="",0,1) -> 0 | AO14: =N14 -> 1 | AP14: =O14 -> 1 | AQ14: =P14 -> 1 | AR14: =Q14 -> 1 | AS14: =U14 -> 0 | AT14: =AD14 -> 1 | AU14: =SUM(AO14:AT14) -> 5 | AV14: =IF(AU14=6,E13,"") | AW14: =IF(AV14="",0,1) -> 0 | AX14: =N14 -> 1 | AY14: =AG14 -> 1 | AZ14: =AH14 -> 1 | BA14: =AI14 -> 1 | BB14: =Y14 -> 0 | BC14: =AT14 -> 1 | BD14: =SUM(AX14:BC14) -> 5 | BE14: =IF(BD14=6,E13,"") | BF14: =IF(BE14="",0,1) -> 0 | BG14: =N14 -> 1 | BH14: =O14 -> 1 | BI14: =AQ14 -> 1 | BJ14: =AR14 -> 1 | BK14: =Y14 -> 0 | BL14: =AD14 -> 1 | BM14: =SUM(BG14:BL14) -> 5 | BN14: =IF(BM14=6,E13,"") | BO14: =IF(BN14="",0,1) -> 0 | BQ14: =AN14+AW14+BF14+BO14 -> 0 | BR14: =IF(BQ14=0,"",E13) | BS14: =IF(BQ14=0,"",M14) | BT14: =IF(BR14="",0,1) -> 0
D15: Arenas (mas de la | E15: SP | F15: Arenas pobremente gradadas, arenas gravosas, pocos o ningun fino | G15: No cumple todos los requisitos de gradacion para SW | I15: Pasante Nº 200 menos del 5% | L15: Frac Grava < 15% | M15: Arena mal graduada | N15: =IF(C90<50,1,0) -> 1 | O15: =IF((B82/2)>C89,1,0) -> 1 | P15: =IF((P13+Q13=2),0,1) -> 0 | Q15: =IF((P13+Q13=2),0,1) -> 0 | R15: - | S15: - | T15: - | U15: =IF(C90<5,1,0) -> 0 | V15: - | W15: - | X15: - | Y15: =IF(AB15=2,1,0) -> 0 | Z15: =IF(C90>=5,1,0) -> 1 | AA15: =IF(C90<=12,1,0) -> 0 | AB15: =Z15+AA15 -> 1 | AC15: - | AD15: =IF(C85<15,1,0) -> 0 | AF15: =N15 -> 1 | AG15: =O15 -> 1 | AH15: =P15 -> 0 | AI15: =Q15 -> 0 | AJ15: =U15 -> 0 | AK15: =AD15 -> 0 | AL15: =SUM(AF15:AK15) -> 2 | AM15: =IF(AL15=6,E15,"") | AN15: =IF(AM15="",0,1) -> 0 | AO15: =N15 -> 1 | AP15: =O15 -> 1 | AQ15: =P15 -> 0 | AR15: =Q15 -> 0 | AS15: =U15 -> 0 | AT15: =AD15 -> 0 | AU15: =SUM(AO15:AT15) -> 2 | AV15: =IF(AU15=6,E15,"") | AW15: =IF(AV15="",0,1) -> 0 | AX15: =N15 -> 1 | AY15: =AG15 -> 1 | AZ15: =AH15 -> 0 | BA15: =AI15 -> 0 | BB15: =Y15 -> 0 | BC15: =AT15 -> 0 | BD15: =SUM(AX15:BC15) -> 2 | BE15: =IF(BD15=6,E15,"") | BF15: =IF(BE15="",0,1) -> 0 | BG15: =N15 -> 1 | BH15: =O15 -> 1 | BI15: =AQ15 -> 0 | BJ15: =AR15 -> 0 | BK15: =Y15 -> 0 | BL15: =AD15 -> 0 | BM15: =SUM(BG15:BL15) -> 2 | BN15: =IF(BM15=6,E15,"") | BO15: =IF(BN15="",0,1) -> 0 | BQ15: =AN15+AW15+BF15+BO15 -> 0 | BR15: =IF(BQ15=0,"",E15) | BS15: =IF(BQ15=0,"",M15) | BT15: =IF(BR15="",0,1) -> 0 | BU15: =BT15+BT16 -> 0 | BV15: =IF(BW15="",0,1) -> 0 | BW15: =IF(BU15=0,"",E15)
D16: mitad de la fraccion | L16: Frac Grava ≥ 15% | M16: Arena mal graduada con grava | N16: =IF(C90<50,1,0) -> 1 | O16: =IF((B82/2)>C89,1,0) -> 1 | P16: =IF((P13+Q13=2),0,1) -> 0 | Q16: =IF((P13+Q13=2),0,1) -> 0 | R16: - | S16: - | T16: - | U16: =IF(C90<5,1,0) -> 0 | V16: - | W16: - | X16: - | Y16: =IF(AB16=2,1,0) -> 0 | Z16: =IF(C90>=5,1,0) -> 1 | AA16: =IF(C90<=12,1,0) -> 0 | AB16: =Z16+AA16 -> 1 | AC16: - | AD16: =IF(C85>=15,1,0) -> 1 | AF16: =N16 -> 1 | AG16: =O16 -> 1 | AH16: =P16 -> 0 | AI16: =Q16 -> 0 | AJ16: =U16 -> 0 | AK16: =AD16 -> 1 | AL16: =SUM(AF16:AK16) -> 3 | AM16: =IF(AL16=6,E15,"") | AN16: =IF(AM16="",0,1) -> 0 | AO16: =N16 -> 1 | AP16: =O16 -> 1 | AQ16: =P16 -> 0 | AR16: =Q16 -> 0 | AS16: =U16 -> 0 | AT16: =AD16 -> 1 | AU16: =SUM(AO16:AT16) -> 3 | AV16: =IF(AU16=6,E15,"") | AW16: =IF(AV16="",0,1) -> 0 | AX16: =N16 -> 1 | AY16: =AG16 -> 1 | AZ16: =AH16 -> 0 | BA16: =AI16 -> 0 | BB16: =Y16 -> 0 | BC16: =AT16 -> 1 | BD16: =SUM(AX16:BC16) -> 3 | BE16: =IF(BD16=6,E15,"") | BF16: =IF(BE16="",0,1) -> 0 | BG16: =N16 -> 1 | BH16: =O16 -> 1 | BI16: =AQ16 -> 0 | BJ16: =AR16 -> 0 | BK16: =Y16 -> 0 | BL16: =AD16 -> 1 | BM16: =SUM(BG16:BL16) -> 3 | BN16: =IF(BM16=6,E15,"") | BO16: =IF(BN16="",0,1) -> 0 | BQ16: =AN16+AW16+BF16+BO16 -> 0 | BR16: =IF(BQ16=0,"",E15) | BS16: =IF(BQ16=0,"",M16) | BT16: =IF(BR16="",0,1) -> 0
D17: gruesa es menor | E17: SM | F17: Arenas limosas mezcla de arena - limo | G17: IP < 4 | I17: Pasante Nº 200 mas del 12% | L17: Frac Grava < 15% | M17: Arena limosa | N17: =IF(C90<50,1,0) -> 1 | O17: =IF((B82/2)>C89,1,0) -> 1 | P17: =IF(C94<4,1,0) -> 0 | Q17: =IF(T17=2,1,0) -> 0 | R17: =IF(C94>=4,1,0) -> 1 | S17: =IF(C94<=7,1,0) -> 0 | T17: =R17+S17 -> 1 | U17: =IF(C90>12,1,0) -> 1 | V17: - | W17: - | X17: - | Y17: =IF(AB17=2,1,0) -> 0 | Z17: =IF(C90>=5,1,0) -> 1 | AA17: =IF(C90<=12,1,0) -> 0 | AB17: =Z17+AA17 -> 1 | AC17: - | AD17: =IF(C85<15,1,0) -> 0 | AF17: =N17 -> 1 | AG17: =O17 -> 1 | AH17: =P17 -> 0 | AI17: - | AJ17: =U17 -> 1 | AK17: =AD17 -> 0 | AL17: =SUM(AF17:AK17) -> 3 | AM17: =IF(AL17=5,E17,"") | AN17: =IF(AM17="",0,1) -> 0 | AO17: =N17 -> 1 | AP17: =O17 -> 1 | AQ17: - | AR17: =Q17 -> 0 | AS17: =U17 -> 1 | AT17: =AD17 -> 0 | AU17: =SUM(AO17:AT17) -> 3 | AV17: =IF(AU17=5,E17,"") | AW17: =IF(AV17="",0,1) -> 0 | AX17: =N17 -> 1 | AY17: =AG17 -> 1 | AZ17: =AH17 -> 0 | BA17: =AI17 -> - | BB17: =Y17 -> 0 | BC17: =AT17 -> 0 | BD17: =SUM(AX17:BC17) -> 2 | BE17: =IF(BD17=5,E17,"") | BF17: =IF(BE17="",0,1) -> 0 | BG17: =N17 -> 1 | BH17: =O17 -> 1 | BI17: =AQ17 -> - | BJ17: =AR17 -> 0 | BK17: =Y17 -> 0 | BL17: =AD17 -> 0 | BM17: =SUM(BG17:BL17) -> 2 | BN17: =IF(BM17=5,E17,"") | BO17: =IF(BN17="",0,1) -> 0 | BQ17: =AN17+AW17+BF17+BO17 -> 0 | BR17: =IF(BQ17=0,"",E17) | BS17: =IF(BQ17=0,"",M17) | BT17: =IF(BR17="",0,1) -> 0 | BU17: =BT17+BT18 -> 0 | BV17: =IF(BW17="",0,1) -> 0 | BW17: =IF(BU17=0,"",E17)
D18: que el tamiz Nº 4 | H18: 1 | L18: Frac Grava ≥ 15% | M18: Arena limosa con grava | N18: =IF(C90<50,1,0) -> 1 | O18: =IF((B82/2)>C89,1,0) -> 1 | P18: =IF(C94<4,1,0) -> 0 | Q18: =IF(T18=2,1,0) -> 0 | R18: =IF(C94>=4,1,0) -> 1 | S18: =IF(C94<=7,1,0) -> 0 | T18: =R18+S18 -> 1 | U18: =IF(C90>12,1,0) -> 1 | V18: - | W18: - | X18: - | Y18: =IF(AB18=2,1,0) -> 0 | Z18: =IF(C90>=5,1,0) -> 1 | AA18: =IF(C90<=12,1,0) -> 0 | AB18: =Z18+AA18 -> 1 | AC18: - | AD18: =IF(C85>=15,1,0) -> 1 | AF18: =N18 -> 1 | AG18: =O18 -> 1 | AH18: =P18 -> 0 | AI18: - | AJ18: =U18 -> 1 | AK18: =AD18 -> 1 | AL18: =SUM(AF18:AK18) -> 4 | AM18: =IF(AL18=5,E17,"") | AN18: =IF(AM18="",0,1) -> 0 | AO18: =N18 -> 1 | AP18: =O18 -> 1 | AQ18: - | AR18: =Q18 -> 0 | AS18: =U18 -> 1 | AT18: =AD18 -> 1 | AU18: =SUM(AO18:AT18) -> 4 | AV18: =IF(AU18=5,E17,"") | AW18: =IF(AV18="",0,1) -> 0 | AX18: =N18 -> 1 | AY18: =AG18 -> 1 | AZ18: =AH18 -> 0 | BA18: =AI18 -> - | BB18: =Y18 -> 0 | BC18: =AT18 -> 1 | BD18: =SUM(AX18:BC18) -> 3 | BE18: =IF(BD18=5,E17,"") | BF18: =IF(BE18="",0,1) -> 0 | BG18: =N18 -> 1 | BH18: =O18 -> 1 | BI18: =AQ18 -> - | BJ18: =AR18 -> 0 | BK18: =Y18 -> 0 | BL18: =AD18 -> 1 | BM18: =SUM(BG18:BL18) -> 3 | BN18: =IF(BM18=5,E17,"") | BO18: =IF(BN18="",0,1) -> 0 | BQ18: =AN18+AW18+BF18+BO18 -> 0 | BR18: =IF(BQ18=0,"",E17) | BS18: =IF(BQ18=0,"",M18) | BT18: =IF(BR18="",0,1) -> 0
E19: SC | F19: Arenas arcillosas, mezclas arenas - arcilla | G19: IP > 7 | H19: se coloca doble simbolo | I19: Pasante Nº 200 mas del 12% | L19: Frac Grava < 15% | M19: Arena arcillosa | N19: =IF(C90<50,1,0) -> 1 | O19: =IF((B82/2)>C89,1,0) -> 1 | P19: =IF(C94>7,1,0) -> 1 | Q19: =IF(T19=2,1,0) -> 0 | R19: =IF(C94>=4,1,0) -> 1 | S19: =IF(C94<=7,1,0) -> 0 | T19: =R19+S19 -> 1 | U19: =IF(C90>12,1,0) -> 1 | V19: - | W19: - | X19: - | Y19: =IF(AB19=2,1,0) -> 0 | Z19: =IF(C90>=5,1,0) -> 1 | AA19: =IF(C90<=12,1,0) -> 0 | AB19: =Z19+AA19 -> 1 | AC19: - | AD19: =IF(C85<15,1,0) -> 0 | AF19: =N19 -> 1 | AG19: =O19 -> 1 | AH19: =P19 -> 1 | AI19: - | AJ19: =U19 -> 1 | AK19: =AD19 -> 0 | AL19: =SUM(AF19:AK19) -> 4 | AM19: =IF(AL19=5,E19,"") | AN19: =IF(AM19="",0,1) -> 0 | AO19: =N19 -> 1 | AP19: =O19 -> 1 | AQ19: - | AR19: =Q19 -> 0 | AS19: =U19 -> 1 | AT19: =AD19 -> 0 | AU19: =SUM(AO19:AT19) -> 3 | AV19: =IF(AU19=5,E19,"") | AW19: =IF(AV19="",0,1) -> 0 | AX19: =N19 -> 1 | AY19: =AG19 -> 1 | AZ19: =AH19 -> 1 | BA19: =AI19 -> - | BB19: =Y19 -> 0 | BC19: =AT19 -> 0 | BD19: =SUM(AX19:BC19) -> 3 | BE19: =IF(BD19=5,E19,"") | BF19: =IF(BE19="",0,1) -> 0 | BG19: =N19 -> 1 | BH19: =O19 -> 1 | BI19: =AQ19 -> - | BJ19: =AR19 -> 0 | BK19: =Y19 -> 0 | BL19: =AD19 -> 0 | BM19: =SUM(BG19:BL19) -> 2 | BN19: =IF(BM19=5,E19,"") | BO19: =IF(BN19="",0,1) -> 0 | BQ19: =AN19+AW19+BF19+BO19 -> 0 | BR19: =IF(BQ19=0,"",E19) | BS19: =IF(BQ19=0,"",M19) | BT19: =IF(BR19="",0,1) -> 0 | BU19: =BT19+BT20 -> 1 | BV19: =IF(BW19="",0,1) -> 1 | BW19: =IF(BU19=0,"",E19) -> SC
L20: Frac Grava ≥ 15% | M20: Arena arcillosa con grava | N20: =IF(C90<50,1,0) -> 1 | O20: =IF((B82/2)>C89,1,0) -> 1 | P20: =IF(C94>7,1,0) -> 1 | Q20: =IF(T20=2,1,0) -> 0 | R20: =IF(C94>=4,1,0) -> 1 | S20: =IF(C94<=7,1,0) -> 0 | T20: =R20+S20 -> 1 | U20: =IF(C90>12,1,0) -> 1 | V20: - | W20: - | X20: - | Y20: =IF(AB20=2,1,0) -> 0 | Z20: =IF(C90>=5,1,0) -> 1 | AA20: =IF(C90<=12,1,0) -> 0 | AB20: =Z20+AA20 -> 1 | AC20: - | AD20: =IF(C85>=15,1,0) -> 1 | AF20: =N20 -> 1 | AG20: =O20 -> 1 | AH20: =P20 -> 1 | AI20: - | AJ20: =U20 -> 1 | AK20: =AD20 -> 1 | AL20: =SUM(AF20:AK20) -> 5 | AM20: =IF(AL20=5,E19,"") -> SC | AN20: =IF(AM20="",0,1) -> 1 | AO20: =N20 -> 1 | AP20: =O20 -> 1 | AQ20: - | AR20: =Q20 -> 0 | AS20: =U20 -> 1 | AT20: =AD20 -> 1 | AU20: =SUM(AO20:AT20) -> 4 | AV20: =IF(AU20=5,E19,"") | AW20: =IF(AV20="",0,1) -> 0 | AX20: =N20 -> 1 | AY20: =AG20 -> 1 | AZ20: =AH20 -> 1 | BA20: =AI20 -> - | BB20: =Y20 -> 0 | BC20: =AT20 -> 1 | BD20: =SUM(AX20:BC20) -> 4 | BE20: =IF(BD20=5,E19,"") | BF20: =IF(BE20="",0,1) -> 0 | BG20: =N20 -> 1 | BH20: =O20 -> 1 | BI20: =AQ20 -> - | BJ20: =AR20 -> 0 | BK20: =Y20 -> 0 | BL20: =AD20 -> 1 | BM20: =SUM(BG20:BL20) -> 3 | BN20: =IF(BM20=5,E19,"") | BO20: =IF(BN20="",0,1) -> 0 | BQ20: =AN20+AW20+BF20+BO20 -> 1 | BR20: =IF(BQ20=0,"",E19) -> SC | BS20: =IF(BQ20=0,"",M20) -> Arena arcillosa con grava | BT20: =IF(BR20="",0,1) -> 1
BT21: =IF(BR21="",0,1) -> 0
AF22: CLASIFICACION SIMPLE (Inf. 3) | AQ22: CLASIFICACION SIMPLE (Inf. 4) | BT22: =IF(BR22="",0,1) -> 0
AF23: 1 | AG23: 2 | AH23: 3 | AI23: 4 | AJ23: 5 | AK23: 6 | AL23: 7 | AM23: 8 | AN23: SUM. | AO23: CLAS. | AQ23: 1 | AR23: 2 | AS23: 3 | AT23: 4 | AU23: 5 | AV23: 6 | AW23: 7 | AX23: 8 | AY23: SUM. | AZ23: CLAS. | BT23: =IF(BR23="",0,1) -> 0
A24: GRANO FINO | E24: ML | G24: IP < 4 | I24: Retenido Nº 200 < 15% | J24: - | K24: - | L24: - | M24: Limo | N24: =IF(C90>50,1,0) -> 0 | O24: =IF(C92<50,1,0) -> 1 | P24: =IF(C94<4,1,0) -> 0 | Q24: =IF(T24=2,1,0) -> 0 | R24: =IF(C94>=4,1,0) -> 1 | S24: =IF(C94<=7,1,0) -> 0 | T24: =R24+S24 -> 1 | U24: =IF(C91<15,1,0) -> 0 | V24: - | W24: - | X24: - | Y24: - | Z24: - | AA24: - | AB24: - | AC24: - | AD24: - | AF24: =N24 -> 0 | AG24: =O24 -> 1 | AH24: =P24 -> 0 | AI24: - | AJ24: =U24 -> 0 | AK24: =Y24 -> - | AL24: =AC24 -> - | AM24: =AD24 -> - | AN24: =SUM(AF24:AM24) -> 1 | AO24: =IF(AN24=4,E24,"") | AP24: =IF(AO24="",0,1) -> 0 | AQ24: =N24 -> 0 | AR24: =O24 -> 1 | AS24: - | AT24: =Q24 -> 0 | AU24: =U24 -> 0 | AV24: =Y24 -> - | AW24: =AC24 -> - | AX24: =AD24 -> - | AY24: =SUM(AQ24:AX24) -> 1 | AZ24: =IF(AY24=4,E24,"") | BA24: =IF(AZ24="",0,1) -> 0 | BQ24: =AP24+BA24 -> 0 | BR24: =IF(BQ24=0,"",E24) | BS24: =IF(BQ24=0,"",M24) | BT24: =IF(BR24="",0,1) -> 0 | BU24: =SUM(BT21:BT30) -> 0 | BV24: =IF(BW24="",0,1) -> 0 | BW24: =IF(BU24=0,"",E24)
I25: Retenido Nº 200 15% - 29% | J25: %Arena / %Grava ≥ 1 | K25: - | L25: - | M25: Limo con arena | N25: =IF(C90>50,1,0) -> 0 | O25: =IF(C92<50,1,0) -> 1 | P25: =IF(C94<4,1,0) -> 0 | Q25: =IF(T25=2,1,0) -> 0 | R25: =IF(C94>=4,1,0) -> 1 | S25: =IF(C94<=7,1,0) -> 0 | T25: =R25+S25 -> 1 | U25: =IF(X25=2,1,0) -> 0 | V25: =IF(C91>=15,1,0) -> 1 | W25: =IF(C91<=29,1,0) -> 0 | X25: =V25+W25 -> 1 | Y25: =IF((C85/C84)>=1,1,0) -> 1 | Z25: - | AA25: - | AB25: - | AC25: - | AD25: - | AF25: =N25 -> 0 | AG25: =O25 -> 1 | AH25: =P25 -> 0 | AI25: - | AJ25: =U25 -> 0 | AK25: =Y25 -> 1 | AL25: =AC25 -> - | AM25: =AD25 -> - | AN25: =SUM(AF25:AM25) -> 2 | AO25: =IF(AN25=5,E24,"") | AP25: =IF(AO25="",0,1) -> 0 | AQ25: =N25 -> 0 | AR25: =O25 -> 1 | AS25: - | AT25: =Q25 -> 0 | AU25: =U25 -> 0 | AV25: =Y25 -> 1 | AW25: =AC25 -> - | AX25: =AD25 -> - | AY25: =SUM(AQ25:AX25) -> 2 | AZ25: =IF(AY25=5,E24,"") | BA25: =IF(AZ25="",0,1) -> 0 | BQ25: =AP25+BA25 -> 0 | BR25: =IF(BQ25=0,"",E24) | BS25: =IF(BQ25=0,"",M25) | BT25: =IF(BR25="",0,1) -> 0
F26: Limos inorganicos y arena muy finas, polvo de roca, arenas finas limosas | J26: %Arena / %Grava < 1 | K26: - | L26: - | M26: Limo con grava | N26: =IF(C90>50,1,0) -> 0 | O26: =IF(C92<50,1,0) -> 1 | P26: =IF(C94<4,1,0) -> 0 | Q26: =IF(T26=2,1,0) -> 0 | R26: =IF(C94>=4,1,0) -> 1 | S26: =IF(C94<=7,1,0) -> 0 | T26: =R26+S26 -> 1 | U26: - | V26: - | W26: - | X26: - | Y26: =IF(C85/C84<1,1,0) -> 0 | Z26: - | AA26: - | AB26: - | AC26: - | AD26: - | AF26: =N26 -> 0 | AG26: =O26 -> 1 | AH26: =P26 -> 0 | AI26: - | AJ26: =U26 -> - | AK26: =Y26 -> 0 | AL26: =AC26 -> - | AM26: =AD26 -> - | AN26: =SUM(AF26:AM26) -> 1 | AO26: =IF(AN26=4,E24,"") | AP26: =IF(AO26="",0,1) -> 0 | AQ26: =N26 -> 0 | AR26: =O26 -> 1 | AS26: - | AT26: =Q26 -> 0 | AU26: =U26 -> - | AV26: =Y26 -> 0 | AW26: =AC26 -> - | AX26: =AD26 -> - | AY26: =SUM(AQ26:AX26) -> 1 | AZ26: =IF(AY26=5,E24,"") | BA26: =IF(AZ26="",0,1) -> 0 | BQ26: =AP26+BA26 -> 0 | BR26: =IF(BQ26=0,"",E24) | BS26: =IF(BQ26=0,"",M26) | BT26: =IF(BR26="",0,1) -> 0
I27: Retenido Nº 200 ≥ 30% | J27: %Arena / %Grava ≥ 1 | K27: %Grava < 15 | L27: - | M27: Limo arenoso | N27: =IF(C90>50,1,0) -> 0 | O27: =IF(C92<50,1,0) -> 1 | P27: =IF(C94<4,1,0) -> 0 | Q27: =IF(T27=2,1,0) -> 0 | R27: =IF(C94>=4,1,0) -> 1 | S27: =IF(C94<=7,1,0) -> 0 | T27: =R27+S27 -> 1 | U27: =IF(C91>=30,1,0) -> 1 | V27: - | W27: - | X27: - | Y27: =IF((C85/C84)>=1,1,0) -> 1 | Z27: - | AA27: - | AB27: - | AC27: =IF(C84<15,1,0) -> 0 | AD27: - | AF27: =N27 -> 0 | AG27: =O27 -> 1 | AH27: =P27 -> 0 | AI27: - | AJ27: =U27 -> 1 | AK27: =Y27 -> 1 | AL27: =AC27 -> 0 | AM27: =AD27 -> - | AN27: =SUM(AF27:AM27) -> 3 | AO27: =IF(AN27=6,E24,"") | AP27: =IF(AO27="",0,1) -> 0 | AQ27: =N27 -> 0 | AR27: =O27 -> 1 | AS27: - | AT27: =Q27 -> 0 | AU27: =U27 -> 1 | AV27: =Y27 -> 1 | AW27: =AC27 -> 0 | AX27: =AD27 -> - | AY27: =SUM(AQ27:AX27) -> 3 | AZ27: =IF(AY27=6,E24,"") | BA27: =IF(AZ27="",0,1) -> 0 | BQ27: =AP27+BA27 -> 0 | BR27: =IF(BQ27=0,"",E24) | BS27: =IF(BQ27=0,"",M27) | BT27: =IF(BR27="",0,1) -> 0
F28: o arcillosas, o limos arcillosos con poca plasticidad | J28: %Arena / %Grava ≥ 1 | K28: %Grava ≥ 15 | L28: - | M28: Limo arenoso con grava | N28: =IF(C90>50,1,0) -> 0 | O28: =IF(C92<50,1,0) -> 1 | P28: =IF(C94<4,1,0) -> 0 | Q28: =IF(T28=2,1,0) -> 0 | R28: =IF(C94>=4,1,0) -> 1 | S28: =IF(C94<=7,1,0) -> 0 | T28: =R28+S28 -> 1 | U28: - | V28: - | W28: - | X28: - | Y28: =IF((C85/C84)>=1,1,0) -> 1 | Z28: - | AA28: - | AB28: - | AC28: =IF(C84>=15,1,0) -> 1 | AD28: - | AF28: =N28 -> 0 | AG28: =O28 -> 1 | AH28: =P28 -> 0 | AI28: - | AJ28: =U28 -> - | AK28: =Y28 -> 1 | AL28: =AC28 -> 1 | AM28: =AD28 -> - | AN28: =SUM(AF28:AM28) -> 3 | AO28: =IF(AN28=5,E24,"") | AP28: =IF(AO28="",0,1) -> 0 | AQ28: =N28 -> 0 | AR28: =O28 -> 1 | AS28: - | AT28: =Q28 -> 0 | AU28: =U28 -> - | AV28: =Y28 -> 1 | AW28: =AC28 -> 1 | AX28: =AD28 -> - | AY28: =SUM(AQ28:AX28) -> 3 | AZ28: =IF(AY28=6,E24,"") | BA28: =IF(AZ28="",0,1) -> 0 | BQ28: =AP28+BA28 -> 0 | BR28: =IF(BQ28=0,"",E24) | BS28: =IF(BQ28=0,"",M28) | BT28: =IF(BR28="",0,1) -> 0
H29: 4 ≤ IP ≤ 7 | J29: %Arena / %Grava < 1 | K29: - | L29: %Arena < 15 | M29: Limo con mucha grava | N29: =IF(C90>50,1,0) -> 0 | O29: =IF(C92<50,1,0) -> 1 | P29: =IF(C94<4,1,0) -> 0 | Q29: =IF(T29=2,1,0) -> 0 | R29: =IF(C94>=4,1,0) -> 1 | S29: =IF(C94<=7,1,0) -> 0 | T29: =R29+S29 -> 1 | U29: - | V29: - | W29: - | X29: - | Y29: =IF(C85/C84<1,1,0) -> 0 | Z29: - | AA29: - | AB29: - | AC29: - | AD29: =IF(C85<15,1,0) -> 0 | AF29: =N29 -> 0 | AG29: =O29 -> 1 | AH29: =P29 -> 0 | AI29: - | AJ29: =U29 -> - | AK29: =Y29 -> 0 | AL29: =AC29 -> - | AM29: =AD29 -> 0 | AN29: =SUM(AF29:AM29) -> 1 | AO29: =IF(AN29=5,E24,"") | AP29: =IF(AO29="",0,1) -> 0 | AQ29: =N29 -> 0 | AR29: =O29 -> 1 | AS29: - | AT29: =Q29 -> 0 | AU29: =U29 -> - | AV29: =Y29 -> 0 | AW29: =AC29 -> - | AX29: =AD29 -> 0 | AY29: =SUM(AQ29:AX29) -> 1 | AZ29: =IF(AY29=6,E24,"") | BA29: =IF(AZ29="",0,1) -> 0 | BQ29: =AP29+BA29 -> 0 | BR29: =IF(BQ29=0,"",E24) | BS29: =IF(BQ29=0,"",M29) | BT29: =IF(BR29="",0,1) -> 0
J30: %Arena / %Grava < 1 | K30: - | L30: %Arena ≥ 15 | M30: Limo con mucha grava y con arena | N30: =IF(C90>50,1,0) -> 0 | O30: =IF(C92<50,1,0) -> 1 | P30: =IF(C94<4,1,0) -> 0 | Q30: =IF(T30=2,1,0) -> 0 | R30: =IF(C94>=4,1,0) -> 1 | S30: =IF(C94<=7,1,0) -> 0 | T30: =R30+S30 -> 1 | U30: - | V30: - | W30: - | X30: - | Y30: =IF(C85/C84<1,1,0) -> 0 | Z30: - | AA30: - | AB30: - | AC30: - | AD30: =IF(C85>=15,1,0) -> 1 | AF30: =N30 -> 0 | AG30: =O30 -> 1 | AH30: =P30 -> 0 | AI30: - | AJ30: =U30 -> - | AK30: =Y30 -> 0 | AL30: =AC30 -> - | AM30: =AD30 -> 1 | AN30: =SUM(AF30:AM30) -> 2 | AO30: =IF(AN30=5,E24,"") | AP30: =IF(AO30="",0,1) -> 0 | AQ30: =N30 -> 0 | AR30: =O30 -> 1 | AS30: - | AT30: =Q30 -> 0 | AU30: =U30 -> - | AV30: =Y30 -> 0 | AW30: =AC30 -> - | AX30: =AD30 -> 1 | AY30: =SUM(AQ30:AX30) -> 2 | AZ30: =IF(AY30=6,E24,"") | BA30: =IF(AZ30="",0,1) -> 0 | BQ30: =AP30+BA30 -> 0 | BR30: =IF(BQ30=0,"",E24) | BS30: =IF(BQ30=0,"",M30) | BT30: =IF(BR30="",0,1) -> 0
E31: CL | G31: IP > 7 | I31: Retenido Nº 200 < 15% | J31: - | K31: - | L31: - | M31: Arcilla delgada | N31: =IF(C90>50,1,0) -> 0 | O31: =IF(C92<50,1,0) -> 1 | P31: =IF(C94>7,1,0) -> 1 | Q31: =IF(T31=2,1,0) -> 0 | R31: =IF(C94>=4,1,0) -> 1 | S31: =IF(C94<=7,1,0) -> 0 | T31: =R31+S31 -> 1 | U31: =IF(C91<15,1,0) -> 0 | V31: - | W31: - | X31: - | Y31: - | Z31: - | AA31: - | AB31: - | AC31: - | AD31: - | AF31: =N31 -> 0 | AG31: =O31 -> 1 | AH31: =P31 -> 1 | AI31: - | AJ31: =U31 -> 0 | AK31: =Y31 -> - | AL31: =AC31 -> - | AM31: =AD31 -> - | AN31: =SUM(AF31:AM31) -> 2 | AO31: =IF(AN31=4,E31,"") | AP31: =IF(AO31="",0,1) -> 0 | AQ31: =N31 -> 0 | AR31: =O31 -> 1 | AS31: - | AT31: =Q31 -> 0 | AU31: =U31 -> 0 | AV31: =Y31 -> - | AW31: =AC31 -> - | AX31: =AD31 -> - | AY31: =SUM(AQ31:AX31) -> 1 | AZ31: =IF(AY31=4,E31,"") | BA31: =IF(AZ31="",0,1) -> 0 | BQ31: =AP31+BA31 -> 0 | BR31: =IF(BQ31=0,"",E31) | BS31: =IF(BQ31=0,"",M31) | BT31: =IF(BR31="",0,1) -> 0 | BU31: =SUM(BT31:BT37) -> 0 | BV31: =IF(BW31="",0,1) -> 0 | BW31: =IF(BU31=0,"",E31)
H32: Se les asigna doble simbolo | I32: Retenido Nº 200 15% - 29% | J32: %Arena / %Grava ≥ 1 | K32: - | L32: - | M32: Arcilla delgada con arena | N32: =IF(C90>50,1,0) -> 0 | O32: =IF(C92<50,1,0) -> 1 | P32: =IF(C94>7,1,0) -> 1 | Q32: =IF(T32=2,1,0) -> 0 | R32: =IF(C94>=4,1,0) -> 1 | S32: =IF(C94<=7,1,0) -> 0 | T32: =R32+S32 -> 1 | U32: =IF(X32=2,1,0) -> 0 | V32: =IF(C91>=15,1,0) -> 1 | W32: =IF(C91<=29,1,0) -> 0 | X32: =V32+W32 -> 1 | Y32: =IF((C85/C84)>=1,1,0) -> 1 | Z32: - | AA32: - | AB32: - | AC32: - | AD32: - | AF32: =N32 -> 0 | AG32: =O32 -> 1 | AH32: =P32 -> 1 | AI32: - | AJ32: =U32 -> 0 | AK32: =Y32 -> 1 | AL32: =AC32 -> - | AM32: =AD32 -> - | AN32: =SUM(AF32:AM32) -> 3 | AO32: =IF(AN32=5,E31,"") | AP32: =IF(AO32="",0,1) -> 0 | AQ32: =N32 -> 0 | AR32: =O32 -> 1 | AS32: - | AT32: =Q32 -> 0 | AU32: =U32 -> 0 | AV32: =Y32 -> 1 | AW32: =AC32 -> - | AX32: =AD32 -> - | AY32: =SUM(AQ32:AX32) -> 2 | AZ32: =IF(AY32=5,E31,"") | BA32: =IF(AZ32="",0,1) -> 0 | BQ32: =AP32+BA32 -> 0 | BR32: =IF(BQ32=0,"",E31) | BS32: =IF(BQ32=0,"",M32) | BT32: =IF(BR32="",0,1) -> 0
F33: Arcillas inorganicas de plasticidad baja a media, arcillas gravosas, arcillas | J33: %Arena / %Grava < 1 | K33: - | L33: - | M33: Arcilla delgada con grava | N33: =IF(C90>50,1,0) -> 0 | O33: =IF(C92<50,1,0) -> 1 | P33: =IF(C94>7,1,0) -> 1 | Q33: =IF(T33=2,1,0) -> 0 | R33: =IF(C94>=4,1,0) -> 1 | S33: =IF(C94<=7,1,0) -> 0 | T33: =R33+S33 -> 1 | U33: - | V33: - | W33: - | X33: - | Y33: =IF(C85/C84<1,1,0) -> 0 | Z33: - | AA33: - | AB33: - | AC33: - | AD33: - | AF33: =N33 -> 0 | AG33: =O33 -> 1 | AH33: =P33 -> 1 | AI33: - | AJ33: =U33 -> - | AK33: =Y33 -> 0 | AL33: =AC33 -> - | AM33: =AD33 -> - | AN33: =SUM(AF33:AM33) -> 2 | AO33: =IF(AN33=4,E31,"") | AP33: =IF(AO33="",0,1) -> 0 | AQ33: =N33 -> 0 | AR33: =O33 -> 1 | AS33: - | AT33: =Q33 -> 0 | AU33: =U33 -> - | AV33: =Y33 -> 0 | AW33: =AC33 -> - | AX33: =AD33 -> - | AY33: =SUM(AQ33:AX33) -> 1 | AZ33: =IF(AY33=5,E31,"") | BA33: =IF(AZ33="",0,1) -> 0 | BQ33: =AP33+BA33 -> 0 | BR33: =IF(BQ33=0,"",E31) | BS33: =IF(BQ33=0,"",M33) | BT33: =IF(BR33="",0,1) -> 0
I34: Retenido Nº 200 ≥ 30% | J34: %Arena / %Grava ≥ 1 | K34: %Grava < 15 | L34: - | M34: Arcilla delgada arenosa | N34: =IF(C90>50,1,0) -> 0 | O34: =IF(C92<50,1,0) -> 1 | P34: =IF(C94>7,1,0) -> 1 | Q34: =IF(T34=2,1,0) -> 0 | R34: =IF(C94>=4,1,0) -> 1 | S34: =IF(C94<=7,1,0) -> 0 | T34: =R34+S34 -> 1 | U34: =IF(C91>=30,1,0) -> 1 | V34: - | W34: - | X34: - | Y34: =IF((C85/C84)>=1,1,0) -> 1 | Z34: - | AA34: - | AB34: - | AC34: =IF(C84<15,1,0) -> 0 | AD34: - | AF34: =N34 -> 0 | AG34: =O34 -> 1 | AH34: =P34 -> 1 | AI34: - | AJ34: =U34 -> 1 | AK34: =Y34 -> 1 | AL34: =AC34 -> 0 | AM34: =AD34 -> - | AN34: =SUM(AF34:AM34) -> 4 | AO34: =IF(AN34=6,E31,"") | AP34: =IF(AO34="",0,1) -> 0 | AQ34: =N34 -> 0 | AR34: =O34 -> 1 | AS34: - | AT34: =Q34 -> 0 | AU34: =U34 -> 1 | AV34: =Y34 -> 1 | AW34: =AC34 -> 0 | AX34: =AD34 -> - | AY34: =SUM(AQ34:AX34) -> 3 | AZ34: =IF(AY34=6,E31,"") | BA34: =IF(AZ34="",0,1) -> 0 | BQ34: =AP34+BA34 -> 0 | BR34: =IF(BQ34=0,"",E31) | BS34: =IF(BQ34=0,"",M34) | BT34: =IF(BR34="",0,1) -> 0
F35: arenosas, arcillas limosas, arcillas magras | J35: %Arena / %Grava ≥ 1 | K35: %Grava ≥ 15 | L35: - | M35: Arcilla delgada arenosa con grava | N35: =IF(C90>50,1,0) -> 0 | O35: =IF(C92<50,1,0) -> 1 | P35: =IF(C94>7,1,0) -> 1 | Q35: =IF(T35=2,1,0) -> 0 | R35: =IF($C$94>=4,1,0) -> 1 | S35: =IF(C94<=7,1,0) -> 0 | T35: =R35+S35 -> 1 | U35: - | V35: - | W35: - | X35: - | Y35: =IF((C85/C84)>=1,1,0) -> 1 | Z35: - | AA35: - | AB35: - | AC35: =IF(C84>=15,1,0) -> 1 | AD35: - | AF35: =N35 -> 0 | AG35: =O35 -> 1 | AH35: =P35 -> 1 | AI35: - | AJ35: =U35 -> - | AK35: =Y35 -> 1 | AL35: =AC35 -> 1 | AM35: =AD35 -> - | AN35: =SUM(AF35:AM35) -> 4 | AO35: =IF(AN35=5,E31,"") | AP35: =IF(AO35="",0,1) -> 0 | AQ35: =N35 -> 0 | AR35: =O35 -> 1 | AS35: - | AT35: =Q35 -> 0 | AU35: =U35 -> - | AV35: =Y35 -> 1 | AW35: =AC35 -> 1 | AX35: =AD35 -> - | AY35: =SUM(AQ35:AX35) -> 3 | AZ35: =IF(AY35=6,E31,"") | BA35: =IF(AZ35="",0,1) -> 0 | BQ35: =AP35+BA35 -> 0 | BR35: =IF(BQ35=0,"",E31) | BS35: =IF(BQ35=0,"",M35) | BT35: =IF(BR35="",0,1) -> 0
J36: %Arena / %Grava < 1 | K36: - | L36: %Arena < 15 | M36: Arcilla delgada con mucha grava | N36: =IF(C90>50,1,0) -> 0 | O36: =IF(C92<50,1,0) -> 1 | P36: =IF(C94>7,1,0) -> 1 | Q36: =IF(T36=2,1,0) -> 0 | R36: =IF(C94>=4,1,0) -> 1 | S36: =IF(C94<=7,1,0) -> 0 | T36: =R36+S36 -> 1 | U36: - | V36: - | W36: - | X36: - | Y36: =IF(C85/C84<1,1,0) -> 0 | Z36: - | AA36: - | AB36: - | AC36: - | AD36: =IF(C85<15,1,0) -> 0 | AF36: =N36 -> 0 | AG36: =O36 -> 1 | AH36: =P36 -> 1 | AI36: - | AJ36: =U36 -> - | AK36: =Y36 -> 0 | AL36: =AC36 -> - | AM36: =AD36 -> 0 | AN36: =SUM(AF36:AM36) -> 2 | AO36: =IF(AN36=5,E31,"") | AP36: =IF(AO36="",0,1) -> 0 | AQ36: =N36 -> 0 | AR36: =O36 -> 1 | AS36: - | AT36: =Q36 -> 0 | AU36: =U36 -> - | AV36: =Y36 -> 0 | AW36: =AC36 -> - | AX36: =AD36 -> 0 | AY36: =SUM(AQ36:AX36) -> 1 | AZ36: =IF(AY36=6,E31,"") | BA36: =IF(AZ36="",0,1) -> 0 | BQ36: =AP36+BA36 -> 0 | BR36: =IF(BQ36=0,"",E31) | BS36: =IF(BQ36=0,"",M36) | BT36: =IF(BR36="",0,1) -> 0
D37: Limos y Arcillas | J37: %Arena / %Grava < 1 | K37: - | L37: %Arena ≥ 15 | M37: Arcilla delgada con mucha grava y con arena | N37: =IF(C90>50,1,0) -> 0 | O37: =IF(C92<50,1,0) -> 1 | P37: =IF(C94>7,1,0) -> 1 | Q37: =IF(T37=2,1,0) -> 0 | R37: =IF(C94>=4,1,0) -> 1 | S37: =IF(C94<=7,1,0) -> 0 | T37: =R37+S37 -> 1 | U37: - | V37: - | W37: - | X37: - | Y37: =IF(C85/C84<1,1,0) -> 0 | Z37: - | AA37: - | AB37: - | AC37: - | AD37: =IF(C85>=15,1,0) -> 1 | AF37: =N37 -> 0 | AG37: =O37 -> 1 | AH37: =P37 -> 1 | AI37: - | AJ37: =U37 -> - | AK37: =Y37 -> 0 | AL37: =AC37 -> - | AM37: =AD37 -> 1 | AN37: =SUM(AF37:AM37) -> 3 | AO37: =IF(AN37=5,E31,"") | AP37: =IF(AO37="",0,1) -> 0 | AQ37: =N37 -> 0 | AR37: =O37 -> 1 | AS37: - | AT37: =Q37 -> 0 | AU37: =U37 -> - | AV37: =Y37 -> 0 | AW37: =AC37 -> - | AX37: =AD37 -> 1 | AY37: =SUM(AQ37:AX37) -> 2 | AZ37: =IF(AY37=6,E31,"") | BA37: =IF(AZ37="",0,1) -> 0 | BQ37: =AP37+BA37 -> 0 | BR37: =IF(BQ37=0,"",E31) | BS37: =IF(BQ37=0,"",M37) | BT37: =IF(BR37="",0,1) -> 0
E38: OL | F38: Limos organicos, arcillas limosas organicas de baja plasticidad | H38: IP ≥ 4 | I38: Retenido Nº 200 < 15% | J38: - | K38: - | L38: - | M38: Arcilla organica | N38: =IF(C90>50,1,0) -> 0 | O38: =IF(C92<50,1,0) -> 1 | P38: =IF((C93/C92)<0.75,1,0) -> 0 | Q38: =IF(C94>=4,1,0) -> 1 | R38: - | S38: - | T38: - | U38: =IF(C91<15,1,0) -> 0 | V38: - | W38: - | X38: - | Y38: - | Z38: - | AA38: - | AB38: - | AC38: - | AD38: - | AF38: =N38 -> 0 | AG38: =O38 -> 1 | AH38: =P38 -> 0 | AI38: =Q38 -> 1 | AJ38: =U38 -> 0 | AK38: =Y38 -> - | AL38: =AC38 -> - | AM38: =AD38 -> - | AN38: =SUM(AF38:AM38) -> 2 | AO38: =IF(AN38=5,E38,"") | AP38: =IF(AO38="",0,1) -> 0 | BQ38: =AP38 -> 0 | BR38: =IF(BQ38=0,"",E38) | BS38: =IF(BQ38=0,"",M38) | BT38: =IF(BR38="",0,1) -> 0 | BU38: =SUM(BT38:BT51) -> 0 | BV38: =IF(BW38="",0,1) -> 0 | BW38: =IF(BU38=0,"",E38)
D39: (Limite Liquido < 50) | I39: Retenido Nº 200 15% - 29% | J39: %Arena / %Grava ≥ 1 | K39: - | L39: - | M39: Arcilla organica con arena | N39: =IF(C90>50,1,0) -> 0 | O39: =IF(C92<50,1,0) -> 1 | P39: =IF((C93/C92)<0.75,1,0) -> 0 | Q39: =IF(C94>=4,1,0) -> 1 | R39: - | S39: - | T39: - | U39: =IF(X39=2,1,0) -> 0 | V39: =IF(C91>=15,1,0) -> 1 | W39: =IF(C91<=29,1,0) -> 0 | X39: =V39+W39 -> 1 | Y39: =IF((C85/C84)>=1,1,0) -> 1 | Z39: - | AA39: - | AB39: - | AC39: - | AD39: - | AF39: =N39 -> 0 | AG39: =O39 -> 1 | AH39: =P39 -> 0 | AI39: =Q39 -> 1 | AJ39: =U39 -> 0 | AK39: =Y39 -> 1 | AL39: =AC39 -> - | AM39: =AD39 -> - | AN39: =SUM(AF39:AM39) -> 3 | AO39: =IF(AN39=6,E38,"") | AP39: =IF(AO39="",0,1) -> 0 | BQ39: =AP39 -> 0 | BR39: =IF(BQ39=0,"",E38) | BS39: =IF(BQ39=0,"",M39) | BT39: =IF(BR39="",0,1) -> 0
J40: %Arena / %Grava < 1 | K40: - | L40: - | M40: Arcilla organica con grava | N40: =IF(C90>50,1,0) -> 0 | O40: =IF(C92<50,1,0) -> 1 | P40: =IF((C93/C92)<0.75,1,0) -> 0 | Q40: =IF(C94>=4,1,0) -> 1 | R40: - | S40: - | T40: - | U40: - | V40: - | W40: - | X40: - | Y40: =IF(C85/C84<1,1,0) -> 0 | Z40: - | AA40: - | AB40: - | AC40: - | AD40: - | AF40: =N40 -> 0 | AG40: =O40 -> 1 | AH40: =P40 -> 0 | AI40: =Q40 -> 1 | AJ40: =U40 -> - | AK40: =Y40 -> 0 | AL40: =AC40 -> - | AM40: =AD40 -> - | AN40: =SUM(AF40:AM40) -> 2 | AO40: =IF(AN40=5,E38,"") | AP40: =IF(AO40="",0,1) -> 0 | BQ40: =AP40 -> 0 | BR40: =IF(BQ40=0,"",E38) | BS40: =IF(BQ40=0,"",M40) | BT40: =IF(BR40="",0,1) -> 0
I41: Retenido Nº 200 ≥ 30% | J41: %Arena / %Grava ≥ 1 | K41: %Grava < 15 | L41: - | M41: Arcilla organica arenosa | N41: =IF(C90>50,1,0) -> 0 | O41: =IF(C92<50,1,0) -> 1 | P41: =IF((C93/C92)<0.75,1,0) -> 0 | Q41: =IF(C94>=4,1,0) -> 1 | R41: - | S41: - | T41: - | U41: =IF(C91>=30,1,0) -> 1 | V41: - | W41: - | X41: - | Y41: =IF((C85/C84)>=1,1,0) -> 1 | Z41: - | AA41: - | AB41: - | AC41: =IF(C84<15,1,0) -> 0 | AD41: - | AF41: =N41 -> 0 | AG41: =O41 -> 1 | AH41: =P41 -> 0 | AI41: =Q41 -> 1 | AJ41: =U41 -> 1 | AK41: =Y41 -> 1 | AL41: =AC41 -> 0 | AM41: =AD41 -> - | AN41: =SUM(AF41:AM41) -> 4 | AO41: =IF(AN41=7,E38,"") | AP41: =IF(AO41="",0,1) -> 0 | BQ41: =AP41 -> 0 | BR41: =IF(BQ41=0,"",E38) | BS41: =IF(BQ41=0,"",M41) | BT41: =IF(BR41="",0,1) -> 0
...

Sheet SUCS N° 03
B1: SISTEMA UNIFICADO DE CLASIFICACION
B3: N 200= | C3: =ROUND('D6913'!F46,2) -> 17.33 | D3: Cu = | E3: =+'D6913'!J144 -> 192.23469 | K3: L.L. | L3: =+IF(N_10="NP",0,N_10) -> 31
B4: N 4= | C4: =IF('D6913'!F34="",0,ROUND('D6913'!F34,2)) -> 62.48 | D4: Cc = | E4: =+'D6913'!L144 -> 2.7454764 | F4: CLASIFICACION SUCS | G4: =IF(N_200<>0,R9,"") -> SC | K4: I.P. | L4: =+IF(C6="NP",0,C6) -> 11.61521
B5: L.L.= | C5: =+IF('D4318'!F59="NP",0,'D4318'!F59) -> 31 | G5: =P9&P10&P11&P12&P13&P14&P15&P16&P17&P18&P19&P20&P21&P22&P23 -> - Arena Arcillosa con grava | K5: CU | L5: =IF(OR(E3="",E3=""),0,E3) -> 192.23469
B6: I.P.= | C6: =+IF('D4318'!F61="NP",0,'D4318'!F61) -> 11.61521 | K6: CC | L6: =IF(OR(E4="",E4=""),0,E4) -> 2.7454764
B8: DIVISIONES MAYORES | E8: SIMBOLO DE GRUPO | F8: NOMBRES TIPICOS | G8: CRITERIOS DE CLASIFICACION PARA SUELOS GRANULARES | L8: CLASIF | M8: SIMBOLOS DOBLES | O8: SIMBOLOS TRIPLES | P8: NOMBRE DEL GRUPO | Q8: CLASIFICACION | R8: SIMBOLO
