Workbook
Name AAA: #REF!
Name AAA: #REF!
Name AAA: #REF!
Name AAAAA: #REF!
Name AAAAA: #REF!
Name AAAAA: #REF!
Name CC: #REF!
Name cddd: #REF!
Name cddd: #REF!
Name cddd: #REF!
Name chatas: #REF!
Name chatas: #REF!
Name chatas: #REF!
Name CM: #REF!
Name CM: #REF!
Name CM: #REF!
Name COMPACT: #REF!
Name COMPACT: #REF!
Name COMPACT: #REF!
Name CU: #REF!
Name Dato: #REF!
Name Dato: #REF!
Name Dato: #REF!
Name datos: #REF!
Name datos: #REF!
Name datos: #REF!
Name Datoss: #REF!
Name Datoss: #REF!
Name Datoss: #REF!
Name diasem: #REF!
Name diasem: #REF!
Name diasem: #REF!
Name Divisiones: #REF!
Name Divisiones: #REF!
Name Divisiones: #REF!
Name E: #REF!
Name E: #REF!
Name E: #REF!
Name ED: #REF!
Name ED: #REF!
Name ED: #REF!
Name ELEMENTOS: #REF!
Name escala: #REF!
Name escala: #REF!
Name escala: #REF!
Name FF: #REF!
Name FF: #REF!
Name FF: #REF!
Name GAUS: #REF!
Name GAUS: #REF!
Name GAUS: #REF!
Name INDICE: #REF!
Name INDICE: #REF!
Name INDICE: #REF!
Name IP: #REF!
Name laditos: #REF!
Name laditos: #REF!
Name laditos: #REF!
Name lados: #REF!
Name lados: #REF!

Sheet QC-C-019 (Cono Arena)
E1: SOCIEDAD MINERA CERRO VERDE S.A.A. | K1: ID del Documento: | M1: QC-C-019
E2: ASEGURAMIENTO DE CALIDAD | K2: Revisión: | M2: 2
E3: ENSAYO DE DENSIDAD DE CAMPO CONO DE ARENA ASTM D1556 | K3: Fecha: | M3: 45659
K4: Especialidad: | M4: Civil
B5: PROYECTO: | C5: PROYECTO: | E5: TL SADDLE DAM 1, 2, 4, 5. | J5: N° SISTEMA: | L5: CAP22027-C2-4000-0505
B6: PRODUCTO ENTREGABLE: | C6: PRODUCTO ENTREGABLE: | E6: RELLENO DE MATERIAL DEL NÚCLEO | J6: CÓDIGO FACILIDAD: | L6: CAP22027-C2-4000-0505-02/02
B7: CONTRATISTA: | C7: CONTRATISTA: | E7: SGS DEL PERÚ S.A.C. | J7: FECHA: | L7: =+L13 -> 46120
B8: ESPECIFICACION: | C8: ESPECIFICACION: | E8: CAP220271490000-C2-4000-10-CS-112_0 | J8: N° REGISTRO: | L8: C-Z3-CA12-
B9: PLANOS: | C9: PLANOS: | J9: PÁGINA: | L9: 1 DE | M9: 1
B11: ENSAYO DE CONO DE ARENA 12" TOMANDO COMO REFERENCIA LA NORMA ASTM D1556 | P11: Profundidad | R11: 150 | S11: 150 | T11: 150
B12: Datos de la muestra | P12: Rodillo Pata de Cabra 825h (33 Tn) | R12: 14 | S12: 14 | T12: 14
B13: UBICACIÓN DE LA MUESTRA: | E13: SD5 - COT - Capa Nº 45 (12 Ciclos) | K13: FECHA DE ENSAYO: | L13: 46120
B14: MATERIAL: | E14: Zona 3 - Núcleo | K14: REGISTRO DE ENSAYO: | L14: SGS-CA12-Z3-045 | N14: 4
B15: TURNO: | E15: Día | K15: ENSAYADO POR: | L15: Percy Mollo
B16: Número de Prueba | H16: (Nº) | I16: 49
B17: Número de Cono | H17: (Nº) | I17: CA12" - 01
B18: Profundidad de la Prueba | H18: (m) | I18: 0.2
B19: Número de Ciclos Compactados | H19: (Nº) | I19: 12
B20: Lado | H20: - | I20: Inboard
B21: Espesor de Capa (cm) | H21: (cm) | I21: 30
B22: Número de Capa | H22: (Nº) | I22: 45
B23: Coordenadas | H23: N: | I23: 8166207.5 | N23: 1
H24: E: | I24: 222746.07
H25: Cota: | I25: 2674.315 | O25: 0.9773
B26: VOLUMEN DEL HOYO | O26: 0.9545
B27: 01 | C27: Peso de la arena + frasco | H27: (g) | I27: 51500 | O27: =ROUND(+I27*$O$25,0) -> 50331 | P27: =ROUND(+J27*$O$25,0) -> 0 | Q27: =ROUND(+K27*$O$25,0) -> 0 | R27: =ROUND(+L27*$O$25,0) -> 0 | S27: =ROUND(+M27*$O$25,0) -> 0
B28: =+B27+1 -> 2 | C28: Peso de la arena remanente + frasco | H28: (g) | I28: 26500 | O28: =ROUND(+I28*$O$26,0) -> 25294 | P28: =ROUND(+J28*$O$26,0) -> 0 | Q28: =ROUND(+K28*$O$26,0) -> 0 | R28: =ROUND(+L28*$O$26,0) -> 0 | S28: =ROUND(+M28*$O$26,0) -> 0
B29: =+B28+1 -> 3 | C29: Peso de la arena empleada (01-02) | H29: (g) | I29: =I27-I28 -> 25000 | M29: 6016
B30: =+B29+1 -> 4 | C30: Peso de la arena en el cono y plato | H30: (g) | I30: 7827
B31: =+B30+1 -> 5 | C31: Peso de la arena en el hoyo (03-04) | H31: (g) | I31: =I29-I30 -> 17173 | M31: 4291
B32: =+B31+1 -> 6 | C32: Densidad de la arena | H32: (g/cm3) | I32: 1.348
B33: =+B32+1 -> 7 | C33: Volumen del hoyo (05/06) | H33: (cm3) | I33: =ROUND(I31/I32,0) -> 12740 | M33: 2899
B34: DENSIDAD SECA EN SITU DE LA MUESTRA TOTAL | O34: 0.99
B35: =+B33+1 -> 8 | C35: Peso de la muestra húmeda extraída del hoyo + recipiente | H35: (g) | I35: 29800 | O35: =ROUND(+I35*$O$34,0) -> 29502 | P35: =ROUND(+J35*$O$34,0) -> 0 | Q35: =ROUND(+K35*$O$34,0) -> 0 | R35: =ROUND(+L35*$O$34,0) -> 0 | S35: =ROUND(+M35*$O$34,0) -> 0
B36: =+B35+1 -> 9 | C36: Peso del recipiente | H36: (g) | I36: 10
B37: =+B36+1 -> 10 | C37: Peso de la muestra húmeda extraída del hoyo (08-09) | H37: (g) | I37: =I35-I36 -> 29790 | M37: =M35-M36 -> 0
B38: =+B37+1 -> 11 | C38: Densidad húmeda in situ (10/07) | H38: (g/cm3) | I38: =ROUND(I37/I33,3) -> 2.338 | M38: =ROUND(M37/M33,3) -> 0
B39: =+B38+1 -> 12 | C39: Densidad seca in situ 11/(1+(19/100)) | H39: (g/cm3) | I39: =ROUND(I38/(1+(I47/100)),3) -> 2.127 | M39: =ROUND(M38/(1+(M47/100)),3) -> #DIV/0!
B40: CONTENIDO DE HUMEDAD DE LA FRACCIÓN FINA (ASTM D2216)
B41: =+B39+1 -> 13 | C41: Peso de la muestra húmeda + Tara | H41: (g) | I41: 2540
...

Sheet Cono Asumido
E1: SOCIEDAD MINERA CERRO VERDE S.A.A. | K1: ID del Documento: | M1: QC-C-019
E2: ASEGURAMIENTO DE CALIDAD | K2: Revisión: | M2: 2
E3: ENSAYO DE DENSIDAD DE CAMPO CONO DE ARENA ASTM D1556 | K3: Fecha: | M3: 45659
K4: Especialidad: | M4: Civil
B5: PROYECTO: | C5: PROYECTO: | E5: TL SADDLE DAM 1, 2, 4, 5. | J5: N° SISTEMA: | L5: CAP22027-C2-4000-0505
B6: PRODUCTO ENTREGABLE: | C6: PRODUCTO ENTREGABLE: | E6: RELLENO DE MATERIAL DEL NÚCLEO | J6: CÓDIGO FACILIDAD: | L6: CAP22027-C2-4000-0505-02/01
B7: CONTRATISTA: | C7: CONTRATISTA: | E7: OPEMIP | J7: FECHA: | L7: =+L13 -> 46120
B8: ESPECIFICACION: | C8: ESPECIFICACION: | E8: CAP220271490000-C2-4000-10-CS-112_0 | J8: N° REGISTRO:
B9: PLANOS: | C9: PLANOS: | J9: PÁGINA: | L9: DE
B11: ENSAYO DE CONO DE ARENA (ASTM D1556) | P11: Profundidad | R11: 150 | S11: 150
B12: Datos de la muestra | P12: Rodillo Pata de Cabra 825h (33 Tn) | R12: 14 | S12: 14
B13: UBICACIÓN DE LA MUESTRA: | E13: ='QC-C-019 (Cono Arena)'!E13 -> SD5 - COT - Capa Nº 45 (12 Ciclos) | K13: FECHA DE ENSAYO: | L13: ='QC-C-019 (Cono Arena)'!L13 -> 46120 | P13: Rodillo Pata de Cabra 825h (33 Tn) | R13: 5 | S13: 5
B14: MATERIAL: | E14: ='QC-C-019 (Cono Arena)'!E14 -> Zona 3 - Núcleo | K14: REGISTRO DE ENSAYO: | L14: ='QC-C-019 (Cono Arena)'!L14 -> SGS-CA12-Z3-045 | N14: 34 | P14: Rodillo Pata de Cabra Bomag (13 Tn) | R14: 0 | S14: 0
B15: TURNO: | E15: ='QC-C-019 (Cono Arena)'!E15 -> Día | K15: ENSAYADO POR: | L15: ='QC-C-019 (Cono Arena)'!L15 -> Percy Mollo | P15: Progresiva | R15: 1235.85 | S15: 1235.85
B16: Número de Prueba | I16: ='QC-C-019 (Cono Arena)'!I16 -> 49 | J16: ='QC-C-019 (Cono Arena)'!J16 -> 0
B17: Lado | I17: ='QC-C-019 (Cono Arena)'!I20 -> Inboard | J17: ='QC-C-019 (Cono Arena)'!J20 -> 0
B18: Espesor de Capa (cm) | I18: ='QC-C-019 (Cono Arena)'!I21 -> 30 | J18: ='QC-C-019 (Cono Arena)'!J21 -> 0
B19: Número de Capa | I19: ='QC-C-019 (Cono Arena)'!I22 -> 45 | J19: ='QC-C-019 (Cono Arena)'!J22 -> 0
B20: Coordenadas | H20: N: | I20: ='QC-C-019 (Cono Arena)'!I23 -> 8166207.5 | J20: ='QC-C-019 (Cono Arena)'!J23 -> 0 | N20: 1
H21: E: | I21: ='QC-C-019 (Cono Arena)'!I24 -> 222746.07 | J21: ='QC-C-019 (Cono Arena)'!J24 -> 0
H22: Cota: | I22: ='QC-C-019 (Cono Arena)'!I25 -> 2674.315 | J22: ='QC-C-019 (Cono Arena)'!J25 -> 0 | O22: 0.9773
B23: VOLUMEN DEL HOYO | O23: 0.9545
B24: 01 | C24: Peso de la arena + frasco | H24: (g) | I24: ='QC-C-019 (Cono Arena)'!I27 -> 51500 | J24: ='QC-C-019 (Cono Arena)'!J27 -> 0 | O24: =ROUND(+I24*$O$22,0) -> 50331 | P24: =ROUND(+J24*$O$22,0) -> 0 | Q24: =ROUND(+K24*$O$22,0) -> 0 | R24: =ROUND(+L24*$O$22,0) -> 0 | S24: =ROUND(+M24*$O$22,0) -> 0
B25: =+B24+1 -> 2 | C25: Peso de la arena remanente + frasco | H25: (g) | I25: ='QC-C-019 (Cono Arena)'!I28 -> 26500 | J25: ='QC-C-019 (Cono Arena)'!J28 -> 0 | O25: =ROUND(+I25*$O$23,0) -> 25294 | P25: =ROUND(+J25*$O$23,0) -> 0 | Q25: =ROUND(+K25*$O$23,0) -> 0 | R25: =ROUND(+L25*$O$23,0) -> 0 | S25: =ROUND(+M25*$O$23,0) -> 0
B26: =+B25+1 -> 3 | C26: Peso de la arena empleada (01-02) | H26: (g) | I26: =I24-I25 -> 25000 | J26: =J24-J25 -> 0 | M26: 6016
B27: =+B26+1 -> 4 | C27: Peso de la arena en el cono y plato | H27: (g) | I27: ='QC-C-019 (Cono Arena)'!I30 -> 7827 | J27: ='QC-C-019 (Cono Arena)'!J30 -> 0
B28: =+B27+1 -> 5 | C28: Peso de la arena en el hoyo (03-04) | H28: (g) | I28: =I26-I27 -> 17173 | J28: =J26-J27 -> 0 | M28: 4291
B29: =+B28+1 -> 6 | C29: Densidad de la arena | H29: (g/cm3) | I29: ='QC-C-019 (Cono Arena)'!I32 -> 1.348 | J29: ='QC-C-019 (Cono Arena)'!J32 -> 0
B30: =+B29+1 -> 7 | C30: Volumen del hoyo (05/06) | H30: (cm3) | I30: =ROUND(I28/I29,0) -> 12740 | J30: =ROUND(J28/J29,0) -> #DIV/0! | M30: 2899
B31: DENSIDAD SECA EN SITU DE LA MUESTRA TOTAL | O31: 0.99
B32: =+B30+1 -> 8 | C32: Peso de la muestra húmeda extraída del hoyo + recipiente | H32: (g) | I32: ='QC-C-019 (Cono Arena)'!I35 -> 29800 | J32: ='QC-C-019 (Cono Arena)'!J35 -> 0 | O32: =ROUND(+I32*$O$31,0) -> 29502 | P32: =ROUND(+J32*$O$31,0) -> 0 | Q32: =ROUND(+K32*$O$31,0) -> 0 | R32: =ROUND(+L32*$O$31,0) -> 0 | S32: =ROUND(+M32*$O$31,0) -> 0
B33: =+B32+1 -> 9 | C33: Peso del recipiente | H33: (g) | I33: ='QC-C-019 (Cono Arena)'!I36 -> 10 | J33: ='QC-C-019 (Cono Arena)'!J36 -> 0
B34: =+B33+1 -> 10 | C34: Peso de la muestra húmeda extraída del hoyo (08-09) | H34: (g) | I34: =I32-I33 -> 29790 | J34: =J32-J33 -> 0 | M34: =M32-M33 -> 0
B35: =+B34+1 -> 11 | C35: Densidad húmeda in situ (10/07) | H35: (g/cm3) | I35: =ROUND(I34/I30,3) -> 2.338 | J35: =ROUND(J34/J30,3) -> #DIV/0! | M35: =ROUND(M34/M30,3) -> 0
B36: =+B35+1 -> 12 | C36: Densidad seca in situ 11/(1+(19/100)) | H36: (g/cm3) | I36: =ROUND(I35/(1+(I44/100)),3) -> 2.937 | J36: =ROUND(J35/(1+(J44/100)),3) -> #DIV/0! | M36: =ROUND(M35/(1+(M44/100)),3) -> #DIV/0!
B37: CONTENIDO DE HUMEDAD DE LA FRACCIÓN FINA (ASTM D2216)
B38: =+B36+1 -> 13 | C38: Peso de la muestra húmeda + Tara | H38: (g) | I38: ='QC-C-019 (Cono Arena)'!I41 -> 2540 | J38: ='QC-C-019 (Cono Arena)'!J41 -> 0
B39: =+B38+1 -> 14 | C39: Peso de la muestra seca + Tara | H39: (g) | I39: 3050 | J39: 1835
B40: =+B39+1 -> 15 | C40: Peso del agua (13-14) | H40: (g) | I40: =+I38-I39 -> -510 | J40: =+J38-J39 -> -1835 | M40: =+M38-M39 -> 0
B41: =+B40+1 -> 16 | C41: Peso de la Tara | H41: (g) | I41: ='QC-C-019 (Cono Arena)'!I44 -> 1058.4 | J41: ='QC-C-019 (Cono Arena)'!J44 -> 0
...
