Workbook
Name Fecha_turno: DN!$D$5:$D$516

Sheet DN
B1: Control de Calidad | E1: DENSIDAD DE CAMPO - METODO NUCLEAR | K1: CV-GC-QC-FORDN-003
B2: Depósito de Relaves Enlozada | K2: Ver. | L2: 00 | O2: Equipos de compactación y su combinación | T2: Bandeja | U2: Tara
E3: ASTM D6938 | K3: Fecha | L3: 46091 | O3: B13T(*) | P3: 6 | Q3: 3 | T3: 1 | U3: 335.4
D4: N° ensayos | E4: 4 | G4: 261345 | O4: B13T | P4: 4 | Q4: 2 | T4: 2 | U4: 335.9
A5: Proyecto | C5: : Tailings Storage Facility | F5: Reporte Nº | H5: : | I5: =CONCATENATE("CV-DRE-QC-RDN-",TEXT(I9,"yy"),TEXT(MONTH(I9),"0#"),TEXT(DAY(I9),"0#"),"-",L9) -> CV-DRE-QC-RDN-260319-A | O5: D6R+B6T | P5: 8 | Q5: 4 | T5: 3 | U5: 335.7
A6: Propietario | C6: : Sociedad Minera Cerro Verde | F6: Ensayo | H6: : | I6: Compactación de campo | O6: B3.3T | P6: 12 | Q6: 6 | T6: 4 | U6: 336.4
A7: Gerencia | C7: : Relaves y Aguas | F7: Tipo de material | H7: : | I7: Arena de relaves | O7: B7T | P7: 6 | Q7: 3 | T7: 5 | U7: 336.2
A8: Área | C8: : Operaciones Relaves C1 | F8: Ubicación general | H8: : | I8: Depósito de Relaves Enlozada | O8: Plancha 1T/Exc. | P8: 15 | Q8: 15 | T8: 6 | U8: 336.4
A9: Guardia QC N° | C9: : 4 | D9: Supervisor: | E9: GM | F9: Fecha | H9: : | I9: 46100 | K9: Turno : | L9: A | O9: Vibro apisonadora | P9: 16 | Q9: 8 | T9: 7 | U9: 337.3
A10: DATOS GENERALES | T10: 8 | U10: 345.4
A11: Código de ensayo | E11: =IF($E$4>=1,CONCATENATE("DN-",$G$4),"") -> DN-261345 | G11: =IF($E$4>=2,CONCATENATE("DN-",$G$4+1),"") -> DN-261346 | I11: =IF($E$4>=3,CONCATENATE("DN-",$G$4+2),"") -> DN-261347 | K11: =IF($E$4>=4,CONCATENATE("DN-",$G$4+3),"") -> DN-261348 | T11: 9 | U11: 345.8
A12: Cancha - Zona | E12: =+topo!G6 -> 4C-H | G12: =topo!G7 -> 4C-H | I12: =topo!G8 -> 4C-H | K12: =topo!G9 -> 4C-H | T12: 10 | U12: 347.4
A13: Spool (Sp) - Pórtico (P) | E13: =topo!H6 -> Sp 67 | G13: =topo!H7 -> Sp 64 | I13: =topo!H8 -> Sp 62 | K13: =topo!H9 -> Sp 61 | T13: 11 | U13: 350.9
A14: Progresiva de presa (E-O) | E14: =topo!C6 -> 2151.91 | G14: =topo!C7 -> 2075.79 | I14: =topo!C8 -> 1989.7 | K14: =topo!C9 -> 1966.84 | T14: 12 | U14: 347.7
A15: Distancia a eje de presa (aguas abajo) (S-N) | E15: =topo!D6 -> -171.88 | G15: =topo!D7 -> -133.86 | I15: =topo!D8 -> -146.98 | K15: =topo!D9 -> -57.09 | T15: 13 | U15: 391.1
A16: Cota de elevación (msnm) | E16: =topo!E6 -> 2630.71 | G16: =topo!E7 -> 2622.68 | I16: =topo!E8 -> 2631.82 | K16: =topo!E9 -> 2610.18 | T16: 14 | U16: 391.2
A17: Equipo utilizado | E17: D6R+B6T | G17: D6R+B6T | I17: D6R+B6T | K17: D6R+B6T | T17: 15 | U17: 392.6
A18: Número de pasadas | E18: =IF(E11="","",VLOOKUP(E17,$O$3:$Q$9,2,0)) -> 8 | G18: =IF(G11="","",VLOOKUP(G17,$O$3:$Q$9,2,0)) -> 8 | I18: =IF(I11="","",VLOOKUP(I17,$O$3:$Q$9,2,0)) -> 8 | K18: =IF(K11="","",VLOOKUP(K17,$O$3:$Q$9,2,0)) -> 8 | T18: 16 | U18: 392.9
A19: Número total de Ciclos | E19: =IF(E11="","",VLOOKUP(E17,$O$3:$Q$9,3,0)) -> 4 | G19: =IF(G11="","",VLOOKUP(G17,$O$3:$Q$9,3,0)) -> 4 | I19: =IF(I11="","",VLOOKUP(I17,$O$3:$Q$9,3,0)) -> 4 | K19: =IF(K11="","",VLOOKUP(K17,$O$3:$Q$9,3,0)) -> 4 | T19: 17 | U19: 394.2
A20: Profundidad de fuente (m) | G20: =IF(G11="","",$E$20) -> 0 | I20: =IF(I11="","",$E$20) -> 0 | K20: =IF(K11="","",$E$20) -> 0 | T20: 18 | U20: 394.3
A21: Número de densímetro | E21: 88653 | G21: =IF(G11="","",$E$21) -> 88653 | I21: =IF(I11="","",$E$21) -> 88653 | K21: =IF(K11="","",$E$21) -> 88653 | T21: 19 | U21: 395.2
A22: Valor de corrección para humedad, (K) | E22: =+LOOKUP(E21,L78:M80) -> 55.72 | G22: =IF(G11="","",$E$22) -> 55.72 | I22: =IF(I11="","",$E$22) -> 55.72 | K22: =IF(K11="","",$E$22) -> 55.72 | T22: 20 | U22: 395.4
A23: DENSIDAD Y CONTENIDO DE HUMEDAD CON DENSÍMETRO NUCLEAR (ASTM D6938) | T23: 21 | U23: 395.9
E24: Val. Dens. | F24: Val. Corr. | G24: Val. Dens. | H24: Val. Corr. | I24: Val. Dens. | J24: Val. Corr. | K24: Val. Dens. | L24: Val. Corr. | T24: 22 | U24: 395.5
A25: Conteo estándar de densidad | E25: 2329 | F25: 0.7 | G25: =IF(G11="","",$E$25) -> 2329 | H25: =IF(G11="","",$F$25) -> 0.7 | I25: =IF(I11="","",$E$25) -> 2329 | J25: =IF(I11="","",$F$25) -> 0.7 | K25: =IF(K11="","",$E$25) -> 2329 | L25: =IF(K11="","",$F$25) -> 0.7 | O25: Técnicos | T25: 23 | U25: 396.5
A26: Conteo estándar de humedad | E26: 698 | F26: 0.8 | G26: =IF(G11="","",$E$26) -> 698 | H26: =IF(G11="","",$F$26) -> 0.8 | I26: =IF(I11="","",$E$26) -> 698 | J26: =IF(I11="","",$F$26) -> 0.8 | K26: =IF(K11="","",$E$26) -> 698 | L26: =IF(K11="","",$F$26) -> 0.8 | O26: Hebert Asqui Vargas | Q26: =CHOOSE(LEN($O26) - LEN(SUBSTITUTE($O26," ","")) + 1, LEFT($O26), LEFT($O26, 1) & MID($O26, FIND(" ", $O26) + 1, 1), LEFT($O26, 1) & MID($O26, FIND(" ", $O26) + 1, 1) & MID($O26, FIND(" ", $O26, FIND(" ", $O26) + 1) + 1, 1)) -> HAV | T26: 24 | U26: 397.2
A27: Operador | E27: GGB | G27: =IF(G11="","",$E$27) -> GGB | I27: =IF(I11="","",$E$27) -> GGB | K27: =IF(K11="","",$E$27) -> GGB | O27: Felix Tarqui Mendoza | Q27: =CHOOSE(LEN($O27) - LEN(SUBSTITUTE($O27," ","")) + 1, LEFT($O27), LEFT($O27, 1) & MID($O27, FIND(" ", $O27) + 1, 1), LEFT($O27, 1) & MID($O27, FIND(" ", $O27) + 1, 1) & MID($O27, FIND(" ", $O27, FIND(" ", $O27) + 1) + 1, 1)) -> FTM
A28: Conteo de densidad (DC) | E28: 521 | G28: 538 | I28: 447 | K28: 564 | O28: Edwin Chullo Cahuana | Q28: =CHOOSE(LEN($O28) - LEN(SUBSTITUTE($O28," ","")) + 1, LEFT($O28), LEFT($O28, 1) & MID($O28, FIND(" ", $O28) + 1, 1), LEFT($O28, 1) & MID($O28, FIND(" ", $O28) + 1, 1) & MID($O28, FIND(" ", $O28, FIND(" ", $O28) + 1) + 1, 1)) -> ECC | T28: Fecha de toma de datos
A29: Conteo de humedad (MC) | E29: 94 | G29: 91 | I29: 119 | K29: 78 | O29: Gerson Gallegos Belisario | Q29: =CHOOSE(LEN($O29) - LEN(SUBSTITUTE($O29," ","")) + 1, LEFT($O29), LEFT($O29, 1) & MID($O29, FIND(" ", $O29) + 1, 1), LEFT($O29, 1) & MID($O29, FIND(" ", $O29) + 1, 1) & MID($O29, FIND(" ", $O29, FIND(" ", $O29) + 1) + 1, 1)) -> GGB | U29: 23/1/2026
A30: Densidad suelo húmedo (g/cm3) | E30: 1.92 | G30: 1.905 | I30: 2.01 | K30: 1.883 | O30: Juan Herrera Juárez | Q30: =CHOOSE(LEN($O30) - LEN(SUBSTITUTE($O30," ","")) + 1, LEFT($O30), LEFT($O30, 1) & MID($O30, FIND(" ", $O30) + 1, 1), LEFT($O30, 1) & MID($O30, FIND(" ", $O30) + 1, 1) & MID($O30, FIND(" ", $O30, FIND(" ", $O30) + 1) + 1, 1)) -> JHJ
A31: Densidad suelo seco (g/cm3) | E31: 1.722 | F31: =IF(F33="",0,(E30/(1+F33))) -> 1.6976127 | G31: 1.711 | H31: =IF(H33="",0,(G30/(1+H33))) -> 1.7039356 | I31: 1.761 | J31: =IF(J33="",0,(I30/(1+J33))) -> 1.7238422 | K31: 1.707 | L31: =IF(L33="",0,(K30/(1+L33))) -> 1.7212066 | O31: Pablo Hinojosa Talavera | Q31: =CHOOSE(LEN($O31) - LEN(SUBSTITUTE($O31," ","")) + 1, LEFT($O31), LEFT($O31, 1) & MID($O31, FIND(" ", $O31) + 1, 1), LEFT($O31, 1) & MID($O31, FIND(" ", $O31) + 1, 1) & MID($O31, FIND(" ", $O31, FIND(" ", $O31) + 1) + 1, 1)) -> PHT
A32: Contenido de humedad con densímetro-(%) | E32: =IF(E31=0,"",(E30/E31)-1) -> 0.11498258 | G32: =IF(G31=0,"",(G30/G31)-1) -> 0.11338399 | I32: =IF(I31=0,"",(I30/I31)-1) -> 0.14139693 | K32: =IF(K31=0,"",(K30/K31)-1) -> 0.10310486 | O32: Juan Carlos Marin | Q32: =CHOOSE(LEN($O32) - LEN(SUBSTITUTE($O32," ","")) + 1, LEFT($O32), LEFT($O32, 1) & MID($O32, FIND(" ", $O32) + 1, 1), LEFT($O32, 1) & MID($O32, FIND(" ", $O32) + 1, 1) & MID($O32, FIND(" ", $O32, FIND(" ", $O32) + 1) + 1, 1)) -> JCM | T32: Comntactos
A33: Contenido de humedad en horno (%) | F33: =IF(E53="",F53,E53) -> 0.131 | H33: =IF(G53="",H53,G53) -> 0.118 | J33: =IF(I53="",J53,I53) -> 0.166 | L33: =IF(K53="",L53,K53) -> 0.094 | O33: Francisco Javier Vilcapaza | Q33: =CHOOSE(LEN($O33) - LEN(SUBSTITUTE($O33," ","")) + 1, LEFT($O33), LEFT($O33, 1) & MID($O33, FIND(" ", $O33) + 1, 1), LEFT($O33, 1) & MID($O33, FIND(" ", $O33) + 1, 1) & MID($O33, FIND(" ", $O33, FIND(" ", $O33) + 1) + 1, 1)) -> FJV | T33: Contacto
A34: PUNTO PRÓCTOR (ASTM D 698 - MÉTODO A) | O34: Sergio Zapana Condori | Q34: =CHOOSE(LEN($O34) - LEN(SUBSTITUTE($O34," ","")) + 1, LEFT($O34), LEFT($O34, 1) & MID($O34, FIND(" ", $O34) + 1, 1), LEFT($O34, 1) & MID($O34, FIND(" ", $O34) + 1, 1) & MID($O34, FIND(" ", $O34, FIND(" ", $O34) + 1) + 1, 1)) -> SZC | T34: Contacto Der.
A35: Densidad Seca del Punto Próctor | O35: Guillermo Perez Honorato | Q35: =CHOOSE(LEN($O35) - LEN(SUBSTITUTE($O35," ","")) + 1, LEFT($O35), LEFT($O35, 1) & MID($O35, FIND(" ", $O35) + 1, 1), LEFT($O35, 1) & MID($O35, FIND(" ", $O35) + 1, 1) & MID($O35, FIND(" ", $O35, FIND(" ", $O35) + 1) + 1, 1)) -> GPH | T35: Contacto Izq.
A36: Número de Molde | O36: Brian Fernandez Bernedo | Q36: =CHOOSE(LEN($O36) - LEN(SUBSTITUTE($O36," ","")) + 1, LEFT($O36), LEFT($O36, 1) & MID($O36, FIND(" ", $O36) + 1, 1), LEFT($O36, 1) & MID($O36, FIND(" ", $O36) + 1, 1) & MID($O36, FIND(" ", $O36, FIND(" ", $O36) + 1) + 1, 1)) -> BFB | T36: Reparación
A37: Peso del molde + suelo (g) | O37: Paul Paz Jara | Q37: =CHOOSE(LEN($O37) - LEN(SUBSTITUTE($O37," ","")) + 1, LEFT($O37), LEFT($O37, 1) & MID($O37, FIND(" ", $O37) + 1, 1), LEFT($O37, 1) & MID($O37, FIND(" ", $O37) + 1, 1) & MID($O37, FIND(" ", $O37, FIND(" ", $O37) + 1) + 1, 1)) -> PPJ
A38: Peso del molde (g) | F38: =IF(F36=0," ",VLOOKUP(F36,$L$83:$N$85,2)) | H38: =IF(H36=0," ",VLOOKUP(H36,$L$83:$N$85,2)) | J38: =IF(J36=0," ",VLOOKUP(J36,$L$83:$N$85,2)) | L38: =IF(L36=0," ",VLOOKUP(L36,$L$83:$N$85,2)) | O38: Niuler Mamani Cordova | Q38: =CHOOSE(LEN($O38) - LEN(SUBSTITUTE($O38," ","")) + 1, LEFT($O38), LEFT($O38, 1) & MID($O38, FIND(" ", $O38) + 1, 1), LEFT($O38, 1) & MID($O38, FIND(" ", $O38) + 1, 1) & MID($O38, FIND(" ", $O38, FIND(" ", $O38) + 1) + 1, 1)) -> NMC
A39: Peso suelo compactado (g) | E39: =IF(E37="","",E37-E38) | F39: =IF(F37="","",F37-F38) | G39: =IF(G37="","",G37-G38) | H39: =IF(H37="","",H37-H38) | I39: =IF(I37="","",I37-I38) | J39: =IF(J37="","",J37-J38) | K39: =IF(K37="","",K37-K38) | L39: =IF(L37="","",L37-L38) | O39: Anderson Magner Apaza | Q39: =CHOOSE(LEN($O39) - LEN(SUBSTITUTE($O39," ","")) + 1, LEFT($O39), LEFT($O39, 1) & MID($O39, FIND(" ", $O39) + 1, 1), LEFT($O39, 1) & MID($O39, FIND(" ", $O39) + 1, 1) & MID($O39, FIND(" ", $O39, FIND(" ", $O39) + 1) + 1, 1)) -> AMA
A40: Volumen molde (cm3) | F40: =IF(F36=0," ",VLOOKUP(F36,$L$83:$N$85,3)) | H40: =IF(H36=0," ",VLOOKUP(H36,$L$83:$N$85,3)) | J40: =IF(J36=0," ",VLOOKUP(J36,$L$83:$N$85,3)) | L40: =IF(L36=0," ",VLOOKUP(L36,$L$83:$N$85,3)) | Q40: =CHOOSE(LEN($O40) - LEN(SUBSTITUTE($O40," ","")) + 1, LEFT($O40), LEFT($O40, 1) & MID($O40, FIND(" ", $O40) + 1, 1), LEFT($O40, 1) & MID($O40, FIND(" ", $O40) + 1, 1) & MID($O40, FIND(" ", $O40, FIND(" ", $O40) + 1) + 1, 1))
...

Sheet topo
C2: Fecha | D2: =DN!I9 -> 46100
B5: PUNTO | C5: ESTE | D5: NORTE | E5: COTA | F5: N° ENSAYO PARA FORMATO DE VERIFICACION | G5: Cancha | H5: Spool | I5: Descripcion si es corona o piezometro | J5: Cancha | K5: Spools | L5: Sub Zonas
A6: 1 | B6: D-01 | C6: 2151.91 | D6: -171.88 | E6: 2630.71 | F6: =DN!$E11 -> DN-261345 | G6: =IF(C6="","",CONCATENATE(MATCH(C6,$J$6:$J$9,1),VLOOKUP(C6,$L$6:$M$17,2),IF(D6<250,"-H",IF(D6<500,"-M","-L")))) -> 4C-H | H6: =IF(C6="","",IF(I6="",CONCATENATE("Sp ",MATCH(C6,$K$6:$K$73,1)),I6)) -> Sp 67 | J6: 0 | K6: 0 | L6: 0 | M6: A
A7: 2 | B7: D-02 | C7: 2075.79 | D7: -133.86 | E7: 2622.68 | F7: =DN!$G11 -> DN-261346 | G7: =IF(C7="","",CONCATENATE(MATCH(C7,$J$6:$J$9,1),VLOOKUP(C7,$L$6:$M$17,2),IF(D7<250,"-H",IF(D7<500,"-M","-L")))) -> 4C-H | H7: =IF(C7="","",IF(I7="",CONCATENATE("Sp ",MATCH(C7,$K$6:$K$73,1)),I7)) -> Sp 64 | J7: 600 | K7: 31.1502 | L7: 260 | M7: B
A8: 3 | B8: D-03 | C8: 1989.7 | D8: -146.98 | E8: 2631.82 | F8: =DN!$I11 -> DN-261347 | G8: =IF(C8="","",CONCATENATE(MATCH(C8,$J$6:$J$9,1),VLOOKUP(C8,$L$6:$M$17,2),IF(D8<250,"-H",IF(D8<500,"-M","-L")))) -> 4C-H | H8: =IF(C8="","",IF(I8="",CONCATENATE("Sp ",MATCH(C8,$K$6:$K$73,1)),I8)) -> Sp 62 | J8: 1120 | K8: 62.91555 | L8: 440 | M8: C
A9: 4 | B9: D-04 | C9: 1966.84 | D9: -57.09 | E9: 2610.18 | F9: =DN!$K11 -> DN-261348 | G9: =IF(C9="","",CONCATENATE(MATCH(C9,$J$6:$J$9,1),VLOOKUP(C9,$L$6:$M$17,2),IF(D9<250,"-H",IF(D9<500,"-M","-L")))) -> 4C-H | H9: =IF(C9="","",IF(I9="",CONCATENATE("Sp ",MATCH(C9,$K$6:$K$73,1)),I9)) -> Sp 61 | J9: 1640 | K9: 94.68085 | L9: 600 | M9: A
A10: 5 | B10: D-05 | F10: =DN!#REF! -> #REF! | G10: =IF(C10="","",CONCATENATE(MATCH(C10,$J$6:$J$9,1),VLOOKUP(C10,$L$6:$M$17,2),IF(D10<250,"-H",IF(D10<500,"-M","-L")))) | H10: =IF(C10="","",IF(I10="",CONCATENATE("Sp ",MATCH(C10,$K$6:$K$73,1)),I10)) | K10: 131.7404 | L10: 780 | M10: B
A11: 6 | B11: D-06 | F11: =DN!#REF! -> #REF! | G11: =IF(C11="","",CONCATENATE(MATCH(C11,$J$6:$J$9,1),VLOOKUP(C11,$L$6:$M$17,2),IF(D11<250,"-H",IF(D11<500,"-M","-L")))) | H11: =IF(C11="","",IF(I11="",CONCATENATE("Sp ",MATCH(C11,$K$6:$K$73,1)),I11)) | K11: 168.79995 | L11: 940 | M11: C
A12: 7 | B12: D-07 | F12: =DN!#REF! -> #REF! | G12: =IF(C12="","",CONCATENATE(MATCH(C12,$J$6:$J$9,1),VLOOKUP(C12,$L$6:$M$17,2),IF(D12<250,"-H",IF(D12<500,"-M","-L")))) | H12: =IF(C12="","",IF(I12="",CONCATENATE("Sp ",MATCH(C12,$K$6:$K$73,1)),I12)) | K12: 201.0816 | L12: 1120 | M12: A
A13: 8 | B13: D-08 | F13: =DN!#REF! -> #REF! | G13: =IF(C13="","",CONCATENATE(MATCH(C13,$J$6:$J$9,1),VLOOKUP(C13,$L$6:$M$17,2),IF(D13<250,"-H",IF(D13<500,"-M","-L")))) | H13: =IF(C13="","",IF(I13="",CONCATENATE("Sp ",MATCH(C13,$K$6:$K$73,1)),I13)) | K13: 234.4245 | L13: 1280 | M13: B
A14: 9 | B14: D-09 | F14: =DN!#REF! -> #REF! | G14: =IF(C14="","",CONCATENATE(MATCH(C14,$J$6:$J$9,1),VLOOKUP(C14,$L$6:$M$17,2),IF(D14<250,"-H",IF(D14<500,"-M","-L")))) | H14: =IF(C14="","",IF(I14="",CONCATENATE("Sp ",MATCH(C14,$K$6:$K$73,1)),I14)) | K14: 268.3123 | L14: 1460 | M14: C
A15: 10 | B15: D-10 | F15: =DN!#REF! -> #REF! | G15: =IF(C15="","",CONCATENATE(MATCH(C15,$J$6:$J$9,1),VLOOKUP(C15,$L$6:$M$17,2),IF(D15<250,"-H",IF(D15<500,"-M","-L")))) | H15: =IF(C15="","",IF(I15="",CONCATENATE("Sp ",MATCH(C15,$K$6:$K$73,1)),I15)) | K15: 302.2001 | L15: 1640 | M15: A
A16: 11 | B16: D-11 | F16: =DN!#REF! -> #REF! | G16: =IF(C16="","",CONCATENATE(MATCH(C16,$J$6:$J$9,1),VLOOKUP(C16,$L$6:$M$17,2),IF(D16<250,"-H",IF(D16<500,"-M","-L")))) | H16: =IF(C16="","",IF(I16="",CONCATENATE("Sp ",MATCH(C16,$K$6:$K$73,1)),I16)) | K16: 336.0879 | L16: 1760 | M16: B
A17: 12 | B17: D-12 | F17: =DN!#REF! -> #REF! | G17: =IF(C17="","",CONCATENATE(MATCH(C17,$J$6:$J$9,1),VLOOKUP(C17,$L$6:$M$17,2),IF(D17<250,"-H",IF(D17<500,"-M","-L")))) | H17: =IF(C17="","",IF(I17="",CONCATENATE("Sp ",MATCH(C17,$K$6:$K$73,1)),I17)) | K17: 369.97575 | L17: 1920 | M17: C
A18: 13 | B18: D-13 | F18: =DN!#REF! -> #REF! | G18: =IF(C18="","",CONCATENATE(MATCH(C18,$J$6:$J$9,1),VLOOKUP(C18,$L$6:$M$17,2),IF(D18<250,"-H",IF(D18<500,"-M","-L")))) | H18: =IF(C18="","",IF(I18="",CONCATENATE("Sp ",MATCH(C18,$K$6:$K$73,1)),I18)) | K18: 403.8636
A19: 14 | B19: D-14 | F19: =DN!#REF! -> #REF! | G19: =IF(C19="","",CONCATENATE(MATCH(C19,$J$6:$J$9,1),VLOOKUP(C19,$L$6:$M$17,2),IF(D19<250,"-H",IF(D19<500,"-M","-L")))) | H19: =IF(C19="","",IF(I19="",CONCATENATE("Sp ",MATCH(C19,$K$6:$K$73,1)),I19)) | K19: 437.80885
A20: 15 | B20: D-15 | F20: =DN!#REF! -> #REF! | G20: =IF(C20="","",CONCATENATE(MATCH(C20,$J$6:$J$9,1),VLOOKUP(C20,$L$6:$M$17,2),IF(D20<250,"-H",IF(D20<500,"-M","-L")))) | H20: =IF(C20="","",IF(I20="",CONCATENATE("Sp ",MATCH(C20,$K$6:$K$73,1)),I20)) | K20: 471.75035
A21: 16 | B21: D-16 | F21: =DN!#REF! -> #REF! | G21: =IF(C21="","",CONCATENATE(MATCH(C21,$J$6:$J$9,1),VLOOKUP(C21,$L$6:$M$17,2),IF(D21<250,"-H",IF(D21<500,"-M","-L")))) | H21: =IF(C21="","",IF(I21="",CONCATENATE("Sp ",MATCH(C21,$K$6:$K$73,1)),I21)) | K21: 505.61375
A22: 17 | B22: D-17 | F22: =DN!#REF! -> #REF! | G22: =IF(C22="","",CONCATENATE(MATCH(C22,$J$6:$J$9,1),VLOOKUP(C22,$L$6:$M$17,2),IF(D22<250,"-H",IF(D22<500,"-M","-L")))) | H22: =IF(C22="","",IF(I22="",CONCATENATE("Sp ",MATCH(C22,$K$6:$K$73,1)),I22)) | K22: 539.4432
A23: 18 | B23: D-18 | F23: =DN!#REF! -> #REF! | G23: =IF(C23="","",CONCATENATE(MATCH(C23,$J$6:$J$9,1),VLOOKUP(C23,$L$6:$M$17,2),IF(D23<250,"-H",IF(D23<500,"-M","-L")))) | H23: =IF(C23="","",IF(I23="",CONCATENATE("Sp ",MATCH(C23,$K$6:$K$73,1)),I23)) | K23: 573.2935
A24: 19 | B24: D-19 | F24: =DN!#REF! -> #REF! | G24: =IF(C24="","",CONCATENATE(MATCH(C24,$J$6:$J$9,1),VLOOKUP(C24,$L$6:$M$17,2),IF(D24<250,"-H",IF(D24<500,"-M","-L")))) | H24: =IF(C24="","",IF(I24="",CONCATENATE("Sp ",MATCH(C24,$K$6:$K$73,1)),I24)) | K24: 607.1419
A25: 20 | B25: D-20 | F25: =DN!#REF! -> #REF! | G25: =IF(C25="","",CONCATENATE(MATCH(C25,$J$6:$J$9,1),VLOOKUP(C25,$L$6:$M$17,2),IF(D25<250,"-H",IF(D25<500,"-M","-L")))) | H25: =IF(C25="","",IF(I25="",CONCATENATE("Sp ",MATCH(C25,$K$6:$K$73,1)),I25)) | K25: 640.37135
A26: 21 | B26: D-21 | F26: =DN!#REF! -> #REF! | G26: =IF(C26="","",CONCATENATE(MATCH(C26,$J$6:$J$9,1),VLOOKUP(C26,$L$6:$M$17,2),IF(D26<250,"-H",IF(D26<500,"-M","-L")))) | H26: =IF(C26="","",IF(I26="",CONCATENATE("Sp ",MATCH(C26,$K$6:$K$73,1)),I26)) | K26: 671.1569
A27: 22 | B27: D-22 | F27: =DN!#REF! -> #REF! | G27: =IF(C27="","",CONCATENATE(MATCH(C27,$J$6:$J$9,1),VLOOKUP(C27,$L$6:$M$17,2),IF(D27<250,"-H",IF(D27<500,"-M","-L")))) | H27: =IF(C27="","",IF(I27="",CONCATENATE("Sp ",MATCH(C27,$K$6:$K$73,1)),I27)) | K27: 698.9354
A28: 23 | B28: D-23 | F28: =DN!#REF! -> #REF! | G28: =IF(C28="","",CONCATENATE(MATCH(C28,$J$6:$J$9,1),VLOOKUP(C28,$L$6:$M$17,2),IF(D28<250,"-H",IF(D28<500,"-M","-L")))) | H28: =IF(C28="","",IF(I28="",CONCATENATE("Sp ",MATCH(C28,$K$6:$K$73,1)),I28)) | K28: 726.11345
A29: 24 | B29: D-24 | F29: =DN!#REF! -> #REF! | G29: =IF(C29="","",CONCATENATE(MATCH(C29,$J$6:$J$9,1),VLOOKUP(C29,$L$6:$M$17,2),IF(D29<250,"-H",IF(D29<500,"-M","-L")))) | H29: =IF(C29="","",IF(I29="",CONCATENATE("Sp ",MATCH(C29,$K$6:$K$73,1)),I29)) | K29: 756.1313
K30: 789.3561
K31: 822.79705
K32: 856.144
K33: 890.09225
K34: 924.01645
K35: 957.9634
K36: 991.93895
K37: 1025.8921
K38: 1059.8365
K39: 1093.7632
K40: 1127.7107
K41: 1161.6654
... K73: 2184.4082
