Workbook

Sheet Cono de Arena
C1: Control de Calidad | F1: DENSIDAD DE CAMPO | J1: CV-GC-QC-FORCA-002
C2: Depósito de Relaves Enlozada | F2: CONO DE ARENA | J2: Ver. | K2: 0
F3: ASTM D1556 | J3: Fecha | K3: 46091
A4: Proyecto | C4: : Tailings Storage Facility | F4: Reporte Nº: | I4: =CONCATENATE("CV-DRE-QC-RCA-",TEXT(C10,"yy"),TEXT(MONTH(C10),"0#"),TEXT(DAY(C10),"0#"),"-",D10) -> CV-DRE-QC-RCA-250427-A
A5: Propietario | C5: : Sociedad Minera Cerro Verde | F5: Código de ensayo: | I5: CA-260000
A6: Gerencia | C6: : Relaves y Aguas | F6: Tipo de material: | I6: Arena de relaves
A7: Area | C7: : Operaciones Relaves C1 | F7: Ubicación: | I7: Depósito de Relaves Enlozada
A8: Guardia N° | C8: : 4 | F8: Fecha: | I8: =C10 -> 45774
A10: Fecha Muestreo: | C10: 45774 | D10: A | F10: Muestreado por: | I10: Anderson Apaza
A11: Fecha Ensayo: | C11: =C10 -> 45774 | D11: =D10 -> A | F11: Cono Ensayado por: | I11: Anderson Apaza
A12: Ubicacion ensayo: | C12: =CONCATENATE("Cancha ", 'Cono de Arena'!D17," , ",'Cono de Arena'!D18) -> Cancha 3A-M , Sp 39 | F12: Granul. ensayado por: | I12: Anderson Apaza | V12: Tecnicos
A13: Procedencia: | C13: Underflow de relaves ciclones N°2 | F13: Revisado por: | I13: Gustavo Muñoz | P13: Verificar última fecha de Calibraciones | T13: =HLOOKUP(Q16,P18:R21,4) -> 46116 | V13: Juan Carlos Marín
V14: Sergio Zapana
A15: CONO DE ARENA | V15: Francisco Vilcapaza
A16: Datos generales | F16: Contenido de humedad | J16: Muestra | K16: Pto proctor | P16: Colocar el N° de molde | Q16: 14 | V16: Paul Paz
A17: Cancha-Zona | D17: 3A-M | F17: N° Tara | J17: 22 | K17: 40 | V17: Hebert Asqui
A18: Spray Bar (Sb) - Spool (Sp) - Pórtico (P) | D18: Sp 39 | F18: Peso suelo húmedo + tara (g) | J18: 1029.5 | K18: 1098.1 | N18: Molde # | P18: 12 | Q18: 13 | R18: 14 | V18: Pablo Hinojosa
A19: Progresiva de Presa (E-O) | D19: 1273.74 | F19: Peso suelo seco + tara (g) | J19: 992.6 | K19: 1045.2 | N19: Peso | P19: 4118.4 | Q19: 4111.7 | R19: 4285.1 | V19: Edwin Chullo
A20: Distancia a eje de Presa (aguas abajo) (S-N) | D20: 385.12 | F20: Peso de la tara (g) | J20: 653.1 | K20: 721.6 | N20: Volumen | P20: 938.7 | Q20: 937.4 | R20: 940.8 | V20: Felix Tarqui M
A21: Cota de elevación (msnm) | D21: 2531.73 | F21: Peso del agua (g) | J21: =J18-J19 -> 36.9 | K21: =K18-K19 -> 52.9 | P21: 46116 | Q21: 46116 | R21: 46116 | V21: Gerson Gallegos
A22: Cono número | D22: 28 | F22: Peso del suelo seco (g) | J22: =J19-J20 -> 339.5 | K22: =K19-K20 -> 323.6 | V22: Jorge Pulcha
A23: Equipo utilizado | D23: D6R+B6T | F23: Contenido de humedad (%) | J23: =J21/J22 -> 0.10868925 | K23: =K21/K22 -> 0.16347342 | P23: Verificar última fecha de Calibraciones | T23: =HLOOKUP(D22,P24:R28,5) -> 46125 | V23: Brian Fernandez
A24: Nº de pasadas | D24: 8 | F24: Peso seco total (g) | J24: =+J22 -> 339.5 | N24: Cono # | P24: 28 | Q24: 29 | R24: 31 | V24: Niuler Mamani
V25: Juan Herrera
A26: Datos del ensayo y resultados | F26: Punto proctor, selección de curva y resultados | N26: Peso | P26: 1807 | Q26: 1813 | R26: 1904 | V26: Guillermo Perez
A27: Peso del material bruto (g) | D27: 4782 | F27: P. mat. + molde | G27: P. molde | H27: P. material | I27: Vol. molde | J27: D. húmeda | K27: D. seca | N27: Densidad | P27: 1.551 | Q27: 1.551 | R27: 1.541 | V27: Anderson Apaza
A28: Peso de la tara (g) | D28: 10 | F28: 6184 | G28: =IF(Q16=P18,P19,IF(Q16=Q18,Q19,IF(Q16=R18,R19))) -> 4285.1 | H28: =+F28-G28 -> 1898.9 | I28: =IF(Q16=P18,P20,IF(Q16=Q18,Q20,IF(Q16=R18,R20))) -> 940.8 | J28: =+H28/I28 -> 2.0183886 | K28: =J28/(1+K23) -> 1.7347956 | P28: 46125 | Q28: 46125 | R28: 46127 | V28: Jhon Villalobos
A29: Peso del suelo húmedo (g) | D29: =IF(D27=0,"",(D27-D28)) -> 4772 | F29: Curva adoptada | K29: Pto.Pr.
A30: Peso de la arena + frasco (g) | D30: 7800 | F30: Máxima densidad seca (g/cm3) | K30: 1.735
A31: Peso de la arena del cono (g) | D31: =IF(D22=P24,P26,IF(D22=Q24,Q26,IF(D22=R24,R26,IF(D22=S24,S26,IF(D22=T24,T26))))) -> 1807 | F31: Humedad óptima (%) | K31: 16.3
A32: Peso de la arena que queda + el frasco (g) | D32: 2108 | F32: Porcentaje de compactación (%) | K32: =D38/K30*100 -> 99.040288 | P32: Para Corrección de Granulometría
A33: Peso neto de la arena empleada (g) | D33: =IF(D30=0,"",(D30-D31-D32)) -> 3885 | F33: Compactación especificada (%) | K33: 0.98
A34: Densidad de la arena (g/cm³) | D34: =IF(D22=P24,P27,IF(D22=Q24,Q27,IF(D22=R24,R27,IF(D22=S24,S27,IF(D22=T24,T27))))) -> 1.551 | F34: Profundidad de ensayo (m) | K34: 0.15 | P34: =+J17 -> 22 | Q34: 22
A35: Volumen del hueco (cm³) | D35: =+D33/D34 -> 2504.8356 | F35: Valor asignado a densímetro (g/cm3) | K35: 1.727 | P35: =+J18 -> 1029.5 | Q35: 1029.5 | V35: Supervisores
A36: Densidad del suelo húmedo (g/cm3) | D36: =+D29/D35 -> 1.9051151 | F36: Porcentaje de compactación según densímetro (%) | K36: 100.9 | P36: =+J19 -> 992.6 | Q36: =(P36-P37)*(Q35-Q37)/(P35-P37)+Q37 -> 992.6 | V36: Francisco Vilcapaza
A37: Humedad contenida en el suelo (%) | D37: =+J23 -> 0.10868925 | F37: Pasó/Falló | K37: =IF(K32<=98,"Falló","Pasó") -> Pasó | P37: =+J20 -> 653.1 | Q37: 653.1 | V37: Guillermo Torres
A38: Densidad del suelo seco (g/cm3) | D38: =+D36/(1+D37) -> 1.718349 | F38: Ensayo de Densímetro asociado, código | K38: DN-260410 | V38: Gustavo Muñoz
A39: GRANULOMETRIA | V39: Juan Carlos Marin
F40: Tamices ASTM | G40: Abertura ( µm) | H40: Peso Ret. (g) | I40: % Ret. | J40: % Acum. | K40: % Pasa | V40: Robert Salas
V41: Sergio Zapana
...
